Workbook

Sheet modified_average
A1: GratingPhaseAmplitude | B1: -1035785 | C1: -1035885 | D1: -1035985 | E1: -10351085 | F1: -10351185 | G1: -10351285 | H1: -10351385 | I1: -10351485 | J1: -10351585 | K1: -10351685 | L1: -10351785 | M1: -10351885 | N1: -10351985
A2: 0 | B2: =('1-1'!B2+'1-2'!B2+'1-3'!B2+'1-4'!B2+'1-5'!B2)/5 -> 0 | C2: =('1-1'!C2+'1-2'!C2+'1-3'!C2+'1-4'!C2+'1-5'!C2)/5 -> 0 | D2: =('1-1'!D2+'1-2'!D2+'1-3'!D2+'1-4'!D2+'1-5'!D2)/5 -> 0 | E2: =('1-1'!E2+'1-2'!E2+'1-3'!E2+'1-4'!E2+'1-5'!E2)/5 -> 0 | F2: =('1-1'!F2+'1-2'!F2+'1-3'!F2+'1-4'!F2+'1-5'!F2)/5 -> 0.14222222 | G2: =('1-1'!G2+'1-2'!G2+'1-3'!G2+'1-4'!G2+'1-5'!G2)/5 -> 0 | H2: =('1-1'!H2+'1-2'!H2+'1-3'!H2+'1-4'!H2+'1-5'!H2)/5 -> 0 | I2: =('1-1'!I2+'1-2'!I2+'1-3'!I2+'1-4'!I2+'1-5'!I2)/5 -> 0 | ... N2: =('1-1'!N2+'1-2'!N2+'1-3'!N2+'1-4'!N2+'1-5'!N2)/5 -> 0
A3: 2 | B3: =('1-1'!B3+'1-2'!B3+'1-3'!B3+'1-4'!B3+'1-5'!B3)/5 -> 0 | C3: =('1-1'!C3+'1-2'!C3+'1-3'!C3+'1-4'!C3+'1-5'!C3)/5 -> 0.035555556 | D3: =('1-1'!D3+'1-2'!D3+'1-3'!D3+'1-4'!D3+'1-5'!D3)/5 -> 0 | E3: =('1-1'!E3+'1-2'!E3+'1-3'!E3+'1-4'!E3+'1-5'!E3)/5 -> 0 | F3: =('1-1'!F3+'1-2'!F3+'1-3'!F3+'1-4'!F3+'1-5'!F3)/5 -> 0.035555556 | G3: =('1-1'!G3+'1-2'!G3+'1-3'!G3+'1-4'!G3+'1-5'!G3)/5 -> 0 | H3: =('1-1'!H3+'1-2'!H3+'1-3'!H3+'1-4'!H3+'1-5'!H3)/5 -> 0 | I3: =('1-1'!I3+'1-2'!I3+'1-3'!I3+'1-4'!I3+'1-5'!I3)/5 -> 0.035555556 | ... N3: =('1-1'!N3+'1-2'!N3+'1-3'!N3+'1-4'!N3+'1-5'!N3)/5 -> 0
A4: 4 | B4: =('1-1'!B4+'1-2'!B4+'1-3'!B4+'1-4'!B4+'1-5'!B4)/5 -> 0.035555556 | C4: =('1-1'!C4+'1-2'!C4+'1-3'!C4+'1-4'!C4+'1-5'!C4)/5 -> 0 | D4: =('1-1'!D4+'1-2'!D4+'1-3'!D4+'1-4'!D4+'1-5'!D4)/5 -> 0.035555556 | E4: =('1-1'!E4+'1-2'!E4+'1-3'!E4+'1-4'!E4+'1-5'!E4)/5 -> 0.035555556 | F4: =('1-1'!F4+'1-2'!F4+'1-3'!F4+'1-4'!F4+'1-5'!F4)/5 -> 0.035555556 | G4: =('1-1'!G4+'1-2'!G4+'1-3'!G4+'1-4'!G4+'1-5'!G4)/5 -> 0.10666667 | H4: =('1-1'!H4+'1-2'!H4+'1-3'!H4+'1-4'!H4+'1-5'!H4)/5 -> 0 | I4: =('1-1'!I4+'1-2'!I4+'1-3'!I4+'1-4'!I4+'1-5'!I4)/5 -> 0 | ... N4: =('1-1'!N4+'1-2'!N4+'1-3'!N4+'1-4'!N4+'1-5'!N4)/5 -> 0.035555556
A5: 6 | B5: =('1-1'!B5+'1-2'!B5+'1-3'!B5+'1-4'!B5+'1-5'!B5)/5 -> 0.10666667 | C5: =('1-1'!C5+'1-2'!C5+'1-3'!C5+'1-4'!C5+'1-5'!C5)/5 -> 0.071111111 | D5: =('1-1'!D5+'1-2'!D5+'1-3'!D5+'1-4'!D5+'1-5'!D5)/5 -> 0.10666667 | E5: =('1-1'!E5+'1-2'!E5+'1-3'!E5+'1-4'!E5+'1-5'!E5)/5 -> 0 | F5: =('1-1'!F5+'1-2'!F5+'1-3'!F5+'1-4'!F5+'1-5'!F5)/5 -> 0.071111111 | G5: =('1-1'!G5+'1-2'!G5+'1-3'!G5+'1-4'!G5+'1-5'!G5)/5 -> 0.10666667 | H5: =('1-1'!H5+'1-2'!H5+'1-3'!H5+'1-4'!H5+'1-5'!H5)/5 -> 0.17777778 | I5: =('1-1'!I5+'1-2'!I5+'1-3'!I5+'1-4'!I5+'1-5'!I5)/5 -> 0.14222222 | ... N5: =('1-1'!N5+'1-2'!N5+'1-3'!N5+'1-4'!N5+'1-5'!N5)/5 -> 0.035555556
A6: 8 | B6: =('1-1'!B6+'1-2'!B6+'1-3'!B6+'1-4'!B6+'1-5'!B6)/5 -> 0.035555556 | C6: =('1-1'!C6+'1-2'!C6+'1-3'!C6+'1-4'!C6+'1-5'!C6)/5 -> 0.071111111 | D6: =('1-1'!D6+'1-2'!D6+'1-3'!D6+'1-4'!D6+'1-5'!D6)/5 -> 0.071111111 | E6: =('1-1'!E6+'1-2'!E6+'1-3'!E6+'1-4'!E6+'1-5'!E6)/5 -> 0.071111111 | F6: =('1-1'!F6+'1-2'!F6+'1-3'!F6+'1-4'!F6+'1-5'!F6)/5 -> 0.24888889 | G6: =('1-1'!G6+'1-2'!G6+'1-3'!G6+'1-4'!G6+'1-5'!G6)/5 -> 0.10666667 | H6: =('1-1'!H6+'1-2'!H6+'1-3'!H6+'1-4'!H6+'1-5'!H6)/5 -> 0.14222222 | I6: =('1-1'!I6+'1-2'!I6+'1-3'!I6+'1-4'!I6+'1-5'!I6)/5 -> 0.14222222 | ... N6: =('1-1'!N6+'1-2'!N6+'1-3'!N6+'1-4'!N6+'1-5'!N6)/5 -> 0.035555556
A7: 10 | B7: =('1-1'!B7+'1-2'!B7+'1-3'!B7+'1-4'!B7+'1-5'!B7)/5 -> 0.14222222 | C7: =('1-1'!C7+'1-2'!C7+'1-3'!C7+'1-4'!C7+'1-5'!C7)/5 -> 0.24888889 | D7: =('1-1'!D7+'1-2'!D7+'1-3'!D7+'1-4'!D7+'1-5'!D7)/5 -> 0.74666667 | E7: =('1-1'!E7+'1-2'!E7+'1-3'!E7+'1-4'!E7+'1-5'!E7)/5 -> 0.071111111 | F7: =('1-1'!F7+'1-2'!F7+'1-3'!F7+'1-4'!F7+'1-5'!F7)/5 -> 1.28 | G7: =('1-1'!G7+'1-2'!G7+'1-3'!G7+'1-4'!G7+'1-5'!G7)/5 -> 1.2444444 | H7: =('1-1'!H7+'1-2'!H7+'1-3'!H7+'1-4'!H7+'1-5'!H7)/5 -> 1.2444444 | I7: =('1-1'!I7+'1-2'!I7+'1-3'!I7+'1-4'!I7+'1-5'!I7)/5 -> 0.24888889 | ... N7: =('1-1'!N7+'1-2'!N7+'1-3'!N7+'1-4'!N7+'1-5'!N7)/5 -> 0
A8: 12 | B8: =('1-1'!B8+'1-2'!B8+'1-3'!B8+'1-4'!B8+'1-5'!B8)/5 -> 0.28444444 | C8: =('1-1'!C8+'1-2'!C8+'1-3'!C8+'1-4'!C8+'1-5'!C8)/5 -> 0.32 | D8: =('1-1'!D8+'1-2'!D8+'1-3'!D8+'1-4'!D8+'1-5'!D8)/5 -> 0.60444444 | E8: =('1-1'!E8+'1-2'!E8+'1-3'!E8+'1-4'!E8+'1-5'!E8)/5 -> 0.17777778 | F8: =('1-1'!F8+'1-2'!F8+'1-3'!F8+'1-4'!F8+'1-5'!F8)/5 -> 1.28 | G8: =('1-1'!G8+'1-2'!G8+'1-3'!G8+'1-4'!G8+'1-5'!G8)/5 -> 2.4177778 | H8: =('1-1'!H8+'1-2'!H8+'1-3'!H8+'1-4'!H8+'1-5'!H8)/5 -> 1.6711111 | I8: =('1-1'!I8+'1-2'!I8+'1-3'!I8+'1-4'!I8+'1-5'!I8)/5 -> 0.64 | ... N8: =('1-1'!N8+'1-2'!N8+'1-3'!N8+'1-4'!N8+'1-5'!N8)/5 -> 0
A9: 14 | B9: =('1-1'!B9+'1-2'!B9+'1-3'!B9+'1-4'!B9+'1-5'!B9)/5 -> 0.35555556 | C9: =('1-1'!C9+'1-2'!C9+'1-3'!C9+'1-4'!C9+'1-5'!C9)/5 -> 0.64 | D9: =('1-1'!D9+'1-2'!D9+'1-3'!D9+'1-4'!D9+'1-5'!D9)/5 -> 1.8844444 | E9: =('1-1'!E9+'1-2'!E9+'1-3'!E9+'1-4'!E9+'1-5'!E9)/5 -> 0.32 | F9: =('1-1'!F9+'1-2'!F9+'1-3'!F9+'1-4'!F9+'1-5'!F9)/5 -> 3.9111111 | G9: =('1-1'!G9+'1-2'!G9+'1-3'!G9+'1-4'!G9+'1-5'!G9)/5 -> 3.2355556 | H9: =('1-1'!H9+'1-2'!H9+'1-3'!H9+'1-4'!H9+'1-5'!H9)/5 -> 3.52 | I9: =('1-1'!I9+'1-2'!I9+'1-3'!I9+'1-4'!I9+'1-5'!I9)/5 -> 1.0666667 | ... N9: =('1-1'!N9+'1-2'!N9+'1-3'!N9+'1-4'!N9+'1-5'!N9)/5 -> 0.17777778
A10: 16 | B10: =('1-1'!B10+'1-2'!B10+'1-3'!B10+'1-4'!B10+'1-5'!B10)/5 -> 0.64 | C10: =('1-1'!C10+'1-2'!C10+'1-3'!C10+'1-4'!C10+'1-5'!C10)/5 -> 2.4177778 | D10: =('1-1'!D10+'1-2'!D10+'1-3'!D10+'1-4'!D10+'1-5'!D10)/5 -> 3.4844444 | E10: =('1-1'!E10+'1-2'!E10+'1-3'!E10+'1-4'!E10+'1-5'!E10)/5 -> 1.8844444 | F10: =('1-1'!F10+'1-2'!F10+'1-3'!F10+'1-4'!F10+'1-5'!F10)/5 -> 5.6533333 | G10: =('1-1'!G10+'1-2'!G10+'1-3'!G10+'1-4'!G10+'1-5'!G10)/5 -> 6.6844444 | H10: =('1-1'!H10+'1-2'!H10+'1-3'!H10+'1-4'!H10+'1-5'!H10)/5 -> 6.2222222 | I10: =('1-1'!I10+'1-2'!I10+'1-3'!I10+'1-4'!I10+'1-5'!I10)/5 -> 3.2355556 | ... N10: =('1-1'!N10+'1-2'!N10+'1-3'!N10+'1-4'!N10+'1-5'!N10)/5 -> 0.035555556
A11: 18 | B11: =('1-1'!B11+'1-2'!B11+'1-3'!B11+'1-4'!B11+'1-5'!B11)/5 -> 1.8488889 | C11: =('1-1'!C11+'1-2'!C11+'1-3'!C11+'1-4'!C11+'1-5'!C11)/5 -> 4.0888889 | D11: =('1-1'!D11+'1-2'!D11+'1-3'!D11+'1-4'!D11+'1-5'!D11)/5 -> 6.1866667 | E11: =('1-1'!E11+'1-2'!E11+'1-3'!E11+'1-4'!E11+'1-5'!E11)/5 -> 3.5555556 | F11: =('1-1'!F11+'1-2'!F11+'1-3'!F11+'1-4'!F11+'1-5'!F11)/5 -> 12.302222 | G11: =('1-1'!G11+'1-2'!G11+'1-3'!G11+'1-4'!G11+'1-5'!G11)/5 -> 19.093333 | H11: =('1-1'!H11+'1-2'!H11+'1-3'!H11+'1-4'!H11+'1-5'!H11)/5 -> 10.346667 | I11: =('1-1'!I11+'1-2'!I11+'1-3'!I11+'1-4'!I11+'1-5'!I11)/5 -> 5.2266667 | ... N11: =('1-1'!N11+'1-2'!N11+'1-3'!N11+'1-4'!N11+'1-5'!N11)/5 -> 0.071111111
A12: 20 | B12: =('1-1'!B12+'1-2'!B12+'1-3'!B12+'1-4'!B12+'1-5'!B12)/5 -> 2.6311111 | C12: =('1-1'!C12+'1-2'!C12+'1-3'!C12+'1-4'!C12+'1-5'!C12)/5 -> 4.4088889 | D12: =('1-1'!D12+'1-2'!D12+'1-3'!D12+'1-4'!D12+'1-5'!D12)/5 -> 8.32 | E12: =('1-1'!E12+'1-2'!E12+'1-3'!E12+'1-4'!E12+'1-5'!E12)/5 -> 4.48 | F12: =('1-1'!F12+'1-2'!F12+'1-3'!F12+'1-4'!F12+'1-5'!F12)/5 -> 23.608889 | G12: =('1-1'!G12+'1-2'!G12+'1-3'!G12+'1-4'!G12+'1-5'!G12)/5 -> 32.888889 | H12: =('1-1'!H12+'1-2'!H12+'1-3'!H12+'1-4'!H12+'1-5'!H12)/5 -> 20.871111 | I12: =('1-1'!I12+'1-2'!I12+'1-3'!I12+'1-4'!I12+'1-5'!I12)/5 -> 7.1466667 | ... N12: =('1-1'!N12+'1-2'!N12+'1-3'!N12+'1-4'!N12+'1-5'!N12)/5 -> 0.035555556
A13: 22 | B13: =('1-1'!B13+'1-2'!B13+'1-3'!B13+'1-4'!B13+'1-5'!B13)/5 -> 5.0133333 | C13: =('1-1'!C13+'1-2'!C13+'1-3'!C13+'1-4'!C13+'1-5'!C13)/5 -> 9.3511111 | D13: =('1-1'!D13+'1-2'!D13+'1-3'!D13+'1-4'!D13+'1-5'!D13)/5 -> 26.524444 | E13: =('1-1'!E13+'1-2'!E13+'1-3'!E13+'1-4'!E13+'1-5'!E13)/5 -> 8.5688889 | F13: =('1-1'!F13+'1-2'!F13+'1-3'!F13+'1-4'!F13+'1-5'!F13)/5 -> 78.364444 | G13: =('1-1'!G13+'1-2'!G13+'1-3'!G13+'1-4'!G13+'1-5'!G13)/5 -> 101.22667 | H13: =('1-1'!H13+'1-2'!H13+'1-3'!H13+'1-4'!H13+'1-5'!H13)/5 -> 68.515556 | I13: =('1-1'!I13+'1-2'!I13+'1-3'!I13+'1-4'!I13+'1-5'!I13)/5 -> 19.448889 | ... N13: =('1-1'!N13+'1-2'!N13+'1-3'!N13+'1-4'!N13+'1-5'!N13)/5 -> 0.17777778
... A29: 54 | B29: =('1-1'!B29+'1-2'!B29+'1-3'!B29+'1-4'!B29+'1-5'!B29)/5 -> 406.75556 | C29: =('1-1'!C29+'1-2'!C29+'1-3'!C29+'1-4'!C29+'1-5'!C29)/5 -> 684.55111 | D29: =('1-1'!D29+'1-2'!D29+'1-3'!D29+'1-4'!D29+'1-5'!D29)/5 -> 836.05333 | E29: =('1-1'!E29+'1-2'!E29+'1-3'!E29+'1-4'!E29+'1-5'!E29)/5 -> 842.91556 | F29: =('1-1'!F29+'1-2'!F29+'1-3'!F29+'1-4'!F29+'1-5'!F29)/5 -> 1101.2978 | G29: =('1-1'!G29+'1-2'!G29+'1-3'!G29+'1-4'!G29+'1-5'!G29)/5 -> 1113.8489 | H29: =('1-1'!H29+'1-2'!H29+'1-3'!H29+'1-4'!H29+'1-5'!H29)/5 -> 1078.4711 | I29: =('1-1'!I29+'1-2'!I29+'1-3'!I29+'1-4'!I29+'1-5'!I29)/5 -> 830.75556 | ... N29: =('1-1'!N29+'1-2'!N29+'1-3'!N29+'1-4'!N29+'1-5'!N29)/5 -> 95.111111
A30: 56 | B30: =('1-1'!B30+'1-3'!B30+'1-4'!B30+'1-5'!B30)/4 -> 408.57778 | C30: =('1-1'!C30+'1-3'!C30+'1-4'!C30+'1-5'!C30)/4 -> 701.73333 | D30: =('1-1'!D30+'1-3'!D30+'1-4'!D30+'1-5'!D30)/4 -> 846.8 | E30: =('1-1'!E30+'1-3'!E30+'1-4'!E30+'1-5'!E30)/4 -> 857.82222 | F30: =('1-1'!F30+'1-3'!F30+'1-4'!F30+'1-5'!F30)/4 -> 1112.8444 | G30: =('1-1'!G30+'1-3'!G30+'1-4'!G30+'1-5'!G30)/4 -> 1141.7333 | H30: =('1-1'!H30+'1-3'!H30+'1-4'!H30+'1-5'!H30)/4 -> 1096.1333 | I30: =('1-1'!I30+'1-3'!I30+'1-4'!I30+'1-5'!I30)/4 -> 850.75556 | ... N30: =('1-1'!N30+'1-3'!N30+'1-4'!N30+'1-5'!N30)/4 -> 100.48889
A31: 58 | B31: =('1-1'!B31+'1-2'!B31+'1-3'!B31+'1-4'!B31+'1-5'!B31)/5 -> 480.56889 | C31: =('1-1'!C31+'1-2'!C31+'1-3'!C31+'1-4'!C31+'1-5'!C31)/5 -> 807.89333 | D31: =('1-1'!D31+'1-2'!D31+'1-3'!D31+'1-4'!D31+'1-5'!D31)/5 -> 989.33333 | E31: =('1-1'!E31+'1-2'!E31+'1-3'!E31+'1-4'!E31+'1-5'!E31)/5 -> 1005.8311 | F31: =('1-1'!F31+'1-2'!F31+'1-3'!F31+'1-4'!F31+'1-5'!F31)/5 -> 1282.8089 | G31: =('1-1'!G31+'1-2'!G31+'1-3'!G31+'1-4'!G31+'1-5'!G31)/5 -> 1296.3556 | H31: =('1-1'!H31+'1-2'!H31+'1-3'!H31+'1-4'!H31+'1-5'!H31)/5 -> 1261.1911 | I31: =('1-1'!I31+'1-2'!I31+'1-3'!I31+'1-4'!I31+'1-5'!I31)/5 -> 980.62222 | ... N31: =('1-1'!N31+'1-2'!N31+'1-3'!N31+'1-4'!N31+'1-5'!N31)/5 -> 129.99111
A32: 60 | B32: =('1-1'!B32+'1-2'!B32+'1-3'!B32+'1-4'!B32+'1-5'!B32)/5 -> 523.27111 | C32: =('1-1'!C32+'1-2'!C32+'1-3'!C32+'1-4'!C32+'1-5'!C32)/5 -> 879.00444 | D32: =('1-1'!D32+'1-2'!D32+'1-3'!D32+'1-4'!D32+'1-5'!D32)/5 -> 1087.5022 | E32: =('1-1'!E32+'1-2'!E32+'1-3'!E32+'1-4'!E32+'1-5'!E32)/5 -> 1095.2178 | F32: =('1-1'!F32+'1-2'!F32+'1-3'!F32+'1-4'!F32+'1-5'!F32)/5 -> 1397.2622 | G32: =('1-1'!G32+'1-2'!G32+'1-3'!G32+'1-4'!G32+'1-5'!G32)/5 -> 1409.3511 | H32: =('1-1'!H32+'1-2'!H32+'1-3'!H32+'1-4'!H32+'1-5'!H32)/5 -> 1369.28 | I32: =('1-1'!I32+'1-2'!I32+'1-3'!I32+'1-4'!I32+'1-5'!I32)/5 -> 1071.2889 | ... N32: =('1-1'!N32+'1-2'!N32+'1-3'!N32+'1-4'!N32+'1-5'!N32)/5 -> 138.09778
A33: 62 | B33: =('1-1'!B33+'1-2'!B33+'1-3'!B33+'1-4'!B33+'1-5'!B33)/5 -> 559.57333 | C33: =('1-1'!C33+'1-2'!C33+'1-3'!C33+'1-4'!C33+'1-5'!C33)/5 -> 932.30222 | D33: =('1-1'!D33+'1-2'!D33+'1-3'!D33+'1-4'!D33+'1-5'!D33)/5 -> 1141.2622 | E33: =('1-1'!E33+'1-2'!E33+'1-3'!E33+'1-4'!E33+'1-5'!E33)/5 -> 1161.1022 | F33: =('1-1'!F33+'1-2'!F33+'1-3'!F33+'1-4'!F33+'1-5'!F33)/5 -> 1482.1333 | G33: =('1-1'!G33+'1-2'!G33+'1-3'!G33+'1-4'!G33+'1-5'!G33)/5 -> 1498.0267 | H33: =('1-1'!H33+'1-2'!H33+'1-3'!H33+'1-4'!H33+'1-5'!H33)/5 -> 1454.9689 | I33: =('1-1'!I33+'1-2'!I33+'1-3'!I33+'1-4'!I33+'1-5'!I33)/5 -> 1135.9289 | ... N33: =('1-1'!N33+'1-2'!N33+'1-3'!N33+'1-4'!N33+'1-5'!N33)/5 -> 140.72889
A34: 64 | B34: =('1-1'!B34+'1-2'!B34+'1-3'!B34+'1-4'!B34+'1-5'!B34)/5 -> 635.34222 | C34: =('1-1'!C34+'1-2'!C34+'1-3'!C34+'1-4'!C34+'1-5'!C34)/5 -> 1062.7911 | D34: =('1-1'!D34+'1-2'!D34+'1-3'!D34+'1-4'!D34+'1-5'!D34)/5 -> 1289.5644 | E34: =('1-1'!E34+'1-2'!E34+'1-3'!E34+'1-4'!E34+'1-5'!E34)/5 -> 1307.3422 | F34: =('1-1'!F34+'1-2'!F34+'1-3'!F34+'1-4'!F34+'1-5'!F34)/5 -> 1664.4267 | G34: =('1-1'!G34+'1-2'!G34+'1-3'!G34+'1-4'!G34+'1-5'!G34)/5 -> 1691.4489 | H34: =('1-1'!H34+'1-2'!H34+'1-3'!H34+'1-4'!H34+'1-5'!H34)/5 -> 1648.8889 | I34: =('1-1'!I34+'1-2'!I34+'1-3'!I34+'1-4'!I34+'1-5'!I34)/5 -> 1282.8089 | ... N34: =('1-1'!N34+'1-2'!N34+'1-3'!N34+'1-4'!N34+'1-5'!N34)/5 -> 158.11556
A35: 66 | B35: =('1-1'!B35+'1-2'!B35+'1-3'!B35+'1-4'!B35+'1-5'!B35)/5 -> 652.94222 | C35: =('1-1'!C35+'1-2'!C35+'1-3'!C35+'1-4'!C35+'1-5'!C35)/5 -> 1096.5333 | D35: =('1-1'!D35+'1-2'!D35+'1-3'!D35+'1-4'!D35+'1-5'!D35)/5 -> 1334.08 | E35: =('1-1'!E35+'1-2'!E35+'1-3'!E35+'1-4'!E35+'1-5'!E35)/5 -> 1355.3067 | F35: =('1-1'!F35+'1-2'!F35+'1-3'!F35+'1-4'!F35+'1-5'!F35)/5 -> 1727.5378 | G35: =('1-1'!G35+'1-2'!G35+'1-3'!G35+'1-4'!G35+'1-5'!G35)/5 -> 1747.84 | H35: =('1-1'!H35+'1-2'!H35+'1-3'!H35+'1-4'!H35+'1-5'!H35)/5 -> 1705.5644 | I35: =('1-1'!I35+'1-2'!I35+'1-3'!I35+'1-4'!I35+'1-5'!I35)/5 -> 1333.5467 | ... N35: =('1-1'!N35+'1-2'!N35+'1-3'!N35+'1-4'!N35+'1-5'!N35)/5 -> 161.56444
A36: 68 | B36: =('1-1'!B36+'1-2'!B36+'1-3'!B36+'1-4'!B36+'1-5'!B36)/5 -> 701.65333 | C36: =('1-1'!C36+'1-2'!C36+'1-3'!C36+'1-4'!C36+'1-5'!C36)/5 -> 1180.4089 | D36: =('1-1'!D36+'1-2'!D36+'1-3'!D36+'1-4'!D36+'1-5'!D36)/5 -> 1434.0622 | E36: =('1-1'!E36+'1-2'!E36+'1-3'!E36+'1-4'!E36+'1-5'!E36)/5 -> 1477.0489 | F36: =('1-1'!F36+'1-2'!F36+'1-3'!F36+'1-4'!F36+'1-5'!F36)/5 -> 1851.5911 | G36: =('1-1'!G36+'1-2'!G36+'1-3'!G36+'1-4'!G36+'1-5'!G36)/5 -> 1878.5067 | H36: =('1-1'!H36+'1-2'!H36+'1-3'!H36+'1-4'!H36+'1-5'!H36)/5 -> 1835.3067 | I36: =('1-1'!I36+'1-2'!I36+'1-3'!I36+'1-4'!I36+'1-5'!I36)/5 -> 1440.7822 | ... N36: =('1-1'!N36+'1-2'!N36+'1-3'!N36+'1-4'!N36+'1-5'!N36)/5 -> 183.21778
A37: 70 | B37: =('1-1'!B37+'1-2'!B37+'1-3'!B37+'1-4'!B37+'1-5'!B37)/5 -> 769.45778 | C37: =('1-1'!C37+'1-2'!C37+'1-3'!C37+'1-4'!C37+'1-5'!C37)/5 -> 1283.84 | D37: =('1-1'!D37+'1-2'!D37+'1-3'!D37+'1-4'!D37+'1-5'!D37)/5 -> 1569.3511 | E37: =('1-1'!E37+'1-2'!E37+'1-3'!E37+'1-4'!E37+'1-5'!E37)/5 -> 1613.9022 | F37: =('1-1'!F37+'1-2'!F37+'1-3'!F37+'1-4'!F37+'1-5'!F37)/5 -> 2029.2267 | G37: =('1-1'!G37+'1-2'!G37+'1-3'!G37+'1-4'!G37+'1-5'!G37)/5 -> 2051.7689 | H37: =('1-1'!H37+'1-2'!H37+'1-3'!H37+'1-4'!H37+'1-5'!H37)/5 -> 2010.3467 | I37: =('1-1'!I37+'1-2'!I37+'1-3'!I37+'1-4'!I37+'1-5'!I37)/5 -> 1570.8444 | ... N37: =('1-1'!N37+'1-2'!N37+'1-3'!N37+'1-4'!N37+'1-5'!N37)/5 -> 212.55111
A38: 72 | B38: =('1-1'!B38+'1-2'!B38+'1-3'!B38+'1-4'!B38+'1-5'!B38)/5 -> 827.62667 | C38: =('1-1'!C38+'1-2'!C38+'1-3'!C38+'1-4'!C38+'1-5'!C38)/5 -> 1389.6889 | D38: =('1-1'!D38+'1-2'!D38+'1-3'!D38+'1-4'!D38+'1-5'!D38)/5 -> 1685.9378 | E38: =('1-1'!E38+'1-2'!E38+'1-3'!E38+'1-4'!E38+'1-5'!E38)/5 -> 1756.6578 | F38: =('1-1'!F38+'1-2'!F38+'1-3'!F38+'1-4'!F38+'1-5'!F38)/5 -> 2193.3511 | G38: =('1-1'!G38+'1-2'!G38+'1-3'!G38+'1-4'!G38+'1-5'!G38)/5 -> 2214.1511 | H38: =('1-1'!H38+'1-2'!H38+'1-3'!H38+'1-4'!H38+'1-5'!H38)/5 -> 2165.9022 | I38: =('1-1'!I38+'1-2'!I38+'1-3'!I38+'1-4'!I38+'1-5'!I38)/5 -> 1707.6267 | ... N38: =('1-1'!N38+'1-2'!N38+'1-3'!N38+'1-4'!N38+'1-5'!N38)/5 -> 243.16444
A39: 74 | B39: =('1-1'!B39+'1-2'!B39+'1-3'!B39+'1-4'!B39+'1-5'!B39)/5 -> 882.27556 | C39: =('1-1'!C39+'1-2'!C39+'1-3'!C39+'1-4'!C39+'1-5'!C39)/5 -> 1481.6711 | D39: =('1-1'!D39+'1-2'!D39+'1-3'!D39+'1-4'!D39+'1-5'!D39)/5 -> 1804.2311 | E39: =('1-1'!E39+'1-2'!E39+'1-3'!E39+'1-4'!E39+'1-5'!E39)/5 -> 1870.7911 | F39: =('1-1'!F39+'1-2'!F39+'1-3'!F39+'1-4'!F39+'1-5'!F39)/5 -> 2334.3289 | G39: =('1-1'!G39+'1-2'!G39+'1-3'!G39+'1-4'!G39+'1-5'!G39)/5 -> 2368.6044 | H39: =('1-1'!H39+'1-2'!H39+'1-3'!H39+'1-4'!H39+'1-5'!H39)/5 -> 2313.8489 | I39: =('1-1'!I39+'1-2'!I39+'1-3'!I39+'1-4'!I39+'1-5'!I39)/5 -> 1828.2667 | ... N39: =('1-1'!N39+'1-2'!N39+'1-3'!N39+'1-4'!N39+'1-5'!N39)/5 -> 270.57778
A40: 76 | B40: =('1-1'!B40+'1-2'!B40+'1-3'!B40+'1-4'!B40+'1-5'!B40)/5 -> 936.46222 | C40: =('1-1'!C40+'1-2'!C40+'1-3'!C40+'1-4'!C40+'1-5'!C40)/5 -> 1580.6222 | D40: =('1-1'!D40+'1-2'!D40+'1-3'!D40+'1-4'!D40+'1-5'!D40)/5 -> 1906.0622 | E40: =('1-1'!E40+'1-2'!E40+'1-3'!E40+'1-4'!E40+'1-5'!E40)/5 -> 1994.4178 | F40: =('1-1'!F40+'1-2'!F40+'1-3'!F40+'1-4'!F40+'1-5'!F40)/5 -> 2461.5467 | G40: =('1-1'!G40+'1-2'!G40+'1-3'!G40+'1-4'!G40+'1-5'!G40)/5 -> 2499.2356 | H40: =('1-1'!H40+'1-2'!H40+'1-3'!H40+'1-4'!H40+'1-5'!H40)/5 -> 2465.0667 | I40: =('1-1'!I40+'1-2'!I40+'1-3'!I40+'1-4'!I40+'1-5'!I40)/5 -> 1937.6711 | ... N40: =('1-1'!N40+'1-2'!N40+'1-3'!N40+'1-4'!N40+'1-5'!N40)/5 -> 286.04444
A41: 78 | B41: =('1-1'!B41+'1-2'!B41+'1-3'!B41+'1-4'!B41+'1-5'!B41)/5 -> 964.37333 | C41: =('1-1'!C41+'1-2'!C41+'1-3'!C41+'1-4'!C41+'1-5'!C41)/5 -> 1618.9511 | D41: =('1-1'!D41+'1-2'!D41+'1-3'!D41+'1-4'!D41+'1-5'!D41)/5 -> 1970.9867 | E41: =('1-1'!E41+'1-2'!E41+'1-3'!E41+'1-4'!E41+'1-5'!E41)/5 -> 2049.4933 | F41: =('1-1'!F41+'1-2'!F41+'1-3'!F41+'1-4'!F41+'1-5'!F41)/5 -> 2542.2578 | G41: =('1-1'!G41+'1-2'!G41+'1-3'!G41+'1-4'!G41+'1-5'!G41)/5 -> 2573.12 | H41: =('1-1'!H41+'1-2'!H41+'1-3'!H41+'1-4'!H41+'1-5'!H41)/5 -> 2536.1422 | I41: =('1-1'!I41+'1-2'!I41+'1-3'!I41+'1-4'!I41+'1-5'!I41)/5 -> 2007.2533 | ... N41: =('1-1'!N41+'1-2'!N41+'1-3'!N41+'1-4'!N41+'1-5'!N41)/5 -> 304.60444
A42: 80 | B42: =('1-1'!B42+'1-2'!B42+'1-3'!B42+'1-4'!B42+'1-5'!B42)/5 -> 1028.48 | C42: =('1-1'!C42+'1-2'!C42+'1-3'!C42+'1-4'!C42+'1-5'!C42)/5 -> 1736.6044 | D42: =('1-1'!D42+'1-2'!D42+'1-3'!D42+'1-4'!D42+'1-5'!D42)/5 -> 2093.2622 | E42: =('1-1'!E42+'1-2'!E42+'1-3'!E42+'1-4'!E42+'1-5'!E42)/5 -> 2185.3511 | F42: =('1-1'!F42+'1-2'!F42+'1-3'!F42+'1-4'!F42+'1-5'!F42)/5 -> 2707.8756 | G42: =('1-1'!G42+'1-2'!G42+'1-3'!G42+'1-4'!G42+'1-5'!G42)/5 -> 2750.5422 | H42: =('1-1'!H42+'1-2'!H42+'1-3'!H42+'1-4'!H42+'1-5'!H42)/5 -> 2706.8444 | I42: =('1-1'!I42+'1-2'!I42+'1-3'!I42+'1-4'!I42+'1-5'!I42)/5 -> 2141.9022 | ... N42: =('1-1'!N42+'1-2'!N42+'1-3'!N42+'1-4'!N42+'1-5'!N42)/5 -> 317.19111
... A54: 104 | B54: =('1-1'!B54+'1-2'!B54+'1-3'!B54+'1-4'!B54+'1-5'!B54)/5 -> 1872.2844 | C54: =('1-1'!C54+'1-2'!C54+'1-3'!C54+'1-4'!C54+'1-5'!C54)/5 -> 3085.9378 | D54: =('1-1'!D54+'1-2'!D54+'1-3'!D54+'1-4'!D54+'1-5'!D54)/5 -> 3744.7111 | E54: =('1-1'!E54+'1-2'!E54+'1-3'!E54+'1-4'!E54+'1-5'!E54)/5 -> 3958.1867 | F54: =('1-1'!F54+'1-2'!F54+'1-3'!F54+'1-4'!F54+'1-5'!F54)/5 -> 4848.6044 | G54: =('1-1'!G54+'1-2'!G54+'1-3'!G54+'1-4'!G54+'1-5'!G54)/5 -> 4896.64 | H54: =('1-1'!H54+'1-2'!H54+'1-3'!H54+'1-4'!H54+'1-5'!H54)/5 -> 4898.7022 | I54: =('1-1'!I54+'1-2'!I54+'1-3'!I54+'1-4'!I54+'1-5'!I54)/5 -> 3883.8044 | ... N54: =('1-1'!N54+'1-2'!N54+'1-3'!N54+'1-4'!N54+'1-5'!N54)/5 -> 629.76
A55: 106 | B55: =('1-1'!B55+'1-2'!B55+'1-4'!B55+'1-5'!B55)/4 -> 1965.8667 | C55: =('1-1'!C55+'1-2'!C55+'1-4'!C55+'1-5'!C55)/4 -> 3253.7333 | D55: =('1-1'!D55+'1-2'!D55+'1-4'!D55+'1-5'!D55)/4 -> 3907.4667 | E55: =('1-1'!E55+'1-2'!E55+'1-4'!E55+'1-5'!E55)/4 -> 4169.4667 | F55: =('1-1'!F55+'1-2'!F55+'1-4'!F55+'1-5'!F55)/4 -> 5075.0222 | G55: =('1-1'!G55+'1-2'!G55+'1-4'!G55+'1-5'!G55)/4 -> 5154.7111 | H55: =('1-1'!H55+'1-2'!H55+'1-4'!H55+'1-5'!H55)/4 -> 5151.6444 | I55: =('1-1'!I55+'1-2'!I55+'1-4'!I55+'1-5'!I55)/4 -> 4087.9556 | ... N55: =('1-1'!N55+'1-2'!N55+'1-4'!N55+'1-5'!N55)/4 -> 655.91111
A56: 108 | B56: =('1-1'!B56+'1-2'!B56+'1-3'!B56+'1-4'!B56+'1-5'!B56)/5 -> 2006.7911 | C56: =('1-1'!C56+'1-2'!C56+'1-3'!C56+'1-4'!C56+'1-5'!C56)/5 -> 3312.9956 | D56: =('1-1'!D56+'1-2'!D56+'1-3'!D56+'1-4'!D56+'1-5'!D56)/5 -> 4017.3867 | E56: =('1-1'!E56+'1-2'!E56+'1-3'!E56+'1-4'!E56+'1-5'!E56)/5 -> 4269.44 | F56: =('1-1'!F56+'1-2'!F56+'1-3'!F56+'1-4'!F56+'1-5'!F56)/5 -> 5205.0489 | G56: =('1-1'!G56+'1-2'!G56+'1-3'!G56+'1-4'!G56+'1-5'!G56)/5 -> 5254.8622 | H56: =('1-1'!H56+'1-2'!H56+'1-3'!H56+'1-4'!H56+'1-5'!H56)/5 -> 5276.0178 | I56: =('1-1'!I56+'1-2'!I56+'1-3'!I56+'1-4'!I56+'1-5'!I56)/5 -> 4182.1867 | ... N56: =('1-1'!N56+'1-2'!N56+'1-3'!N56+'1-4'!N56+'1-5'!N56)/5 -> 673.42222
A57: 110 | B57: =('1-1'!B57+'1-3'!B57+'1-4'!B57+'1-5'!B57)/4 -> 2038.2667 | C57: =('1-1'!C57+'1-3'!C57+'1-4'!C57+'1-5'!C57)/4 -> 3378.2667 | D57: =('1-1'!D57+'1-3'!D57+'1-4'!D57+'1-5'!D57)/4 -> 4041.3778 | E57: =('1-1'!E57+'1-3'!E57+'1-4'!E57+'1-5'!E57)/4 -> 4354.6667 | F57: =('1-1'!F57+'1-3'!F57+'1-4'!F57+'1-5'!F57)/4 -> 5274.2222 | G57: =('1-1'!G57+'1-3'!G57+'1-4'!G57+'1-5'!G57)/4 -> 5366.5333 | H57: =('1-1'!H57+'1-3'!H57+'1-4'!H57+'1-5'!H57)/4 -> 5354.0444 | I57: =('1-1'!I57+'1-3'!I57+'1-4'!I57+'1-5'!I57)/4 -> 4262.7556 | ... N57: =('1-1'!N57+'1-3'!N57+'1-4'!N57+'1-5'!N57)/4 -> 682.31111
A58: 112 | B58: =('1-1'!B58+'1-2'!B58+'1-3'!B58+'1-4'!B58+'1-5'!B58)/5 -> 2163.8044 | C58: =('1-1'!C58+'1-2'!C58+'1-3'!C58+'1-4'!C58+'1-5'!C58)/5 -> 3584.5689 | D58: =('1-1'!D58+'1-2'!D58+'1-3'!D58+'1-4'!D58+'1-5'!D58)/5 -> 4347.52 | E58: =('1-1'!E58+'1-2'!E58+'1-3'!E58+'1-4'!E58+'1-5'!E58)/5 -> 4621.0489 | F58: =('1-1'!F58+'1-2'!F58+'1-3'!F58+'1-4'!F58+'1-5'!F58)/5 -> 5634.88 | G58: =('1-1'!G58+'1-2'!G58+'1-3'!G58+'1-4'!G58+'1-5'!G58)/5 -> 5700.2311 | H58: =('1-1'!H58+'1-2'!H58+'1-3'!H58+'1-4'!H58+'1-5'!H58)/5 -> 5715.3778 | I58: =('1-1'!I58+'1-2'!I58+'1-3'!I58+'1-4'!I58+'1-5'!I58)/5 -> 4535.0756 | ... N58: =('1-1'!N58+'1-2'!N58+'1-3'!N58+'1-4'!N58+'1-5'!N58)/5 -> 726.72
A59: 114 | B59: =('1-1'!B59+'1-3'!B59+'1-4'!B59+'1-5'!B59)/4 -> 2242.6667 | C59: =('1-1'!C59+'1-3'!C59+'1-4'!C59+'1-5'!C59)/4 -> 3718.0889 | D59: =('1-1'!D59+'1-3'!D59+'1-4'!D59+'1-5'!D59)/4 -> 4463.4667 | E59: =('1-1'!E59+'1-3'!E59+'1-4'!E59+'1-5'!E59)/4 -> 4784.4 | F59: =('1-1'!F59+'1-3'!F59+'1-4'!F59+'1-5'!F59)/4 -> 5809.3778 | G59: =('1-1'!G59+'1-3'!G59+'1-4'!G59+'1-5'!G59)/4 -> 5909.1111 | H59: =('1-1'!H59+'1-3'!H59+'1-4'!H59+'1-5'!H59)/4 -> 5904.3556 | I59: =('1-1'!I59+'1-3'!I59+'1-4'!I59+'1-5'!I59)/4 -> 4706 | ... N59: =('1-1'!N59+'1-3'!N59+'1-4'!N59+'1-5'!N59)/4 -> 749.11111
A60: 116 | B60: =('1-1'!B60+'1-2'!B60+'1-3'!B60+'1-4'!B60+'1-5'!B60)/5 -> 2409.3511 | C60: =('1-1'!C60+'1-2'!C60+'1-3'!C60+'1-4'!C60+'1-5'!C60)/5 -> 3992.0711 | D60: =('1-1'!D60+'1-2'!D60+'1-3'!D60+'1-4'!D60+'1-5'!D60)/5 -> 4851.2 | E60: =('1-1'!E60+'1-2'!E60+'1-3'!E60+'1-4'!E60+'1-5'!E60)/5 -> 5156.6933 | F60: =('1-1'!F60+'1-2'!F60+'1-3'!F60+'1-4'!F60+'1-5'!F60)/5 -> 6280.6044 | G60: =('1-1'!G60+'1-2'!G60+'1-3'!G60+'1-4'!G60+'1-5'!G60)/5 -> 6356.0889 | H60: =('1-1'!H60+'1-2'!H60+'1-3'!H60+'1-4'!H60+'1-5'!H60)/5 -> 6372.4089 | I60: =('1-1'!I60+'1-2'!I60+'1-3'!I60+'1-4'!I60+'1-5'!I60)/5 -> 5057.7067 | ... N60: =('1-1'!N60+'1-2'!N60+'1-3'!N60+'1-4'!N60+'1-5'!N60)/5 -> 814.75556
A61: 118 | B61: =('1-1'!B61+'1-2'!B61+'1-3'!B61+'1-4'!B61+'1-5'!B61)/5 -> 2444.1244 | C61: =('1-1'!C61+'1-2'!C61+'1-3'!C61+'1-4'!C61+'1-5'!C61)/5 -> 4035.9111 | D61: =('1-1'!D61+'1-2'!D61+'1-3'!D61+'1-4'!D61+'1-5'!D61)/5 -> 4896.1067 | E61: =('1-1'!E61+'1-2'!E61+'1-3'!E61+'1-4'!E61+'1-5'!E61)/5 -> 5209.6711 | F61: =('1-1'!F61+'1-2'!F61+'1-3'!F61+'1-4'!F61+'1-5'!F61)/5 -> 6337.4933 | G61: =('1-1'!G61+'1-2'!G61+'1-3'!G61+'1-4'!G61+'1-5'!G61)/5 -> 6414.5778 | H61: =('1-1'!H61+'1-2'!H61+'1-3'!H61+'1-4'!H61+'1-5'!H61)/5 -> 6438.9333 | I61: =('1-1'!I61+'1-2'!I61+'1-3'!I61+'1-4'!I61+'1-5'!I61)/5 -> 5097.6356 | ... N61: =('1-1'!N61+'1-2'!N61+'1-3'!N61+'1-4'!N61+'1-5'!N61)/5 -> 822.11556
A62: 120 | B62: =('1-1'!B62+'1-2'!B62+'1-3'!B62+'1-4'!B62+'1-5'!B62)/5 -> 2564.0889 | C62: =('1-1'!C62+'1-2'!C62+'1-3'!C62+'1-4'!C62+'1-5'!C62)/5 -> 4222.5067 | D62: =('1-1'!D62+'1-2'!D62+'1-3'!D62+'1-4'!D62+'1-5'!D62)/5 -> 5132.7644 | E62: =('1-1'!E62+'1-2'!E62+'1-3'!E62+'1-4'!E62+'1-5'!E62)/5 -> 5462.6133 | F62: =('1-1'!F62+'1-2'!F62+'1-3'!F62+'1-4'!F62+'1-5'!F62)/5 -> 6655.9644 | G62: =('1-1'!G62+'1-2'!G62+'1-3'!G62+'1-4'!G62+'1-5'!G62)/5 -> 6703.4667 | H62: =('1-1'!H62+'1-2'!H62+'1-3'!H62+'1-4'!H62+'1-5'!H62)/5 -> 6754.0978 | I62: =('1-1'!I62+'1-2'!I62+'1-3'!I62+'1-4'!I62+'1-5'!I62)/5 -> 5330.56 | ... N62: =('1-1'!N62+'1-2'!N62+'1-3'!N62+'1-4'!N62+'1-5'!N62)/5 -> 853.58222
A63: 122 | B63: =('1-1'!B63+'1-2'!B63+'1-3'!B63+'1-4'!B63+'1-5'!B63)/5 -> 2598.8978 | C63: =('1-1'!C63+'1-2'!C63+'1-3'!C63+'1-4'!C63+'1-5'!C63)/5 -> 4297.3511 | D63: =('1-1'!D63+'1-2'!D63+'1-3'!D63+'1-4'!D63+'1-5'!D63)/5 -> 5247.2178 | E63: =('1-1'!E63+'1-2'!E63+'1-3'!E63+'1-4'!E63+'1-5'!E63)/5 -> 5566.3289 | F63: =('1-1'!F63+'1-2'!F63+'1-3'!F63+'1-4'!F63+'1-5'!F63)/5 -> 6783.7867 | G63: =('1-1'!G63+'1-2'!G63+'1-3'!G63+'1-4'!G63+'1-5'!G63)/5 -> 6841.1022 | H63: =('1-1'!H63+'1-2'!H63+'1-3'!H63+'1-4'!H63+'1-5'!H63)/5 -> 6877.1911 | I63: =('1-1'!I63+'1-2'!I63+'1-3'!I63+'1-4'!I63+'1-5'!I63)/5 -> 5453.4756 | ... N63: =('1-1'!N63+'1-2'!N63+'1-3'!N63+'1-4'!N63+'1-5'!N63)/5 -> 875.2
A64: 124 | B64: =('1-1'!B64+'1-2'!B64+'1-3'!B64+'1-4'!B64)/4 -> 2708.0889 | C64: =('1-1'!C64+'1-2'!C64+'1-3'!C64+'1-4'!C64)/4 -> 4482.1333 | D64: =('1-1'!D64+'1-2'!D64+'1-3'!D64+'1-4'!D64)/4 -> 5462.5778 | E64: =('1-1'!E64+'1-2'!E64+'1-3'!E64+'1-4'!E64)/4 -> 5793.7333 | F64: =('1-1'!F64+'1-2'!F64+'1-3'!F64+'1-4'!F64)/4 -> 7084.8 | G64: =('1-1'!G64+'1-2'!G64+'1-3'!G64+'1-4'!G64)/4 -> 7120.8889 | H64: =('1-1'!H64+'1-2'!H64+'1-3'!H64+'1-4'!H64)/4 -> 7152.4 | I64: =('1-1'!I64+'1-2'!I64+'1-3'!I64+'1-4'!I64)/4 -> 5653.0667 | ... N64: =('1-1'!N64+'1-2'!N64+'1-3'!N64+'1-4'!N64)/4 -> 914.66667
A65: 126 | B65: =('1-1'!B65+'1-2'!B65+'1-3'!B65+'1-4'!B65+'1-5'!B65)/5 -> 2768.9244 | C65: =('1-1'!C65+'1-2'!C65+'1-3'!C65+'1-4'!C65+'1-5'!C65)/5 -> 4577.0311 | D65: =('1-1'!D65+'1-2'!D65+'1-3'!D65+'1-4'!D65+'1-5'!D65)/5 -> 5567.5733 | E65: =('1-1'!E65+'1-2'!E65+'1-3'!E65+'1-4'!E65+'1-5'!E65)/5 -> 5932.2667 | F65: =('1-1'!F65+'1-2'!F65+'1-3'!F65+'1-4'!F65+'1-5'!F65)/5 -> 7203.8044 | G65: =('1-1'!G65+'1-2'!G65+'1-3'!G65+'1-4'!G65+'1-5'!G65)/5 -> 7268.9422 | H65: =('1-1'!H65+'1-2'!H65+'1-3'!H65+'1-4'!H65+'1-5'!H65)/5 -> 7302.6489 | I65: =('1-1'!I65+'1-2'!I65+'1-3'!I65+'1-4'!I65+'1-5'!I65)/5 -> 5777.1733 | ... N65: =('1-1'!N65+'1-2'!N65+'1-3'!N65+'1-4'!N65+'1-5'!N65)/5 -> 930.91556
A66: 128 | B66: =('1-1'!B66+'1-2'!B66+'1-3'!B66+'1-4'!B66+'1-5'!B66)/5 -> 2781.2978 | C66: =('1-1'!C66+'1-2'!C66+'1-3'!C66+'1-4'!C66+'1-5'!C66)/5 -> 4586.3467 | D66: =('1-1'!D66+'1-2'!D66+'1-3'!D66+'1-4'!D66+'1-5'!D66)/5 -> 5580.7644 | E66: =('1-1'!E66+'1-2'!E66+'1-3'!E66+'1-4'!E66+'1-5'!E66)/5 -> 5951.1822 | F66: =('1-1'!F66+'1-2'!F66+'1-3'!F66+'1-4'!F66+'1-5'!F66)/5 -> 7236.9778 | G66: =('1-1'!G66+'1-2'!G66+'1-3'!G66+'1-4'!G66+'1-5'!G66)/5 -> 7291.0933 | H66: =('1-1'!H66+'1-2'!H66+'1-3'!H66+'1-4'!H66+'1-5'!H66)/5 -> 7346.88 | I66: =('1-1'!I66+'1-2'!I66+'1-3'!I66+'1-4'!I66+'1-5'!I66)/5 -> 5794.7022 | ... N66: =('1-1'!N66+'1-2'!N66+'1-3'!N66+'1-4'!N66+'1-5'!N66)/5 -> 928.49778
...

Sheet 1-1
A1: GratingPhaseAmplitude | B1: -1035785 | C1: -1035885 | D1: -1035985 | E1: -10351085 | F1: -10351185 | G1: -10351285 | H1: -10351385 | I1: -10351485 | J1: -10351585 | K1: -10351685 | L1: -10351785 | M1: -10351885 | N1: -10351985
A2: 0 | B2: 0 | C2: 0 | D2: 0 | E2: 0 | F2: 0.17777778 | G2: 0 | H2: 0 | I2: 0 | J2: 0 | K2: 0 | L2: 0 | M2: 0 | N2: 0
A3: 2 | B3: 0 | C3: 0.17777778 | D3: 0 | E3: 0 | F3: 0 | G3: 0 | H3: 0 | I3: 0 | J3: 0 | K3: 0 | L3: 0 | M3: 0 | N3: 0
A4: 4 | B4: 0 | C4: 0 | D4: 0 | E4: 0.17777778 | F4: 0 | G4: 0 | H4: 0 | I4: 0 | J4: 0 | K4: 0 | L4: 0.17777778 | M4: 0 | N4: 0.17777778
A5: 6 | B5: 0.35555556 | C5: 0 | D5: 0 | E5: 0 | F5: 0 | G5: 0 | H5: 0.35555556 | I5: 0.17777778 | J5: 0 | K5: 0 | L5: 0 | M5: 0 | N5: 0
A6: 8 | B6: 0 | C6: 0.17777778 | D6: 0 | E6: 0.35555556 | F6: 0.35555556 | G6: 0.17777778 | H6: 0.17777778 | I6: 0 | J6: 0 | K6: 0.17777778 | L6: 0 | M6: 0 | N6: 0
A7: 10 | B7: 0 | C7: 0.17777778 | D7: 0.53333333 | E7: 0 | F7: 0.71111111 | G7: 0.71111111 | H7: 1.6 | I7: 0.71111111 | J7: 0 | K7: 0.53333333 | L7: 0 | M7: 0 | N7: 0
A8: 12 | B8: 0.35555556 | C8: 0.17777778 | D8: 1.6 | E8: 0.17777778 | F8: 1.6 | G8: 4.6222222 | H8: 1.0666667 | I8: 0.53333333 | J8: 0.35555556 | K8: 0.35555556 | L8: 0.17777778 | M8: 0 | N8: 0
A9: 14 | B9: 0.53333333 | C9: 0.71111111 | D9: 1.2444444 | E9: 0.35555556 | F9: 3.7333333 | G9: 3.9111111 | H9: 5.3333333 | I9: 2.3111111 | J9: 0 | K9: 0.35555556 | L9: 0.17777778 | M9: 0 | N9: 0
A10: 16 | B10: 1.2444444 | C10: 3.3777778 | D10: 4.9777778 | E10: 1.9555556 | F10: 6.4 | G10: 9.2444444 | H10: 7.8222222 | I10: 2.8444444 | J10: 1.2444444 | K10: 1.7777778 | L10: 0.17777778 | M10: 0 | N10: 0
A11: 18 | B11: 0.71111111 | C11: 5.6888889 | D11: 5.5111111 | E11: 3.3777778 | F11: 13.866667 | G11: 21.688889 | H11: 12.266667 | I11: 6.9333333 | J11: 4.2666667 | K11: 2.3111111 | L11: 1.0666667 | M11: 0.17777778 | N11: 0.17777778
A12: 20 | B12: 4.9777778 | C12: 4.6222222 | D12: 11.733333 | E12: 4.9777778 | F12: 27.2 | G12: 37.155556 | H12: 29.688889 | I12: 7.1111111 | J12: 2.8444444 | K12: 3.7333333 | L12: 2.4888889 | M12: 0.88888889 | N12: 0
A13: 22 | B13: 4.6222222 | C13: 9.2444444 | D13: 22.755556 | E13: 9.4222222 | F13: 73.777778 | G13: 99.377778 | H13: 72.888889 | I13: 15.466667 | J13: 6.0444444 | K13: 4.2666667 | L13: 3.7333333 | M13: 0.71111111 | N13: 0
... A90: 176 | B90: 4413.3333 | C90: 7188.9778 | D90: 8756.0889 | E90: 9460.9778 | F90: 11387.733 | G90: 11363.556 | H90: 11386.489 | I90: 9076.2667 | J90: 6850.3111 | K90: 6780.8 | L90: 4332.4444 | M90: 2447.4667 | N90: 1421.8667
A91: 178 | B91: 2665.7778 | C91: 4330.8444 | D91: 5219.5556 | E91: 5683.2 | F91: 6805.6889 | G91: 6806.4 | H91: 6798.9333 | I91: 5444.9778 | J91: 4088.3556 | K91: 4067.7333 | L91: 2598.4 | M91: 1458.3111 | N91: 846.75556 | P91: Not considered
A92: 180 | B92: 4702.0444 | C92: 7627.9111 | D92: 9290.6667 | E92: 10045.511 | F92: 12057.6 | G92: 12006.933 | H92: 11973.867 | I92: 9539.7333 | J92: 7209.0667 | K92: 7138.6667 | L92: 4532.4444 | M92: 2560.7111 | N92: 1475.3778
A93: 182 | B93: 4863.6444 | C93: 7886.4 | D93: 9556.0889 | E93: 10373.156 | F93: 12432.356 | G93: 12370.667 | H93: 12324.622 | I93: 9828.6222 | J93: 7398.4 | K93: 7337.7778 | L93: 4665.2444 | M93: 2639.2889 | N93: 1510.4
A94: 184 | B94: 4878.4 | C94: 7914.1333 | D94: 9631.4667 | E94: 10414.756 | F94: 12489.067 | G94: 12369.422 | H94: 12385.244 | I94: 9862.7556 | J94: 7443.9111 | K94: 7360.1778 | L94: 4690.6667 | M94: 2649.4222 | N94: 1515.9111
A95: 186 | B95: 4937.6 | C95: 7994.1333 | D95: 9781.6889 | E95: 10526.222 | F95: 12665.956 | G95: 12533.156 | H95: 12566.044 | I95: 9984.8889 | J95: 7521.7778 | K95: 7440.1778 | L95: 4734.7556 | M95: 2674.3111 | N95: 1553.0667
A96: 188 | B96: 4932.4444 | C96: 7959.8222 | D96: 9728.7111 | E96: 10480 | F96: 12614.222 | G96: 12479.644 | H96: 12459.022 | I96: 9916.8 | J96: 7482.3111 | K96: 7406.0444 | L96: 4699.7333 | M96: 2671.8222 | N96: 1532.2667
A97: 190 | B97: 4819.3778 | C97: 7821.8667 | D97: 9556.9778 | E97: 10356.8 | F97: 12368.711 | G97: 12332.444 | H97: 12265.956 | I97: 9793.2444 | J97: 7369.6 | K97: 7279.2889 | L97: 4632.3556 | M97: 2625.6 | N97: 1512.1778
A98: 192 | B98: 4939.9111 | C98: 7967.6444 | D98: 9797.8667 | E98: 10552.533 | F98: 12623.111 | G98: 12482.133 | H98: 12462.222 | I98: 9905.6 | J98: 7472.1778 | K98: 7382.5778 | L98: 4702.9333 | M98: 2660.0889 | N98: 1525.1556
A99: 194 | B99: 5045.3333 | C99: 8088 | D99: 9971.2 | E99: 10632.356 | F99: 12835.022 | G99: 12635.556 | H99: 12645.156 | I99: 9988.6222 | J99: 7565.1556 | K99: 7472.1778 | L99: 4754.3111 | M99: 2687.8222 | N99: 1551.8222
A100: 196 | B100: 4930.3111 | C100: 7899.2 | D100: 9754.4889 | E100: 10451.022 | F100: 12515.733 | G100: 12361.244 | H100: 12345.244 | I100: 9810.3111 | J100: 7389.8667 | K100: 7321.0667 | L100: 4646.4 | M100: 2632.7111 | N100: 1487.6444
A101: 198 | B101: 5098.3111 | C101: 8223.6444 | D101: 10139.911 | E101: 10859.022 | F101: 13065.778 | G101: 12833.778 | H101: 12824 | I101: 10209.956 | J101: 7664 | K101: 7612.9778 | L101: 4808.8889 | M101: 2719.6444 | N101: 1556.8
A102: 200 | B102: 5203.9111 | C102: 8361.7778 | D102: 10312.178 | E102: 11030.933 | F102: 13261.689 | G102: 13074.667 | H102: 13051.2 | I102: 10326.044 | J102: 7771.3778 | K102: 7694.0444 | L102: 4895.6444 | M102: 2777.9556 | N102: 1584.1778
A103: 202 | B103: 5159.6444 | C103: 8310.2222 | D103: 10233.778 | E103: 10938.133 | F103: 13186.311 | G103: 12890.844 | H103: 12922.133 | I103: 10198.578 | J103: 7694.5778 | K103: 7640.8889 | L103: 4824.1778 | M103: 2740.0889 | N103: 1552
... A126: 248 | B126: 5353.7778 | C126: 8584.1778 | D126: 10913.956 | E126: 11295.822 | F126: 13662.222 | G126: 13032.711 | H126: 13163.378 | I126: 10138.844 | J126: 7779.7333 | K126: 7664 | L126: 4821.6889 | M126: 2772.4444 | N126: 1543.4667

Sheet 1-2
A1: GratingPhaseAmplitude | B1: -1035785 | C1: -1035885 | D1: -1035985 | E1: -10351085 | F1: -10351185 | G1: -10351285 | H1: -10351385 | I1: -10351485 | J1: -10351585 | K1: -10351685 | L1: -10351785 | M1: -10351885 | N1: -10351985
A2: 0 | B2: 0 | C2: 0 | D2: 0 | E2: 0 | F2: 0.35555556 | G2: 0 | H2: 0 | I2: 0 | J2: 0.17777778 | K2: 0 | L2: 0 | M2: 0.71111111 | N2: 0
A3: 2 | B3: 0 | C3: 0 | D3: 0 | E3: 0 | F3: 0 | G3: 0 | H3: 0 | I3: 0 | J3: 0 | K3: 0 | L3: 0 | M3: 0 | N3: 0
A4: 4 | B4: 0.17777778 | C4: 0 | D4: 0.17777778 | E4: 0 | F4: 0.17777778 | G4: 0 | H4: 0 | I4: 0 | J4: 0 | K4: 0 | L4: 0 | M4: 0 | N4: 0
A5: 6 | B5: 0.17777778 | C5: 0 | D5: 0.35555556 | E5: 0 | F5: 0 | G5: 0.35555556 | H5: 0.35555556 | I5: 0 | J5: 0 | K5: 0 | L5: 0 | M5: 0 | N5: 0
A6: 8 | B6: 0 | C6: 0 | D6: 0 | E6: 0 | F6: 0.35555556 | G6: 0 | H6: 0.17777778 | I6: 0.35555556 | J6: 0.17777778 | K6: 0 | L6: 0 | M6: 0 | N6: 0
A7: 10 | B7: 0.17777778 | C7: 0.17777778 | D7: 1.0666667 | E7: 0.17777778 | F7: 2.4888889 | G7: 1.6 | H7: 0.88888889 | I7: 0 | J7: 0.17777778 | K7: 0.53333333 | L7: 0.17777778 | M7: 0.53333333 | N7: 0
A8: 12 | B8: 0.17777778 | C8: 0.17777778 | D8: 0.71111111 | E8: 0.17777778 | F8: 1.7777778 | G8: 0.53333333 | H8: 1.7777778 | I8: 0 | J8: 0.17777778 | K8: 0.53333333 | L8: 0 | M8: 0 | N8: 0
A9: 14 | B9: 0.17777778 | C9: 0.35555556 | D9: 2.4888889 | E9: 0.35555556 | F9: 5.5111111 | G9: 4.2666667 | H9: 5.1555556 | I9: 0.71111111 | J9: 0.35555556 | K9: 0.53333333 | L9: 0.17777778 | M9: 0 | N9: 0
A10: 16 | B10: 1.4222222 | C10: 2.4888889 | D10: 3.7333333 | E10: 3.3777778 | F10: 5.3333333 | G10: 6.0444444 | H10: 4.9777778 | I10: 4.6222222 | J10: 0.88888889 | K10: 1.4222222 | L10: 0.88888889 | M10: 0.17777778 | N10: 0.17777778
A11: 18 | B11: 3.2 | C11: 7.4666667 | D11: 4.9777778 | E11: 4.0888889 | F11: 15.822222 | G11: 17.777778 | H11: 8 | I11: 5.8666667 | J11: 2.6666667 | K11: 4.9777778 | L11: 2.1333333 | M11: 0.71111111 | N11: 0
A12: 20 | B12: 3.2 | C12: 5.5111111 | D12: 9.9555556 | E12: 4.2666667 | F12: 30.577778 | G12: 33.422222 | H12: 20.444444 | I12: 8 | J12: 5.5111111 | K12: 4.4444444 | L12: 5.6888889 | M12: 0.35555556 | N12: 0
A13: 22 | B13: 5.1555556 | C13: 6.0444444 | D13: 32.711111 | E13: 9.7777778 | F13: 95.288889 | G13: 102.75556 | H13: 76.622222 | I13: 17.066667 | J13: 9.9555556 | K13: 6.5777778 | L13: 2.1333333 | M13: 0.53333333 | N13: 0.17777778
... A29: 54 | B29: 427.37778 | C29: 712.17778 | D29: 919.82222 | E29: 871.46667 | F29: 1179.9111 | G29: 1170.3111 | H29: 1150.0444 | I29: 879.64444 | J29: 612.08889 | K29: 656.35556 | L29: 413.68889 | M29: 184.88889 | N29: 109.33333
A30: 56 | B30: 166.57778 | C30: 277.15556 | D30: 355.73333 | E30: 333.86667 | F30: 446.22222 | G30: 446.93333 | H30: 440 | I30: 331.37778 | J30: 235.91111 | K30: 256.53333 | L30: 157.68889 | M30: 72.711111 | N30: 39.288889 | P30: Not considered
A31: 58 | B31: 470.22222 | C31: 764.08889 | D31: 1005.1556 | E31: 951.28889 | F31: 1257.0667 | G31: 1248 | H31: 1219.5556 | I31: 940.62222 | J31: 658.66667 | K31: 700.8 | L31: 453.51111 | M31: 205.15556 | N31: 129.42222
A32: 60 | B32: 522.13333 | C32: 861.51111 | D32: 1103.1111 | E32: 1076.6222 | F32: 1422.5778 | G32: 1392.8889 | H32: 1369.6 | I32: 1065.6 | J32: 744.71111 | K32: 787.2 | L32: 497.95556 | M32: 252.62222 | N32: 137.77778
A33: 62 | B33: 451.02222 | C33: 725.15556 | D33: 956.44444 | E33: 919.28889 | F33: 1218.3111 | G33: 1184 | H33: 1182.2222 | I33: 902.57778 | J33: 638.22222 | K33: 677.86667 | L33: 426.48889 | M33: 228.08889 | N33: 116.62222
A34: 64 | B34: 624 | C34: 1039.2889 | D34: 1304.3556 | E34: 1276.9778 | F34: 1651.0222 | G34: 1665.4222 | H34: 1638.4 | I34: 1244.6222 | J34: 892.97778 | K34: 945.6 | L34: 605.68889 | M34: 309.86667 | N34: 154.48889
A35: 66 | B35: 651.91111 | C35: 1083.3778 | D35: 1357.6889 | E35: 1333.1556 | F35: 1743.6444 | G35: 1726.5778 | H35: 1714.4889 | I35: 1315.0222 | J35: 941.51111 | K35: 998.75556 | L35: 628.8 | M35: 324.97778 | N35: 162.66667
A36: 68 | B36: 700.97778 | C36: 1155.9111 | D36: 1448.5333 | E36: 1441.2444 | F36: 1858.8444 | G36: 1838.7556 | H36: 1822.9333 | I36: 1404.6222 | J36: 1005.3333 | K36: 1085.6889 | L36: 667.2 | M36: 359.82222 | N36: 177.06667
A37: 70 | B37: 779.73333 | C37: 1292.0889 | D37: 1644.2667 | E37: 1632.1778 | F37: 2098.1333 | G37: 2085.3333 | H37: 2055.1111 | I37: 1588.8 | J37: 1145.7778 | K37: 1208.3556 | L37: 766.04444 | M37: 417.77778 | N37: 224.53333
A38: 72 | B38: 829.51111 | C38: 1338.8444 | D38: 1703.4667 | E38: 1723.5556 | F38: 2198.7556 | G38: 2166.2222 | H38: 2139.5556 | I38: 1662.4 | J38: 1196.2667 | K38: 1272.3556 | L38: 794.31111 | M38: 447.82222 | N38: 237.86667
A39: 74 | B39: 825.24444 | C39: 1381.5111 | D39: 1740.4444 | E39: 1755.9111 | F39: 2243.2 | G39: 2217.6 | H39: 2195.5556 | I39: 1708.8 | J39: 1238.2222 | K39: 1301.3333 | L39: 830.57778 | M39: 466.13333 | N39: 253.15556
A40: 76 | B40: 944.53333 | C40: 1576.8889 | D40: 1990.5778 | E40: 1979.2 | F40: 2514.1333 | G40: 2503.8222 | H40: 2492.8 | I40: 1941.8667 | J40: 1424.8889 | K40: 1481.0667 | L40: 929.06667 | M40: 513.24444 | N40: 293.68889
A41: 78 | B41: 975.28889 | C41: 1605.8667 | D41: 2050.6667 | E41: 2036.0889 | F41: 2605.6889 | G41: 2552.3556 | H41: 2551.8222 | I41: 1983.4667 | J41: 1460.2667 | K41: 1547.3778 | L41: 969.42222 | M41: 533.15556 | N41: 308.26667
A42: 80 | B42: 998.22222 | C42: 1653.8667 | D42: 2098.8444 | E42: 2108.0889 | F42: 2678.9333 | G42: 2652.4444 | H42: 2649.7778 | I42: 2051.2 | J42: 1507.9111 | K42: 1586.4889 | L42: 995.2 | M42: 550.75556 | N42: 309.33333
... A56: 108 | B56: 2093.8667 | C56: 3418.8444 | D56: 4340.4444 | E56: 4401.6 | F56: 5506.3111 | G56: 5404.0889 | H56: 5552.3556 | I56: 4296.5333 | J56: 3270.9333 | K56: 3370.1333 | L56: 2138.3111 | M56: 1237.5111 | N56: 707.02222
A57: 110 | B57: 1281.0667 | C57: 2076.4444 | D57: 2626.4889 | E57: 2669.8667 | F57: 3337.7778 | G57: 3323.5556 | H57: 3367.4667 | I57: 2626.4889 | J57: 1985.9556 | K57: 2052.2667 | L57: 1316.9778 | M57: 742.75556 | N57: 425.6 | P57: Not considered
A58: 112 | B58: 2213.3333 | C58: 3614.2222 | D58: 4608.8889 | E58: 4684.6222 | F58: 5845.6889 | G58: 5774.4 | H58: 5873.4222 | I58: 4553.0667 | J58: 3469.3333 | K58: 3577.2444 | L58: 2278.9333 | M58: 1309.8667 | N58: 742.75556
A59: 114 | B59: 1815.2889 | C59: 2954.4889 | D59: 3767.8222 | E59: 3820.9778 | F59: 4785.0667 | G59: 4702.7556 | H59: 4802.6667 | I59: 3715.9111 | J59: 2831.8222 | K59: 2915.3778 | L59: 1854.0444 | M59: 1053.5111 | N59: 597.51111 | P59: Not considered
A60: 116 | B60: 2430.7556 | C60: 3958.5778 | D60: 5052.8 | E60: 5100.8 | F60: 6421.1556 | G60: 6334.9333 | H60: 6465.0667 | I60: 4999.8222 | J60: 3829.5111 | K60: 3908.8 | L60: 2496.1778 | M60: 1423.2889 | N60: 812.26667
A61: 118 | B61: 2488.5333 | C61: 4048.8889 | D61: 5124.6222 | E61: 5227.0222 | F61: 6546.8444 | G61: 6427.2 | H61: 6567.6444 | I61: 5075.3778 | J61: 3909.3333 | K61: 3988.2667 | L61: 2534.9333 | M61: 1454.2222 | N61: 836.97778
A62: 120 | B62: 2561.7778 | C62: 4198.9333 | D62: 5334.7556 | E62: 5455.1111 | F62: 6824 | G62: 6648.1778 | H62: 6858.3111 | I62: 5258.4889 | J62: 4042.4889 | K62: 4139.9111 | L62: 2628.2667 | M62: 1507.7333 | N62: 855.11111
A63: 122 | B63: 2696.3556 | C63: 4421.8667 | D63: 5638.5778 | E63: 5698.3111 | F63: 7164.9778 | G63: 7058.1333 | H63: 7175.1111 | I63: 5571.5556 | J63: 4258.6667 | K63: 4374.7556 | L63: 2771.0222 | M63: 1592 | N63: 911.11111
A64: 124 | B64: 2754.6667 | C64: 4550.4 | D64: 5772.4444 | E64: 5855.4667 | F64: 7347.2 | G64: 7194.6667 | H64: 7332.0889 | I64: 5676.8 | J64: 4356.0889 | K64: 4469.1556 | L64: 2837.8667 | M64: 1618.1333 | N64: 929.24444
A65: 126 | B65: 2707.9111 | C65: 4452.8 | D65: 5668.0889 | E65: 5745.7778 | F65: 7163.3778 | G65: 7051.5556 | H65: 7228.2667 | I65: 5568.7111 | J65: 4289.2444 | K65: 4379.3778 | L65: 2782.7556 | M65: 1596.0889 | N65: 905.24444
A66: 128 | B66: 2883.2 | C66: 4736.1778 | D66: 6019.9111 | E66: 6134.5778 | F66: 7659.5556 | G66: 7503.8222 | H66: 7689.4222 | I66: 5926.5778 | J66: 4557.8667 | K66: 4642.6667 | L66: 2942.9333 | M66: 1694.5778 | N66: 951.82222
A67: 130 | B67: 3011.2 | C67: 4975.2889 | D67: 6322.1333 | E67: 6437.8667 | F67: 8025.9556 | G67: 7894.0444 | H67: 8085.8667 | I67: 6183.2889 | J67: 4809.4222 | K67: 4877.3333 | L67: 3069.1556 | M67: 1790.2222 | N67: 1022.7556
A68: 132 | B68: 2998.0444 | C68: 4940.9778 | D68: 6297.0667 | E68: 6404.4444 | F68: 8028.9778 | G68: 7856.5333 | H68: 8076.9778 | I68: 6176.7111 | J68: 4792.8889 | K68: 4840.1778 | L68: 3088.7111 | M68: 1774.9333 | N68: 1005.6889
...

Sheet 1-3
A1: GratingPhaseAmplitude | B1: -1035785 | C1: -1035885 | D1: -1035985 | E1: -10351085 | F1: -10351185 | G1: -10351285 | H1: -10351385 | I1: -10351485 | J1: -10351585 | K1: -10351685 | L1: -10351785 | M1: -10351885 | N1: -10351985
A2: 0 | B2: 0 | C2: 0 | D2: 0 | E2: 0 | F2: 0.17777778 | G2: 0 | H2: 0 | I2: 0 | J2: 0 | K2: 0 | L2: 0 | M2: 0 | N2: 0
A3: 2 | B3: 0 | C3: 0 | D3: 0 | E3: 0 | F3: 0 | G3: 0 | H3: 0 | I3: 0 | J3: 0 | K3: 0 | L3: 0 | M3: 0 | N3: 0
A4: 4 | B4: 0 | C4: 0 | D4: 0 | E4: 0 | F4: 0 | G4: 0.17777778 | H4: 0 | I4: 0 | J4: 0 | K4: 0 | L4: 0 | M4: 0 | N4: 0
A5: 6 | B5: 0 | C5: 0 | D5: 0 | E5: 0 | F5: 0 | G5: 0.17777778 | H5: 0 | I5: 0.35555556 | J5: 0 | K5: 0 | L5: 0 | M5: 0 | N5: 0
A6: 8 | B6: 0 | C6: 0 | D6: 0.17777778 | E6: 0 | F6: 0.35555556 | G6: 0 | H6: 0.17777778 | I6: 0 | J6: 0.17777778 | K6: 0 | L6: 0 | M6: 0 | N6: 0.17777778
A7: 10 | B7: 0 | C7: 0.53333333 | D7: 0.53333333 | E7: 0 | F7: 1.4222222 | G7: 1.4222222 | H7: 0.88888889 | I7: 0.17777778 | J7: 0 | K7: 0 | L7: 0 | M7: 0 | N7: 0
A8: 12 | B8: 0.17777778 | C8: 0.17777778 | D8: 0.17777778 | E8: 0.17777778 | F8: 0.71111111 | G8: 2.4888889 | H8: 1.4222222 | I8: 1.0666667 | J8: 0.35555556 | K8: 0.17777778 | L8: 0.17777778 | M8: 0 | N8: 0
A9: 14 | B9: 0.53333333 | C9: 0.53333333 | D9: 0.88888889 | E9: 0.35555556 | F9: 5.1555556 | G9: 5.1555556 | H9: 2.1333333 | I9: 1.0666667 | J9: 0.17777778 | K9: 0.35555556 | L9: 0.35555556 | M9: 0.53333333 | N9: 0.35555556
A10: 16 | B10: 0.17777778 | C10: 3.0222222 | D10: 2.3111111 | E10: 1.7777778 | F10: 4.4444444 | G10: 7.2888889 | H10: 9.0666667 | I10: 5.1555556 | J10: 0.88888889 | K10: 1.6 | L10: 0.53333333 | M10: 0.17777778 | N10: 0
A11: 18 | B11: 2.6666667 | C11: 1.2444444 | D11: 4.6222222 | E11: 3.2 | F11: 8.1777778 | G11: 16.355556 | H11: 5.3333333 | I11: 4.4444444 | J11: 1.4222222 | K11: 2.6666667 | L11: 1.6 | M11: 0 | N11: 0
A12: 20 | B12: 2.1333333 | C12: 4.8 | D12: 6.4 | E12: 3.7333333 | F12: 22.577778 | G12: 24.177778 | H12: 21.688889 | I12: 5.8666667 | J12: 3.3777778 | K12: 1.7777778 | L12: 1.0666667 | M12: 0.53333333 | N12: 0
A13: 22 | B13: 5.1555556 | C13: 10.133333 | D13: 20.088889 | E13: 8.1777778 | F13: 69.155556 | G13: 99.555556 | H13: 59.733333 | I13: 18.133333 | J13: 6.2222222 | K13: 6.4 | L13: 3.3777778 | M13: 0.53333333 | N13: 0.35555556
... A54: 104 | B54: 1919.4667 | C54: 3121.0667 | D54: 3857.6 | E54: 4003.2 | F54: 4968.5333 | G54: 4944.3556 | H54: 4972.6222 | I54: 3952 | J54: 2950.7556 | K54: 3016.5333 | L54: 1944 | M54: 1099.9111 | N54: 641.42222
A55: 106 | B55: 769.77778 | C55: 1256.7111 | D55: 1545.6 | E55: 1638.7556 | F55: 2001.2444 | G55: 2010.1333 | H55: 2007.8222 | I55: 1599.6444 | J55: 1196.6222 | K55: 1216.7111 | L55: 783.28889 | M55: 448.35556 | N55: 262.04444 | P55: Not considered
A56: 108 | B56: 1987.2 | C56: 3241.9556 | D56: 4013.1556 | E56: 4209.7778 | F56: 5161.9556 | G56: 5192.8889 | H56: 5208 | I56: 4119.2889 | J56: 3082.4889 | K56: 3192.1778 | L56: 2040 | M56: 1148.4444 | N56: 665.77778
A57: 110 | B57: 2012.2667 | C57: 3271.4667 | D57: 4033.0667 | E57: 4249.7778 | F57: 5208 | G57: 5262.0444 | H57: 5243.3778 | I57: 4160.7111 | J57: 3124.6222 | K57: 3211.0222 | L57: 2049.0667 | M57: 1151.8222 | N57: 670.57778
A58: 112 | B58: 2129.6 | C58: 3466.8444 | D58: 4311.6444 | E58: 4484.4444 | F58: 5520.5333 | G58: 5541.3333 | H58: 5590.0444 | I58: 4419.7333 | J58: 3319.6444 | K58: 3407.1111 | L58: 2190.4 | M58: 1229.8667 | N58: 703.28889
A59: 114 | B59: 2213.8667 | C59: 3550.4 | D59: 4426.6667 | E59: 4600.5333 | F59: 5685.6889 | G59: 5688.5333 | H59: 5695.2889 | I59: 4515.9111 | J59: 3406.4 | K59: 3468.0889 | L59: 2249.2444 | M59: 1253.1556 | N59: 725.86667
A60: 116 | B60: 2390.9333 | C60: 3884.9778 | D60: 4836.9778 | E60: 5047.6444 | F60: 6224.5333 | G60: 6208.7111 | H60: 6250.4889 | I60: 4955.2 | J60: 3709.6889 | K60: 3796.8 | L60: 2451.2 | M60: 1367.8222 | N60: 796.26667
A61: 118 | B61: 2401.4222 | C61: 3903.1111 | D61: 4860.6222 | E61: 5059.2 | F61: 6239.4667 | G61: 6257.4222 | H61: 6289.4222 | I61: 4964.2667 | J61: 3738.4889 | K61: 3857.7778 | L61: 2458.1333 | M61: 1387.3778 | N61: 802.13333
A62: 120 | B62: 2606.4 | C62: 4155.9111 | D62: 5248 | E62: 5426.3111 | F62: 6712.7111 | G62: 6670.7556 | H62: 6712.8889 | I62: 5294.5778 | J62: 4012.4444 | K62: 4109.3333 | L62: 2626.1333 | M62: 1489.2444 | N62: 844.26667
A63: 122 | B63: 2615.2889 | C63: 4237.6889 | D63: 5340.6222 | E63: 5542.7556 | F63: 6781.1556 | G63: 6800.8889 | H63: 6812.8 | I63: 5404.6222 | J63: 4090.4889 | K63: 4165.8667 | L63: 2664.8889 | M63: 1520.7111 | N63: 859.02222
A64: 124 | B64: 2720.1778 | C64: 4342.2222 | D64: 5468.4444 | E64: 5679.8222 | F64: 6992.5333 | G64: 7012.6222 | H64: 7012.6222 | I64: 5518.9333 | J64: 4188.0889 | K64: 4277.6889 | L64: 2725.5111 | M64: 1566.2222 | N64: 892.44444
A65: 126 | B65: 2786.1333 | C65: 4523.3778 | D65: 5700.0889 | E65: 5856.3556 | F65: 7261.6889 | G65: 7211.5556 | H65: 7293.6889 | I65: 5731.7333 | J65: 4343.2889 | K65: 4453.3333 | L65: 2818.4889 | M65: 1605.5111 | N65: 926.04444
A66: 128 | B66: 2852.6222 | C66: 4565.6889 | D66: 5766.0444 | E66: 5956.2667 | F66: 7350.7556 | G66: 7322.3111 | H66: 7396.0889 | I66: 5795.7333 | J66: 4412.2667 | K66: 4491.2 | L66: 2871.1111 | M66: 1633.7778 | N66: 930.13333
A67: 130 | B67: 2931.2 | C67: 4757.8667 | D67: 6033.2444 | E67: 6199.4667 | F67: 7684.9778 | G67: 7632.7111 | H67: 7705.9556 | I67: 6025.9556 | J67: 4590.4 | K67: 4690.1333 | L67: 2989.5111 | M67: 1697.6 | N67: 973.51111
... A117: 230 | B117: 5256.1778 | C117: 8345.7778 | D117: 10450.667 | E117: 11037.333 | F117: 13208 | G117: 12761.422 | H117: 12763.733 | I117: 9939.3778 | J117: 7542.7556 | K117: 7469.5111 | L117: 4685.6889 | M117: 2675.5556 | N117: 1497.6
A118: 232 | B118: 4310.9333 | C118: 6858.8444 | D118: 8561.6 | E118: 9088.1778 | F118: 10839.644 | G118: 10486.4 | H118: 10430.044 | I118: 8171.0222 | J118: 6197.5111 | K118: 6140.0889 | L118: 3841.2444 | M118: 2193.7778 | N118: 1231.8222 | P118: Not considered
A119: 234 | B119: 5422.4 | C119: 8601.4222 | D119: 10717.333 | E119: 11386.133 | F119: 13599.289 | G119: 13177.067 | H119: 13099.2 | I119: 10284.444 | J119: 7810.6667 | K119: 7727.4667 | L119: 4833.9556 | M119: 2760.5333 | N119: 1553.6
A120: 236 | B120: 5490.6667 | C120: 8718.0444 | D120: 10870.4 | E120: 11508.8 | F120: 13779.022 | G120: 13302.578 | H120: 13267.911 | I120: 10335.467 | J120: 7855.1111 | K120: 7782.4 | L120: 4894.0444 | M120: 2781.5111 | N120: 1562.4889
A121: 238 | B121: 5430.7556 | C121: 8611.7333 | D121: 10848.889 | E121: 11393.067 | F121: 13680 | G121: 13206.044 | H121: 13186.489 | I121: 10250.311 | J121: 7839.8222 | K121: 7744 | L121: 4859.7333 | M121: 2767.8222 | N121: 1560.8889
A122: 240 | B122: 5522.4889 | C122: 8780.4444 | D122: 11080.889 | E122: 11571.733 | F122: 13905.067 | G122: 13315.733 | H122: 13348.622 | I122: 10387.556 | J122: 7931.9111 | K122: 7839.1111 | L122: 4909.6889 | M122: 2815.1111 | N122: 1593.4222
A123: 242 | B123: 5589.8667 | C123: 8840 | D123: 11125.156 | E123: 11687.644 | F123: 13981.156 | G123: 13474.133 | H123: 13432 | I123: 10453.511 | J123: 7985.6 | K123: 7883.2 | L123: 4939.7333 | M123: 2814.9333 | N123: 1592.5333
A124: 244 | B124: 5557.3333 | C124: 8819.2 | D124: 11076.8 | E124: 11671.111 | F124: 13923.378 | G124: 13414.4 | H124: 13420.978 | I124: 10414.044 | J124: 7950.2222 | K124: 7852.2667 | L124: 4930.8444 | M124: 2822.7556 | N124: 1591.8222
A125: 246 | B125: 5436.2667 | C125: 8645.5111 | D125: 10910.578 | E125: 11460.8 | F125: 13697.244 | G125: 13189.156 | H125: 13099.556 | I125: 10203.556 | J125: 7764.4444 | K125: 7688.8889 | L125: 4822.5778 | M125: 2758.2222 | N125: 1545.6
A126: 248 | B126: 5475.2 | C126: 8691.3778 | D126: 10872 | E126: 11476.978 | F126: 13687.467 | G126: 13190.933 | H126: 13189.867 | I126: 10274.489 | J126: 7802.6667 | K126: 7727.4667 | L126: 4852.2667 | M126: 2765.6889 | N126: 1544.1778

Sheet 1-4
A1: GratingPhaseAmplitude | B1: -1035785 | C1: -1035885 | D1: -1035985 | E1: -10351085 | F1: -10351185 | G1: -10351285 | H1: -10351385 | I1: -10351485 | J1: -10351585 | K1: -10351685 | L1: -10351785 | M1: -10351885 | N1: -10351985
A2: 0 | B2: 0 | C2: 0 | D2: 0 | E2: 0 | F2: 0 | G2: 0 | H2: 0 | I2: 0 | J2: 0 | K2: 0 | L2: 0 | M2: 0 | N2: 0
A3: 2 | B3: 0 | C3: 0 | D3: 0 | E3: 0 | F3: 0.17777778 | G3: 0 | H3: 0 | I3: 0.17777778 | J3: 0 | K3: 0 | L3: 0.17777778 | M3: 0 | N3: 0
A4: 4 | B4: 0 | C4: 0 | D4: 0 | E4: 0 | F4: 0 | G4: 0.17777778 | H4: 0 | I4: 0 | J4: 0.17777778 | K4: 0 | L4: 0.17777778 | M4: 0 | N4: 0
A5: 6 | B5: 0 | C5: 0 | D5: 0.17777778 | E5: 0 | F5: 0.17777778 | G5: 0 | H5: 0 | I5: 0 | J5: 0 | K5: 0 | L5: 0 | M5: 0 | N5: 0.17777778
A6: 8 | B6: 0 | C6: 0.17777778 | D6: 0.17777778 | E6: 0 | F6: 0.17777778 | G6: 0.35555556 | H6: 0 | I6: 0 | J6: 0 | K6: 0 | L6: 0 | M6: 0 | N6: 0
A7: 10 | B7: 0 | C7: 0.17777778 | D7: 1.4222222 | E7: 0 | F7: 0.71111111 | G7: 1.4222222 | H7: 1.7777778 | I7: 0.17777778 | J7: 0 | K7: 0.35555556 | L7: 0.17777778 | M7: 0.17777778 | N7: 0
A8: 12 | B8: 0.71111111 | C8: 0.71111111 | D8: 0.17777778 | E8: 0.17777778 | F8: 1.4222222 | G8: 2.8444444 | H8: 1.6 | I8: 1.2444444 | J8: 0 | K8: 0.17777778 | L8: 0 | M8: 0 | N8: 0
A9: 14 | B9: 0 | C9: 1.2444444 | D9: 1.7777778 | E9: 0.17777778 | F9: 3.7333333 | G9: 1.7777778 | H9: 3.5555556 | I9: 0.35555556 | J9: 0.53333333 | K9: 0 | L9: 0 | M9: 0 | N9: 0.17777778
A10: 16 | B10: 0.17777778 | C10: 1.7777778 | D10: 1.6 | E10: 1.0666667 | F10: 4.8 | G10: 5.8666667 | H10: 4.2666667 | I10: 1.7777778 | J10: 0.71111111 | K10: 1.6 | L10: 0.17777778 | M10: 0 | N10: 0
A11: 18 | B11: 0.71111111 | C11: 2.6666667 | D11: 7.8222222 | E11: 3.7333333 | F11: 13.511111 | G11: 25.244444 | H11: 14.755556 | I11: 4.0888889 | J11: 1.0666667 | K11: 4.4444444 | L11: 1.7777778 | M11: 0.71111111 | N11: 0.17777778
A12: 20 | B12: 1.9555556 | C12: 3.2 | D12: 6.2222222 | E12: 4.2666667 | F12: 26.311111 | G12: 39.288889 | H12: 21.866667 | I12: 7.4666667 | J12: 3.0222222 | K12: 4.2666667 | L12: 1.7777778 | M12: 0.53333333 | N12: 0.17777778
A13: 22 | B13: 6.7555556 | C13: 14.222222 | D13: 30.577778 | E13: 8 | F13: 72 | G13: 109.15556 | H13: 71.288889 | I13: 23.822222 | J13: 7.2888889 | K13: 4.8 | L13: 7.1111111 | M13: 0.17777778 | N13: 0.35555556
... A78: 152 | B78: 3808.1778 | C78: 6222.0444 | D78: 7478.9333 | E78: 8127.1111 | F78: 9752.8889 | G78: 9842.8444 | H78: 9839.6444 | I78: 7838.0444 | J78: 5910.9333 | K78: 5907.0222 | L78: 3766.2222 | M78: 2136.3556 | N78: 1232.3556
A79: 154 | B79: 2394.8444 | C79: 3931.0222 | D79: 4783.2889 | E79: 5144.3556 | F79: 6237.3333 | G79: 6276.8 | H79: 6280.7111 | I79: 4995.7333 | J79: 3758.0444 | K79: 3764.8 | L79: 2404.4444 | M79: 1364.9778 | N79: 789.33333 | P79: Not considered
A80: 156 | B80: 3955.5556 | C80: 6469.1556 | D80: 7793.9556 | E80: 8477.8667 | F80: 10164.089 | G80: 10230.4 | H80: 10238.756 | I80: 8173.8667 | J80: 6176.1778 | K80: 6146.3111 | L80: 3919.6444 | M80: 2227.2 | N80: 1267.3778
A81: 158 | B81: 4072.5333 | C81: 6582.7556 | D81: 8024.3556 | E81: 8666.8444 | F81: 10456.711 | G81: 10471.289 | H81: 10491.022 | I81: 8346.6667 | J81: 6319.2889 | K81: 6295.1111 | L81: 4021.8667 | M81: 2278.9333 | N81: 1317.8667
A82: 160 | B82: 4088.5333 | C82: 6643.9111 | D82: 8087.6444 | E82: 8770.8444 | F82: 10504.356 | G82: 10545.778 | H82: 10561.778 | I82: 8401.7778 | J82: 6373.1556 | K82: 6325.1556 | L82: 4038.2222 | M82: 2297.4222 | N82: 1307.2
A83: 162 | B83: 4183.2889 | C83: 6775.2889 | D83: 8333.6889 | E83: 8867.9111 | F83: 10730.133 | G83: 10728 | H83: 10751.467 | I83: 8543.8222 | J83: 6496.8889 | K83: 6448.7111 | L83: 4113.0667 | M83: 2315.5556 | N83: 1341.5111
A84: 164 | B84: 4284.4444 | C84: 6886.9333 | D84: 8519.8222 | E84: 9088.1778 | F84: 10997.511 | G84: 10994.844 | H84: 10985.067 | I84: 8701.8667 | J84: 6594.1333 | K84: 6600.7111 | L84: 4201.6 | M84: 2380.6222 | N84: 1366.0444
A85: 166 | B85: 4428.9778 | C85: 7166.2222 | D85: 8715.3778 | E85: 9453.1556 | F85: 11328.533 | G85: 11334.933 | H85: 11278.222 | I85: 8987.9111 | J85: 6800.7111 | K85: 6771.2 | L85: 4300.0889 | M85: 2430.5778 | N85: 1396.2667
A86: 168 | B86: 4442.8444 | C86: 7184.8889 | D86: 8776.7111 | E86: 9475.5556 | F86: 11388.622 | G86: 11413.511 | H86: 11454.4 | I86: 9033.9556 | J86: 6849.4222 | K86: 6818.8444 | L86: 4346.4889 | M86: 2452.8 | N86: 1413.5111
A87: 170 | B87: 4405.3333 | C87: 7070.0444 | D87: 8693.5111 | E87: 9338.3111 | F87: 11279.289 | G87: 11217.067 | H87: 11232.711 | I87: 8890.6667 | J87: 6759.8222 | K87: 6738.6667 | L87: 4267.9111 | M87: 2424.1778 | N87: 1387.7333
A88: 172 | B88: 4484.8 | C88: 7210.4889 | D88: 8882.1333 | E88: 9476.8 | F88: 11453.867 | G88: 11379.733 | H88: 11346.489 | I88: 8987.5556 | J88: 6833.2444 | K88: 6787.7333 | L88: 4302.2222 | M88: 2451.9111 | N88: 1395.9111
A89: 174 | B89: 4631.6444 | C89: 7512.8889 | D89: 9224.7111 | E89: 9891.0222 | F89: 11879.822 | G89: 11834.133 | H89: 11820.978 | I89: 9408.1778 | J89: 7115.3778 | K89: 7072.1778 | L89: 4480.5333 | M89: 2526.2222 | N89: 1452.6222
A90: 176 | B90: 4615.8222 | C90: 7463.4667 | D90: 9153.7778 | E90: 9867.9111 | F90: 11852.267 | G90: 11837.333 | H90: 11839.644 | I90: 9375.1111 | J90: 7081.0667 | K90: 7058.6667 | L90: 4472.5333 | M90: 2533.6889 | N90: 1455.6444
A91: 178 | B91: 4609.4222 | C91: 7465.4222 | D91: 9103.2889 | E91: 9839.6444 | F91: 11831.822 | G91: 11765.689 | H91: 11768.533 | I91: 9317.1556 | J91: 7018.1333 | K91: 7012.0889 | L91: 4440 | M91: 2508.4444 | N91: 1431.4667
... A126: 248 | B126: 5515.5556 | C126: 8750.4 | D126: 10729.422 | E126: 11550.933 | F126: 13674.133 | G126: 13225.778 | H126: 13139.556 | I126: 10356.622 | J126: 7823.4667 | K126: 7721.9556 | L126: 4826.3111 | M126: 2735.8222 | N126: 1547.2

Sheet 1-5
A1: GratingPhaseAmplitude | B1: -1035785 | C1: -1035885 | D1: -1035985 | E1: -10351085 | F1: -10351185 | G1: -10351285 | H1: -10351385 | I1: -10351485 | J1: -10351585 | K1: -10351685 | L1: -10351785 | M1: -10351885 | N1: -10351985
A2: 0 | B2: 0 | C2: 0 | D2: 0 | E2: 0 | F2: 0 | G2: 0 | H2: 0 | I2: 0 | J2: 0 | K2: 0 | L2: 0 | M2: 0 | N2: 0
A3: 2 | B3: 0 | C3: 0 | D3: 0 | E3: 0 | F3: 0 | G3: 0 | H3: 0 | I3: 0 | J3: 0 | K3: 0 | L3: 0 | M3: 0 | N3: 0
A4: 4 | B4: 0 | C4: 0 | D4: 0 | E4: 0 | F4: 0 | G4: 0.17777778 | H4: 0 | I4: 0 | J4: 0.17777778 | K4: 0 | L4: 0 | M4: 0 | N4: 0
A5: 6 | B5: 0 | C5: 0.35555556 | D5: 0 | E5: 0 | F5: 0.17777778 | G5: 0 | H5: 0.17777778 | I5: 0.17777778 | J5: 0 | K5: 0 | L5: 0 | M5: 0 | N5: 0
A6: 8 | B6: 0.17777778 | C6: 0 | D6: 0 | E6: 0 | F6: 0 | G6: 0 | H6: 0.17777778 | I6: 0.35555556 | J6: 0 | K6: 0.35555556 | L6: 0 | M6: 0.17777778 | N6: 0
A7: 10 | B7: 0.53333333 | C7: 0.17777778 | D7: 0.17777778 | E7: 0.17777778 | F7: 1.0666667 | G7: 1.0666667 | H7: 1.0666667 | I7: 0.17777778 | J7: 0 | K7: 0 | L7: 0 | M7: 0 | N7: 0
A8: 12 | B8: 0 | C8: 0.35555556 | D8: 0.35555556 | E8: 0.17777778 | F8: 0.88888889 | G8: 1.6 | H8: 2.4888889 | I8: 0.35555556 | J8: 0.17777778 | K8: 0.17777778 | L8: 0 | M8: 0 | N8: 0
A9: 14 | B9: 0.53333333 | C9: 0.35555556 | D9: 3.0222222 | E9: 0.35555556 | F9: 1.4222222 | G9: 1.0666667 | H9: 1.4222222 | I9: 0.88888889 | J9: 0.35555556 | K9: 0.53333333 | L9: 0 | M9: 0 | N9: 0.35555556
A10: 16 | B10: 0.17777778 | C10: 1.4222222 | D10: 4.8 | E10: 1.2444444 | F10: 7.2888889 | G10: 4.9777778 | H10: 4.9777778 | I10: 1.7777778 | J10: 1.4222222 | K10: 1.6 | L10: 0.71111111 | M10: 0 | N10: 0
A11: 18 | B11: 1.9555556 | C11: 3.3777778 | D11: 8 | E11: 3.3777778 | F11: 10.133333 | G11: 14.4 | H11: 11.377778 | I11: 4.8 | J11: 1.9555556 | K11: 4.0888889 | L11: 1.0666667 | M11: 0 | N11: 0
A12: 20 | B12: 0.88888889 | C12: 3.9111111 | D12: 7.2888889 | E12: 5.1555556 | F12: 11.377778 | G12: 30.4 | H12: 10.666667 | I12: 7.2888889 | J12: 2.8444444 | K12: 1.9555556 | L12: 1.7777778 | M12: 0.17777778 | N12: 0
A13: 22 | B13: 3.3777778 | C13: 7.1111111 | D13: 26.488889 | E13: 7.4666667 | F13: 81.6 | G13: 95.288889 | H13: 62.044444 | I13: 22.755556 | J13: 5.1555556 | K13: 4.8 | L13: 4.2666667 | M13: 0.35555556 | N13: 0
... A63: 122 | B63: 2458.8444 | C63: 4099.7333 | D63: 4856.1778 | E63: 5331.2 | F63: 6360.3556 | G63: 6516.2667 | H63: 6504.5333 | I63: 5188.8 | J63: 3900.6222 | K63: 3959.4667 | L63: 2529.6 | M63: 1422.0444 | N63: 824.35556
A64: 124 | B64: 1073.0667 | C64: 1767.2889 | D64: 2121.4222 | E64: 2299.3778 | F64: 2760.8889 | G64: 2834.4889 | H64: 2824.5333 | I64: 2246.7556 | J64: 1672.8889 | K64: 1697.7778 | L64: 1098.4889 | M64: 614.57778 | N64: 357.86667 | P64: Not considered
A65: 126 | B65: 2757.8667 | C65: 4530.1333 | D65: 5414.5778 | E65: 5946.1333 | F65: 7076.6222 | G65: 7218.1333 | H65: 7170.6667 | I65: 5726.7556 | J65: 4320.8889 | K65: 4360.1778 | L65: 2812.2667 | M65: 1591.2889 | N65: 917.68889
A66: 128 | B66: 2686.5778 | C66: 4456.7111 | D66: 5279.6444 | E66: 5803.5556 | F66: 6890.3111 | G66: 7071.6444 | H66: 7067.9111 | I66: 5608.1778 | J66: 4237.6889 | K66: 4269.8667 | L66: 2746.6667 | M66: 1539.0222 | N66: 892.8
A67: 130 | B67: 2761.2444 | C67: 4582.4 | D67: 5461.5111 | E67: 5971.2 | F67: 7164.8 | G67: 7293.1556 | H67: 7251.9111 | I67: 5790.7556 | J67: 4374.4 | K67: 4401.9556 | L67: 2810.8444 | M67: 1596.8 | N67: 917.15556
A68: 132 | B68: 2806.9333 | C68: 4628.2667 | D68: 5523.2 | E68: 6047.8222 | F68: 7283.9111 | G68: 7409.9556 | H68: 7396.8 | I68: 5860.6222 | J68: 4424.3556 | K68: 4495.1111 | L68: 2911.2889 | M68: 1630.9333 | N68: 929.24444
A69: 134 | B69: 3040.8889 | C69: 5023.8222 | D69: 6027.9111 | E69: 6580.4444 | F69: 7858.4889 | G69: 8012.4444 | H69: 7956.8 | I69: 6365.3333 | J69: 4819.7333 | K69: 4818.1333 | L69: 3097.7778 | M69: 1751.1111 | N69: 1025.6
A70: 136 | B70: 3011.5556 | C70: 4915.2 | D70: 5972.2667 | E70: 6410.6667 | F70: 7763.2 | G70: 7888.1778 | H70: 7872 | I70: 6231.8222 | J70: 4717.6889 | K70: 4772.9778 | L70: 3048.3556 | M70: 1728.1778 | N70: 1006.9333
A71: 138 | B71: 3162.1333 | C71: 5139.3778 | D71: 6230.2222 | E71: 6741.6889 | F71: 8110.0444 | G71: 8208.8889 | H71: 8200 | I71: 6518.4 | J71: 4951.4667 | K71: 4967.8222 | L71: 3175.1111 | M71: 1794.3111 | N71: 1041.2444
A72: 140 | B72: 3265.0667 | C72: 5312.5333 | D72: 6484.0889 | E72: 6961.6 | F72: 8458.8444 | G72: 8486.5778 | H72: 8539.0222 | I72: 6736 | J72: 5105.0667 | K72: 5159.1111 | L72: 3286.5778 | M72: 1869.3333 | N72: 1075.5556
A73: 142 | B73: 3382.0444 | C73: 5501.6889 | D73: 6707.7333 | E73: 7229.1556 | F73: 8717.1556 | G73: 8800.7111 | H73: 8779.3778 | I73: 6981.3333 | J73: 5266.4889 | K73: 5307.0222 | L73: 3414.4 | M73: 1927.4667 | N73: 1108.0889
A74: 144 | B74: 3396.9778 | C74: 5508.9778 | D74: 6702.4 | E74: 7255.2889 | F74: 8728.7111 | G74: 8800 | H74: 8840.1778 | I74: 6960.3556 | J74: 5309.5111 | K74: 5323.0222 | L74: 3395.7333 | M74: 1927.1111 | N74: 1105.9556
A75: 146 | B75: 3580.9778 | C75: 5828.8 | D75: 7096.5333 | E75: 7646.0444 | F75: 9253.1556 | G75: 9308.4444 | H75: 9282.8444 | I75: 7354.8444 | J75: 5588.8 | K75: 5608.7111 | L75: 3580.4444 | M75: 2022.2222 | N75: 1171.5556
A76: 148 | B76: 3480.5333 | C76: 5799.1111 | D76: 6864 | E76: 7604.9778 | F76: 9022.2222 | G76: 9197.8667 | H76: 9183.1111 | I76: 7266.3111 | J76: 5503.6444 | K76: 5492.9778 | L76: 3516.6222 | M76: 1986.3111 | N76: 1133.3333
... A92: 180 | B92: 4774.9333 | C92: 7656.3556 | D92: 9503.1111 | E92: 10155.556 | F92: 12256.889 | G92: 12088.711 | H92: 12090.667 | I92: 9481.6 | J92: 7227.3778 | K92: 7197.3333 | L92: 4539.0222 | M92: 2580.4444 | N92: 1467.2
A93: 182 | B93: 3809.4222 | C93: 6103.4667 | D93: 7603.5556 | E93: 8119.2889 | F93: 9748.8 | G93: 9664.3556 | H93: 9647.6444 | I93: 7606.4 | J93: 5759.6444 | K93: 5763.5556 | L93: 3627.3778 | M93: 2056.7111 | N93: 1173.8667 | P93: Not considered
