Workbook

Sheet modified_average
A1: GratingPhaseAmplitude | B1: -1035785 | C1: -1035885 | D1: -1035985 | E1: -10351085 | F1: -10351185 | G1: -10351285 | H1: -10351385 | I1: -10351485 | J1: -10351585 | K1: -10351685 | L1: -10351785 | M1: -10351885 | N1: -10351985
A2: 0 | B2: =('2-1'!B2+'2-2'!B2+'2-3'!B2+'2-4'!B2+'2-5'!B2)/5 -> 0 | C2: =('2-1'!C2+'2-2'!C2+'2-3'!C2+'2-4'!C2+'2-5'!C2)/5 -> 0 | D2: =('2-1'!D2+'2-2'!D2+'2-3'!D2+'2-4'!D2+'2-5'!D2)/5 -> 0 | E2: =('2-1'!E2+'2-2'!E2+'2-3'!E2+'2-4'!E2+'2-5'!E2)/5 -> 0 | F2: =('2-1'!F2+'2-2'!F2+'2-3'!F2+'2-4'!F2+'2-5'!F2)/5 -> 0 | G2: =('2-1'!G2+'2-2'!G2+'2-3'!G2+'2-4'!G2+'2-5'!G2)/5 -> 0.071111111 | H2: =('2-1'!H2+'2-2'!H2+'2-3'!H2+'2-4'!H2+'2-5'!H2)/5 -> 0 | I2: =('2-1'!I2+'2-2'!I2+'2-3'!I2+'2-4'!I2+'2-5'!I2)/5 -> 0 | ... N2: =('2-1'!N2+'2-2'!N2+'2-3'!N2+'2-4'!N2+'2-5'!N2)/5 -> 0
A3: 2 | B3: =('2-1'!B3+'2-2'!B3+'2-3'!B3+'2-4'!B3+'2-5'!B3)/5 -> 0 | C3: =('2-1'!C3+'2-2'!C3+'2-3'!C3+'2-4'!C3+'2-5'!C3)/5 -> 0 | D3: =('2-1'!D3+'2-2'!D3+'2-3'!D3+'2-4'!D3+'2-5'!D3)/5 -> 0.035555556 | E3: =('2-1'!E3+'2-2'!E3+'2-3'!E3+'2-4'!E3+'2-5'!E3)/5 -> 0.071111111 | F3: =('2-1'!F3+'2-2'!F3+'2-3'!F3+'2-4'!F3+'2-5'!F3)/5 -> 0 | G3: =('2-1'!G3+'2-2'!G3+'2-3'!G3+'2-4'!G3+'2-5'!G3)/5 -> 0.035555556 | H3: =('2-1'!H3+'2-2'!H3+'2-3'!H3+'2-4'!H3+'2-5'!H3)/5 -> 0 | I3: =('2-1'!I3+'2-2'!I3+'2-3'!I3+'2-4'!I3+'2-5'!I3)/5 -> 0 | ... N3: =('2-1'!N3+'2-2'!N3+'2-3'!N3+'2-4'!N3+'2-5'!N3)/5 -> 0.071111111
A4: 4 | B4: =('2-1'!B4+'2-2'!B4+'2-3'!B4+'2-4'!B4+'2-5'!B4)/5 -> 0 | C4: =('2-1'!C4+'2-2'!C4+'2-3'!C4+'2-4'!C4+'2-5'!C4)/5 -> 0.035555556 | D4: =('2-1'!D4+'2-2'!D4+'2-3'!D4+'2-4'!D4+'2-5'!D4)/5 -> 0.035555556 | E4: =('2-1'!E4+'2-2'!E4+'2-3'!E4+'2-4'!E4+'2-5'!E4)/5 -> 0 | F4: =('2-1'!F4+'2-2'!F4+'2-3'!F4+'2-4'!F4+'2-5'!F4)/5 -> 0.071111111 | G4: =('2-1'!G4+'2-2'!G4+'2-3'!G4+'2-4'!G4+'2-5'!G4)/5 -> 0 | H4: =('2-1'!H4+'2-2'!H4+'2-3'!H4+'2-4'!H4+'2-5'!H4)/5 -> 0 | I4: =('2-1'!I4+'2-2'!I4+'2-3'!I4+'2-4'!I4+'2-5'!I4)/5 -> 0.035555556 | ... N4: =('2-1'!N4+'2-2'!N4+'2-3'!N4+'2-4'!N4+'2-5'!N4)/5 -> 0
A5: 6 | B5: =('2-1'!B5+'2-2'!B5+'2-3'!B5+'2-4'!B5+'2-5'!B5)/5 -> 0 | C5: =('2-1'!C5+'2-2'!C5+'2-3'!C5+'2-4'!C5+'2-5'!C5)/5 -> 0.071111111 | D5: =('2-1'!D5+'2-2'!D5+'2-3'!D5+'2-4'!D5+'2-5'!D5)/5 -> 0.10666667 | E5: =('2-1'!E5+'2-2'!E5+'2-3'!E5+'2-4'!E5+'2-5'!E5)/5 -> 0.14222222 | F5: =('2-1'!F5+'2-2'!F5+'2-3'!F5+'2-4'!F5+'2-5'!F5)/5 -> 0.17777778 | G5: =('2-1'!G5+'2-2'!G5+'2-3'!G5+'2-4'!G5+'2-5'!G5)/5 -> 0.39111111 | H5: =('2-1'!H5+'2-2'!H5+'2-3'!H5+'2-4'!H5+'2-5'!H5)/5 -> 0 | I5: =('2-1'!I5+'2-2'!I5+'2-3'!I5+'2-4'!I5+'2-5'!I5)/5 -> 0.035555556 | ... N5: =('2-1'!N5+'2-2'!N5+'2-3'!N5+'2-4'!N5+'2-5'!N5)/5 -> 0
A6: 8 | B6: =('2-1'!B6+'2-2'!B6+'2-3'!B6+'2-4'!B6+'2-5'!B6)/5 -> 0.14222222 | C6: =('2-1'!C6+'2-2'!C6+'2-3'!C6+'2-4'!C6+'2-5'!C6)/5 -> 0.10666667 | D6: =('2-1'!D6+'2-2'!D6+'2-3'!D6+'2-4'!D6+'2-5'!D6)/5 -> 0.67555556 | E6: =('2-1'!E6+'2-2'!E6+'2-3'!E6+'2-4'!E6+'2-5'!E6)/5 -> 0.71111111 | F6: =('2-1'!F6+'2-2'!F6+'2-3'!F6+'2-4'!F6+'2-5'!F6)/5 -> 1.1377778 | G6: =('2-1'!G6+'2-2'!G6+'2-3'!G6+'2-4'!G6+'2-5'!G6)/5 -> 1.2444444 | H6: =('2-1'!H6+'2-2'!H6+'2-3'!H6+'2-4'!H6+'2-5'!H6)/5 -> 0.88888889 | I6: =('2-1'!I6+'2-2'!I6+'2-3'!I6+'2-4'!I6+'2-5'!I6)/5 -> 0.49777778 | ... N6: =('2-1'!N6+'2-2'!N6+'2-3'!N6+'2-4'!N6+'2-5'!N6)/5 -> 0
A7: 10 | B7: =('2-1'!B7+'2-2'!B7+'2-3'!B7+'2-4'!B7+'2-5'!B7)/5 -> 0.17777778 | C7: =('2-1'!C7+'2-2'!C7+'2-3'!C7+'2-4'!C7+'2-5'!C7)/5 -> 0.17777778 | D7: =('2-1'!D7+'2-2'!D7+'2-3'!D7+'2-4'!D7+'2-5'!D7)/5 -> 1.7422222 | E7: =('2-1'!E7+'2-2'!E7+'2-3'!E7+'2-4'!E7+'2-5'!E7)/5 -> 1.3155556 | F7: =('2-1'!F7+'2-2'!F7+'2-3'!F7+'2-4'!F7+'2-5'!F7)/5 -> 1.9555556 | G7: =('2-1'!G7+'2-2'!G7+'2-3'!G7+'2-4'!G7+'2-5'!G7)/5 -> 2.4177778 | H7: =('2-1'!H7+'2-2'!H7+'2-3'!H7+'2-4'!H7+'2-5'!H7)/5 -> 1.3155556 | I7: =('2-1'!I7+'2-2'!I7+'2-3'!I7+'2-4'!I7+'2-5'!I7)/5 -> 0.88888889 | ... N7: =('2-1'!N7+'2-2'!N7+'2-3'!N7+'2-4'!N7+'2-5'!N7)/5 -> 0.071111111
A8: 12 | B8: =('2-1'!B8+'2-2'!B8+'2-3'!B8+'2-4'!B8+'2-5'!B8)/5 -> 0.071111111 | C8: =('2-1'!C8+'2-2'!C8+'2-3'!C8+'2-4'!C8+'2-5'!C8)/5 -> 0.32 | D8: =('2-1'!D8+'2-2'!D8+'2-3'!D8+'2-4'!D8+'2-5'!D8)/5 -> 1.1733333 | E8: =('2-1'!E8+'2-2'!E8+'2-3'!E8+'2-4'!E8+'2-5'!E8)/5 -> 0.88888889 | F8: =('2-1'!F8+'2-2'!F8+'2-3'!F8+'2-4'!F8+'2-5'!F8)/5 -> 1.8133333 | G8: =('2-1'!G8+'2-2'!G8+'2-3'!G8+'2-4'!G8+'2-5'!G8)/5 -> 2.24 | H8: =('2-1'!H8+'2-2'!H8+'2-3'!H8+'2-4'!H8+'2-5'!H8)/5 -> 1.5288889 | I8: =('2-1'!I8+'2-2'!I8+'2-3'!I8+'2-4'!I8+'2-5'!I8)/5 -> 0.92444444 | ... N8: =('2-1'!N8+'2-2'!N8+'2-3'!N8+'2-4'!N8+'2-5'!N8)/5 -> 0.10666667
A9: 14 | B9: =('2-1'!B9+'2-2'!B9+'2-3'!B9+'2-4'!B9+'2-5'!B9)/5 -> 0.81777778 | C9: =('2-1'!C9+'2-2'!C9+'2-3'!C9+'2-4'!C9+'2-5'!C9)/5 -> 1.0666667 | D9: =('2-1'!D9+'2-2'!D9+'2-3'!D9+'2-4'!D9+'2-5'!D9)/5 -> 3.8755556 | E9: =('2-1'!E9+'2-2'!E9+'2-3'!E9+'2-4'!E9+'2-5'!E9)/5 -> 2.7022222 | F9: =('2-1'!F9+'2-2'!F9+'2-3'!F9+'2-4'!F9+'2-5'!F9)/5 -> 3.9822222 | G9: =('2-1'!G9+'2-2'!G9+'2-3'!G9+'2-4'!G9+'2-5'!G9)/5 -> 5.6177778 | H9: =('2-1'!H9+'2-2'!H9+'2-3'!H9+'2-4'!H9+'2-5'!H9)/5 -> 2.6666667 | I9: =('2-1'!I9+'2-2'!I9+'2-3'!I9+'2-4'!I9+'2-5'!I9)/5 -> 1.8488889 | ... N9: =('2-1'!N9+'2-2'!N9+'2-3'!N9+'2-4'!N9+'2-5'!N9)/5 -> 0.10666667
A10: 16 | B10: =('2-1'!B10+'2-2'!B10+'2-3'!B10+'2-4'!B10+'2-5'!B10)/5 -> 1.7066667 | C10: =('2-1'!C10+'2-2'!C10+'2-3'!C10+'2-4'!C10+'2-5'!C10)/5 -> 3.7688889 | D10: =('2-1'!D10+'2-2'!D10+'2-3'!D10+'2-4'!D10+'2-5'!D10)/5 -> 7.9644444 | E10: =('2-1'!E10+'2-2'!E10+'2-3'!E10+'2-4'!E10+'2-5'!E10)/5 -> 6.2577778 | F10: =('2-1'!F10+'2-2'!F10+'2-3'!F10+'2-4'!F10+'2-5'!F10)/5 -> 15.217778 | G10: =('2-1'!G10+'2-2'!G10+'2-3'!G10+'2-4'!G10+'2-5'!G10)/5 -> 19.235556 | H10: =('2-1'!H10+'2-2'!H10+'2-3'!H10+'2-4'!H10+'2-5'!H10)/5 -> 6.0088889 | I10: =('2-1'!I10+'2-2'!I10+'2-3'!I10+'2-4'!I10+'2-5'!I10)/5 -> 5.2977778 | ... N10: =('2-1'!N10+'2-2'!N10+'2-3'!N10+'2-4'!N10+'2-5'!N10)/5 -> 0.035555556
A11: 18 | B11: =('2-1'!B11+'2-2'!B11+'2-3'!B11+'2-4'!B11+'2-5'!B11)/5 -> 3.0222222 | C11: =('2-1'!C11+'2-2'!C11+'2-3'!C11+'2-4'!C11+'2-5'!C11)/5 -> 4.16 | D11: =('2-1'!D11+'2-2'!D11+'2-3'!D11+'2-4'!D11+'2-5'!D11)/5 -> 22.933333 | E11: =('2-1'!E11+'2-2'!E11+'2-3'!E11+'2-4'!E11+'2-5'!E11)/5 -> 13.12 | F11: =('2-1'!F11+'2-2'!F11+'2-3'!F11+'2-4'!F11+'2-5'!F11)/5 -> 37.546667 | G11: =('2-1'!G11+'2-2'!G11+'2-3'!G11+'2-4'!G11+'2-5'!G11)/5 -> 45.688889 | H11: =('2-1'!H11+'2-2'!H11+'2-3'!H11+'2-4'!H11+'2-5'!H11)/5 -> 16.106667 | I11: =('2-1'!I11+'2-2'!I11+'2-3'!I11+'2-4'!I11+'2-5'!I11)/5 -> 9.6 | ... N11: =('2-1'!N11+'2-2'!N11+'2-3'!N11+'2-4'!N11+'2-5'!N11)/5 -> 0.10666667
A12: 20 | B12: =('2-1'!B12+'2-2'!B12+'2-3'!B12+'2-4'!B12+'2-5'!B12)/5 -> 4.7288889 | C12: =('2-1'!C12+'2-2'!C12+'2-3'!C12+'2-4'!C12+'2-5'!C12)/5 -> 11.555556 | D12: =('2-1'!D12+'2-2'!D12+'2-3'!D12+'2-4'!D12+'2-5'!D12)/5 -> 100.83556 | E12: =('2-1'!E12+'2-2'!E12+'2-3'!E12+'2-4'!E12+'2-5'!E12)/5 -> 87.004444 | F12: =('2-1'!F12+'2-2'!F12+'2-3'!F12+'2-4'!F12+'2-5'!F12)/5 -> 106.24 | G12: =('2-1'!G12+'2-2'!G12+'2-3'!G12+'2-4'!G12+'2-5'!G12)/5 -> 113.74222 | H12: =('2-1'!H12+'2-2'!H12+'2-3'!H12+'2-4'!H12+'2-5'!H12)/5 -> 89.92 | I12: =('2-1'!I12+'2-2'!I12+'2-3'!I12+'2-4'!I12+'2-5'!I12)/5 -> 59.2 | ... N12: =('2-1'!N12+'2-2'!N12+'2-3'!N12+'2-4'!N12+'2-5'!N12)/5 -> 0.39111111
A13: 22 | B13: =('2-1'!B13+'2-2'!B13+'2-3'!B13+'2-4'!B13+'2-5'!B13)/5 -> 4.3377778 | C13: =('2-1'!C13+'2-2'!C13+'2-3'!C13+'2-4'!C13+'2-5'!C13)/5 -> 14.186667 | D13: =('2-1'!D13+'2-2'!D13+'2-3'!D13+'2-4'!D13+'2-5'!D13)/5 -> 103.14667 | E13: =('2-1'!E13+'2-2'!E13+'2-3'!E13+'2-4'!E13+'2-5'!E13)/5 -> 88.177778 | F13: =('2-1'!F13+'2-2'!F13+'2-3'!F13+'2-4'!F13+'2-5'!F13)/5 -> 111.46667 | G13: =('2-1'!G13+'2-2'!G13+'2-3'!G13+'2-4'!G13+'2-5'!G13)/5 -> 120.21333 | H13: =('2-1'!H13+'2-2'!H13+'2-3'!H13+'2-4'!H13+'2-5'!H13)/5 -> 102.22222 | I13: =('2-1'!I13+'2-2'!I13+'2-3'!I13+'2-4'!I13+'2-5'!I13)/5 -> 73.671111 | ... N13: =('2-1'!N13+'2-2'!N13+'2-3'!N13+'2-4'!N13+'2-5'!N13)/5 -> 0.39111111
... A31: 58 | B31: =('2-1'!B31+'2-2'!B31+'2-3'!B31+'2-4'!B31+'2-5'!B31)/5 -> 342.86222 | C31: =('2-1'!C31+'2-2'!C31+'2-3'!C31+'2-4'!C31+'2-5'!C31)/5 -> 549.26222 | D31: =('2-1'!D31+'2-2'!D31+'2-3'!D31+'2-4'!D31+'2-5'!D31)/5 -> 972.26667 | E31: =('2-1'!E31+'2-2'!E31+'2-3'!E31+'2-4'!E31+'2-5'!E31)/5 -> 854.29333 | F31: =('2-1'!F31+'2-2'!F31+'2-3'!F31+'2-4'!F31+'2-5'!F31)/5 -> 1021.3333 | G31: =('2-1'!G31+'2-2'!G31+'2-3'!G31+'2-4'!G31+'2-5'!G31)/5 -> 1053.4044 | H31: =('2-1'!H31+'2-2'!H31+'2-3'!H31+'2-4'!H31+'2-5'!H31)/5 -> 989.44 | I31: =('2-1'!I31+'2-2'!I31+'2-3'!I31+'2-4'!I31+'2-5'!I31)/5 -> 862.64889 | ... N31: =('2-1'!N31+'2-2'!N31+'2-3'!N31+'2-4'!N31+'2-5'!N31)/5 -> 87.857778
A32: 60 | B32: =('2-1'!B32+'2-3'!B32+'2-4'!B32+'2-5'!B32)/4 -> 369.28889 | C32: =('2-1'!C32+'2-3'!C32+'2-4'!C32+'2-5'!C32)/4 -> 584.53333 | D32: =('2-1'!D32+'2-3'!D32+'2-4'!D32+'2-5'!D32)/4 -> 1028.6667 | E32: =('2-1'!E32+'2-3'!E32+'2-4'!E32+'2-5'!E32)/4 -> 890.44444 | F32: =('2-1'!F32+'2-3'!F32+'2-4'!F32+'2-5'!F32)/4 -> 1062.8889 | G32: =('2-1'!G32+'2-3'!G32+'2-4'!G32+'2-5'!G32)/4 -> 1087.4667 | H32: =('2-1'!H32+'2-3'!H32+'2-4'!H32+'2-5'!H32)/4 -> 1022.4889 | I32: =('2-1'!I32+'2-3'!I32+'2-4'!I32+'2-5'!I32)/4 -> 899.86667 | ... N32: =('2-1'!N32+'2-3'!N32+'2-4'!N32+'2-5'!N32)/4 -> 98.311111
A33: 62 | B33: =('2-1'!B33+'2-2'!B33+'2-3'!B33+'2-4'!B33+'2-5'!B33)/5 -> 363.66222 | C33: =('2-1'!C33+'2-2'!C33+'2-3'!C33+'2-4'!C33+'2-5'!C33)/5 -> 571.41333 | D33: =('2-1'!D33+'2-2'!D33+'2-3'!D33+'2-4'!D33+'2-5'!D33)/5 -> 1011.9111 | E33: =('2-1'!E33+'2-2'!E33+'2-3'!E33+'2-4'!E33+'2-5'!E33)/5 -> 882.24 | F33: =('2-1'!F33+'2-2'!F33+'2-3'!F33+'2-4'!F33+'2-5'!F33)/5 -> 1062.5778 | G33: =('2-1'!G33+'2-2'!G33+'2-3'!G33+'2-4'!G33+'2-5'!G33)/5 -> 1080.1067 | H33: =('2-1'!H33+'2-2'!H33+'2-3'!H33+'2-4'!H33+'2-5'!H33)/5 -> 1039.1111 | I33: =('2-1'!I33+'2-2'!I33+'2-3'!I33+'2-4'!I33+'2-5'!I33)/5 -> 904.03556 | ... N33: =('2-1'!N33+'2-2'!N33+'2-3'!N33+'2-4'!N33+'2-5'!N33)/5 -> 97.6
A34: 64 | B34: =('2-1'!B34+'2-2'!B34+'2-3'!B34+'2-4'!B34+'2-5'!B34)/5 -> 430.93333 | C34: =('2-1'!C34+'2-2'!C34+'2-3'!C34+'2-4'!C34+'2-5'!C34)/5 -> 650.56 | D34: =('2-1'!D34+'2-2'!D34+'2-3'!D34+'2-4'!D34+'2-5'!D34)/5 -> 1152.3556 | E34: =('2-1'!E34+'2-2'!E34+'2-3'!E34+'2-4'!E34+'2-5'!E34)/5 -> 1019.4133 | F34: =('2-1'!F34+'2-2'!F34+'2-3'!F34+'2-4'!F34+'2-5'!F34)/5 -> 1201.7422 | G34: =('2-1'!G34+'2-2'!G34+'2-3'!G34+'2-4'!G34+'2-5'!G34)/5 -> 1235.6267 | H34: =('2-1'!H34+'2-2'!H34+'2-3'!H34+'2-4'!H34+'2-5'!H34)/5 -> 1185.9911 | I34: =('2-1'!I34+'2-2'!I34+'2-3'!I34+'2-4'!I34+'2-5'!I34)/5 -> 1028.4444 | ... N34: =('2-1'!N34+'2-2'!N34+'2-3'!N34+'2-4'!N34+'2-5'!N34)/5 -> 121.84889
A35: 66 | B35: =('2-1'!B35+'2-2'!B35+'2-3'!B35+'2-4'!B35+'2-5'!B35)/5 -> 408.74667 | C35: =('2-1'!C35+'2-2'!C35+'2-3'!C35+'2-4'!C35+'2-5'!C35)/5 -> 618.24 | D35: =('2-1'!D35+'2-2'!D35+'2-3'!D35+'2-4'!D35+'2-5'!D35)/5 -> 1087.5378 | E35: =('2-1'!E35+'2-2'!E35+'2-3'!E35+'2-4'!E35+'2-5'!E35)/5 -> 958.79111 | F35: =('2-1'!F35+'2-2'!F35+'2-3'!F35+'2-4'!F35+'2-5'!F35)/5 -> 1141.2622 | G35: =('2-1'!G35+'2-2'!G35+'2-3'!G35+'2-4'!G35+'2-5'!G35)/5 -> 1160.2844 | H35: =('2-1'!H35+'2-2'!H35+'2-3'!H35+'2-4'!H35+'2-5'!H35)/5 -> 1106.4889 | I35: =('2-1'!I35+'2-2'!I35+'2-3'!I35+'2-4'!I35+'2-5'!I35)/5 -> 983.28889 | ... N35: =('2-1'!N35+'2-2'!N35+'2-3'!N35+'2-4'!N35+'2-5'!N35)/5 -> 111.64444
A36: 68 | B36: =('2-1'!B36+'2-2'!B36+'2-3'!B36+'2-4'!B36+'2-5'!B36)/5 -> 452.05333 | C36: =('2-1'!C36+'2-2'!C36+'2-3'!C36+'2-4'!C36+'2-5'!C36)/5 -> 677.29778 | D36: =('2-1'!D36+'2-2'!D36+'2-3'!D36+'2-4'!D36+'2-5'!D36)/5 -> 1191.2533 | E36: =('2-1'!E36+'2-2'!E36+'2-3'!E36+'2-4'!E36+'2-5'!E36)/5 -> 1046.2222 | F36: =('2-1'!F36+'2-2'!F36+'2-3'!F36+'2-4'!F36+'2-5'!F36)/5 -> 1253.3689 | G36: =('2-1'!G36+'2-2'!G36+'2-3'!G36+'2-4'!G36+'2-5'!G36)/5 -> 1276.2667 | H36: =('2-1'!H36+'2-2'!H36+'2-3'!H36+'2-4'!H36+'2-5'!H36)/5 -> 1223.1467 | I36: =('2-1'!I36+'2-2'!I36+'2-3'!I36+'2-4'!I36+'2-5'!I36)/5 -> 1086.8267 | ... N36: =('2-1'!N36+'2-2'!N36+'2-3'!N36+'2-4'!N36+'2-5'!N36)/5 -> 126.22222
A37: 70 | B37: =('2-1'!B37+'2-2'!B37+'2-3'!B37+'2-4'!B37+'2-5'!B37)/5 -> 471.07556 | C37: =('2-1'!C37+'2-2'!C37+'2-3'!C37+'2-4'!C37+'2-5'!C37)/5 -> 719.85778 | D37: =('2-1'!D37+'2-2'!D37+'2-3'!D37+'2-4'!D37+'2-5'!D37)/5 -> 1271.7867 | E37: =('2-1'!E37+'2-2'!E37+'2-3'!E37+'2-4'!E37+'2-5'!E37)/5 -> 1128.3556 | F37: =('2-1'!F37+'2-2'!F37+'2-3'!F37+'2-4'!F37+'2-5'!F37)/5 -> 1331.8044 | G37: =('2-1'!G37+'2-2'!G37+'2-3'!G37+'2-4'!G37+'2-5'!G37)/5 -> 1350.6489 | H37: =('2-1'!H37+'2-2'!H37+'2-3'!H37+'2-4'!H37+'2-5'!H37)/5 -> 1317.76 | I37: =('2-1'!I37+'2-2'!I37+'2-3'!I37+'2-4'!I37+'2-5'!I37)/5 -> 1152.4978 | ... N37: =('2-1'!N37+'2-2'!N37+'2-3'!N37+'2-4'!N37+'2-5'!N37)/5 -> 134.04444
A38: 72 | B38: =('2-1'!B38+'2-2'!B38+'2-3'!B38+'2-4'!B38+'2-5'!B38)/5 -> 505.31556 | C38: =('2-1'!C38+'2-2'!C38+'2-3'!C38+'2-4'!C38+'2-5'!C38)/5 -> 766.86222 | D38: =('2-1'!D38+'2-2'!D38+'2-3'!D38+'2-4'!D38+'2-5'!D38)/5 -> 1351.2533 | E38: =('2-1'!E38+'2-2'!E38+'2-3'!E38+'2-4'!E38+'2-5'!E38)/5 -> 1195.4133 | F38: =('2-1'!F38+'2-2'!F38+'2-3'!F38+'2-4'!F38+'2-5'!F38)/5 -> 1423.6089 | G38: =('2-1'!G38+'2-2'!G38+'2-3'!G38+'2-4'!G38+'2-5'!G38)/5 -> 1449.4933 | H38: =('2-1'!H38+'2-2'!H38+'2-3'!H38+'2-4'!H38+'2-5'!H38)/5 -> 1392.0356 | I38: =('2-1'!I38+'2-2'!I38+'2-3'!I38+'2-4'!I38+'2-5'!I38)/5 -> 1231.1467 | ... N38: =('2-1'!N38+'2-2'!N38+'2-3'!N38+'2-4'!N38+'2-5'!N38)/5 -> 141.86667
A39: 74 | B39: =('2-1'!B39+'2-2'!B39+'2-3'!B39+'2-4'!B39+'2-5'!B39)/5 -> 477.12 | C39: =('2-1'!C39+'2-2'!C39+'2-3'!C39+'2-4'!C39+'2-5'!C39)/5 -> 722.56 | D39: =('2-1'!D39+'2-2'!D39+'2-3'!D39+'2-4'!D39+'2-5'!D39)/5 -> 1280.4622 | E39: =('2-1'!E39+'2-2'!E39+'2-3'!E39+'2-4'!E39+'2-5'!E39)/5 -> 1129.4578 | F39: =('2-1'!F39+'2-2'!F39+'2-3'!F39+'2-4'!F39+'2-5'!F39)/5 -> 1341.2978 | G39: =('2-1'!G39+'2-2'!G39+'2-3'!G39+'2-4'!G39+'2-5'!G39)/5 -> 1364.5156 | H39: =('2-1'!H39+'2-2'!H39+'2-3'!H39+'2-4'!H39+'2-5'!H39)/5 -> 1340.7289 | I39: =('2-1'!I39+'2-2'!I39+'2-3'!I39+'2-4'!I39+'2-5'!I39)/5 -> 1172.1244 | ... N39: =('2-1'!N39+'2-2'!N39+'2-3'!N39+'2-4'!N39+'2-5'!N39)/5 -> 133.47556
A40: 76 | B40: =('2-1'!B40+'2-2'!B40+'2-3'!B40+'2-4'!B40+'2-5'!B40)/5 -> 540.37333 | C40: =('2-1'!C40+'2-2'!C40+'2-3'!C40+'2-4'!C40+'2-5'!C40)/5 -> 809.77778 | D40: =('2-1'!D40+'2-2'!D40+'2-3'!D40+'2-4'!D40+'2-5'!D40)/5 -> 1426.2044 | E40: =('2-1'!E40+'2-2'!E40+'2-3'!E40+'2-4'!E40+'2-5'!E40)/5 -> 1253.5111 | F40: =('2-1'!F40+'2-2'!F40+'2-3'!F40+'2-4'!F40+'2-5'!F40)/5 -> 1488.7822 | G40: =('2-1'!G40+'2-2'!G40+'2-3'!G40+'2-4'!G40+'2-5'!G40)/5 -> 1524.9067 | H40: =('2-1'!H40+'2-2'!H40+'2-3'!H40+'2-4'!H40+'2-5'!H40)/5 -> 1497.4933 | I40: =('2-1'!I40+'2-2'!I40+'2-3'!I40+'2-4'!I40+'2-5'!I40)/5 -> 1305.8844 | ... N40: =('2-1'!N40+'2-2'!N40+'2-3'!N40+'2-4'!N40+'2-5'!N40)/5 -> 146.09778
A41: 78 | B41: =('2-1'!B41+'2-2'!B41+'2-3'!B41+'2-4'!B41)/4 -> 534.57778 | C41: =('2-1'!C41+'2-2'!C41+'2-3'!C41+'2-4'!C41)/4 -> 808.62222 | D41: =('2-1'!D41+'2-2'!D41+'2-3'!D41+'2-4'!D41)/4 -> 1422.8889 | E41: =('2-1'!E41+'2-2'!E41+'2-3'!E41+'2-4'!E41)/4 -> 1252.6667 | F41: =('2-1'!F41+'2-2'!F41+'2-3'!F41+'2-4'!F41)/4 -> 1503.2 | G41: =('2-1'!G41+'2-2'!G41+'2-3'!G41+'2-4'!G41)/4 -> 1524.8444 | H41: =('2-1'!H41+'2-2'!H41+'2-3'!H41+'2-4'!H41)/4 -> 1478.4444 | I41: =('2-1'!I41+'2-2'!I41+'2-3'!I41+'2-4'!I41)/4 -> 1304.5333 | ... N41: =('2-1'!N41+'2-2'!N41+'2-3'!N41+'2-4'!N41)/4 -> 143.73333
A42: 80 | B42: =('2-1'!B42+'2-2'!B42+'2-3'!B42+'2-4'!B42+'2-5'!B42)/5 -> 526.36444 | C42: =('2-1'!C42+'2-2'!C42+'2-3'!C42+'2-4'!C42+'2-5'!C42)/5 -> 800.07111 | D42: =('2-1'!D42+'2-2'!D42+'2-3'!D42+'2-4'!D42+'2-5'!D42)/5 -> 1414.2933 | E42: =('2-1'!E42+'2-2'!E42+'2-3'!E42+'2-4'!E42+'2-5'!E42)/5 -> 1245.1556 | F42: =('2-1'!F42+'2-2'!F42+'2-3'!F42+'2-4'!F42+'2-5'!F42)/5 -> 1471.5378 | G42: =('2-1'!G42+'2-2'!G42+'2-3'!G42+'2-4'!G42+'2-5'!G42)/5 -> 1497.5289 | H42: =('2-1'!H42+'2-2'!H42+'2-3'!H42+'2-4'!H42+'2-5'!H42)/5 -> 1460.8 | I42: =('2-1'!I42+'2-2'!I42+'2-3'!I42+'2-4'!I42+'2-5'!I42)/5 -> 1279.0044 | ... N42: =('2-1'!N42+'2-2'!N42+'2-3'!N42+'2-4'!N42+'2-5'!N42)/5 -> 141.58222
A43: 82 | B43: =('2-1'!B43+'2-2'!B43+'2-3'!B43+'2-4'!B43+'2-5'!B43)/5 -> 479.60889 | C43: =('2-1'!C43+'2-2'!C43+'2-3'!C43+'2-4'!C43+'2-5'!C43)/5 -> 720.46222 | D43: =('2-1'!D43+'2-2'!D43+'2-3'!D43+'2-4'!D43+'2-5'!D43)/5 -> 1270.5778 | E43: =('2-1'!E43+'2-2'!E43+'2-3'!E43+'2-4'!E43+'2-5'!E43)/5 -> 1139.9111 | F43: =('2-1'!F43+'2-2'!F43+'2-3'!F43+'2-4'!F43+'2-5'!F43)/5 -> 1331.8756 | G43: =('2-1'!G43+'2-2'!G43+'2-3'!G43+'2-4'!G43+'2-5'!G43)/5 -> 1352.4978 | H43: =('2-1'!H43+'2-2'!H43+'2-3'!H43+'2-4'!H43+'2-5'!H43)/5 -> 1327.4667 | I43: =('2-1'!I43+'2-2'!I43+'2-3'!I43+'2-4'!I43+'2-5'!I43)/5 -> 1158.2933 | ... N43: =('2-1'!N43+'2-2'!N43+'2-3'!N43+'2-4'!N43+'2-5'!N43)/5 -> 127.18222
A44: 84 | B44: =('2-1'!B44+'2-2'!B44+'2-3'!B44+'2-4'!B44+'2-5'!B44)/5 -> 543.85778 | C44: =('2-1'!C44+'2-2'!C44+'2-3'!C44+'2-4'!C44+'2-5'!C44)/5 -> 817.84889 | D44: =('2-1'!D44+'2-2'!D44+'2-3'!D44+'2-4'!D44+'2-5'!D44)/5 -> 1439.2889 | E44: =('2-1'!E44+'2-2'!E44+'2-3'!E44+'2-4'!E44+'2-5'!E44)/5 -> 1272.2489 | F44: =('2-1'!F44+'2-2'!F44+'2-3'!F44+'2-4'!F44+'2-5'!F44)/5 -> 1488.2489 | G44: =('2-1'!G44+'2-2'!G44+'2-3'!G44+'2-4'!G44+'2-5'!G44)/5 -> 1533.5467 | H44: =('2-1'!H44+'2-2'!H44+'2-3'!H44+'2-4'!H44+'2-5'!H44)/5 -> 1509.0133 | I44: =('2-1'!I44+'2-2'!I44+'2-3'!I44+'2-4'!I44+'2-5'!I44)/5 -> 1312.5333 | ... N44: =('2-1'!N44+'2-2'!N44+'2-3'!N44+'2-4'!N44+'2-5'!N44)/5 -> 141.33333
A45: 86 | B45: =('2-1'!B45+'2-2'!B45+'2-3'!B45+'2-4'!B45+'2-5'!B45)/5 -> 600.28444 | C45: =('2-1'!C45+'2-2'!C45+'2-3'!C45+'2-4'!C45+'2-5'!C45)/5 -> 894.25778 | D45: =('2-1'!D45+'2-2'!D45+'2-3'!D45+'2-4'!D45+'2-5'!D45)/5 -> 1573.2622 | E45: =('2-1'!E45+'2-2'!E45+'2-3'!E45+'2-4'!E45+'2-5'!E45)/5 -> 1385.7067 | F45: =('2-1'!F45+'2-2'!F45+'2-3'!F45+'2-4'!F45+'2-5'!F45)/5 -> 1650.6667 | G45: =('2-1'!G45+'2-2'!G45+'2-3'!G45+'2-4'!G45+'2-5'!G45)/5 -> 1679.2533 | H45: =('2-1'!H45+'2-2'!H45+'2-3'!H45+'2-4'!H45+'2-5'!H45)/5 -> 1641.1733 | I45: =('2-1'!I45+'2-2'!I45+'2-3'!I45+'2-4'!I45+'2-5'!I45)/5 -> 1431.7156 | ... N45: =('2-1'!N45+'2-2'!N45+'2-3'!N45+'2-4'!N45+'2-5'!N45)/5 -> 149.72444
A46: 88 | B46: =('2-1'!B46+'2-2'!B46+'2-3'!B46+'2-4'!B46+'2-5'!B46)/5 -> 637.01333 | C46: =('2-1'!C46+'2-2'!C46+'2-3'!C46+'2-4'!C46+'2-5'!C46)/5 -> 948.26667 | D46: =('2-1'!D46+'2-2'!D46+'2-3'!D46+'2-4'!D46+'2-5'!D46)/5 -> 1679.8933 | E46: =('2-1'!E46+'2-2'!E46+'2-3'!E46+'2-4'!E46+'2-5'!E46)/5 -> 1484.0533 | F46: =('2-1'!F46+'2-2'!F46+'2-3'!F46+'2-4'!F46+'2-5'!F46)/5 -> 1753.7067 | G46: =('2-1'!G46+'2-2'!G46+'2-3'!G46+'2-4'!G46+'2-5'!G46)/5 -> 1781.1556 | H46: =('2-1'!H46+'2-2'!H46+'2-3'!H46+'2-4'!H46+'2-5'!H46)/5 -> 1751.0756 | I46: =('2-1'!I46+'2-2'!I46+'2-3'!I46+'2-4'!I46+'2-5'!I46)/5 -> 1522.3111 | ... N46: =('2-1'!N46+'2-2'!N46+'2-3'!N46+'2-4'!N46+'2-5'!N46)/5 -> 156.51556
A47: 90 | B47: =('2-1'!B47+'2-2'!B47+'2-3'!B47+'2-4'!B47)/4 -> 617.91111 | C47: =('2-1'!C47+'2-2'!C47+'2-3'!C47+'2-4'!C47)/4 -> 926.26667 | D47: =('2-1'!D47+'2-2'!D47+'2-3'!D47+'2-4'!D47)/4 -> 1649.4222 | E47: =('2-1'!E47+'2-2'!E47+'2-3'!E47+'2-4'!E47)/4 -> 1459.1111 | F47: =('2-1'!F47+'2-2'!F47+'2-3'!F47+'2-4'!F47)/4 -> 1714.5778 | G47: =('2-1'!G47+'2-2'!G47+'2-3'!G47+'2-4'!G47)/4 -> 1733.5111 | H47: =('2-1'!H47+'2-2'!H47+'2-3'!H47+'2-4'!H47)/4 -> 1718 | I47: =('2-1'!I47+'2-2'!I47+'2-3'!I47+'2-4'!I47)/4 -> 1489.4667 | ... N47: =('2-1'!N47+'2-2'!N47+'2-3'!N47+'2-4'!N47)/4 -> 150.57778
A48: 92 | B48: =('2-1'!B48+'2-2'!B48+'2-3'!B48+'2-4'!B48+'2-5'!B48)/5 -> 622.86222 | C48: =('2-1'!C48+'2-2'!C48+'2-3'!C48+'2-4'!C48+'2-5'!C48)/5 -> 943.85778 | D48: =('2-1'!D48+'2-2'!D48+'2-3'!D48+'2-4'!D48+'2-5'!D48)/5 -> 1663.6089 | E48: =('2-1'!E48+'2-2'!E48+'2-3'!E48+'2-4'!E48+'2-5'!E48)/5 -> 1468.3022 | F48: =('2-1'!F48+'2-2'!F48+'2-3'!F48+'2-4'!F48+'2-5'!F48)/5 -> 1721.5289 | G48: =('2-1'!G48+'2-2'!G48+'2-3'!G48+'2-4'!G48+'2-5'!G48)/5 -> 1764.3378 | H48: =('2-1'!H48+'2-2'!H48+'2-3'!H48+'2-4'!H48+'2-5'!H48)/5 -> 1742.08 | I48: =('2-1'!I48+'2-2'!I48+'2-3'!I48+'2-4'!I48+'2-5'!I48)/5 -> 1512.2489 | ... N48: =('2-1'!N48+'2-2'!N48+'2-3'!N48+'2-4'!N48+'2-5'!N48)/5 -> 152.35556
A49: 94 | B49: =('2-1'!B49+'2-2'!B49+'2-3'!B49+'2-4'!B49+'2-5'!B49)/5 -> 585.99111 | C49: =('2-1'!C49+'2-2'!C49+'2-3'!C49+'2-4'!C49+'2-5'!C49)/5 -> 874.66667 | D49: =('2-1'!D49+'2-2'!D49+'2-3'!D49+'2-4'!D49+'2-5'!D49)/5 -> 1556.4444 | E49: =('2-1'!E49+'2-2'!E49+'2-3'!E49+'2-4'!E49+'2-5'!E49)/5 -> 1371.2356 | F49: =('2-1'!F49+'2-2'!F49+'2-3'!F49+'2-4'!F49+'2-5'!F49)/5 -> 1607.8222 | G49: =('2-1'!G49+'2-2'!G49+'2-3'!G49+'2-4'!G49+'2-5'!G49)/5 -> 1640.64 | H49: =('2-1'!H49+'2-2'!H49+'2-3'!H49+'2-4'!H49+'2-5'!H49)/5 -> 1635.7689 | I49: =('2-1'!I49+'2-2'!I49+'2-3'!I49+'2-4'!I49+'2-5'!I49)/5 -> 1416.4978 | ... N49: =('2-1'!N49+'2-2'!N49+'2-3'!N49+'2-4'!N49+'2-5'!N49)/5 -> 144.39111
A50: 96 | B50: =('2-2'!B50+'2-3'!B50+'2-4'!B50)/3 -> 620.44444 | C50: =('2-2'!C50+'2-3'!C50+'2-4'!C50)/3 -> 925.62963 | D50: =('2-2'!D50+'2-3'!D50+'2-4'!D50)/3 -> 1641.2444 | E50: =('2-2'!E50+'2-3'!E50+'2-4'!E50)/3 -> 1439.763 | F50: =('2-2'!F50+'2-3'!F50+'2-4'!F50)/3 -> 1701.0963 | G50: =('2-2'!G50+'2-3'!G50+'2-4'!G50)/3 -> 1737.0074 | H50: =('2-2'!H50+'2-3'!H50+'2-4'!H50)/3 -> 1732.2074 | I50: =('2-2'!I50+'2-3'!I50+'2-4'!I50)/3 -> 1505.7778 | ... N50: =('2-2'!N50+'2-3'!N50+'2-4'!N50)/3 -> 149.15556
A51: 98 | B51: =('2-1'!B51+'2-2'!B51+'2-3'!B51+'2-4'!B51+'2-5'!B51)/5 -> 564.23111 | C51: =('2-1'!C51+'2-2'!C51+'2-3'!C51+'2-4'!C51+'2-5'!C51)/5 -> 840.32 | D51: =('2-1'!D51+'2-2'!D51+'2-3'!D51+'2-4'!D51+'2-5'!D51)/5 -> 1496.7111 | E51: =('2-1'!E51+'2-2'!E51+'2-3'!E51+'2-4'!E51+'2-5'!E51)/5 -> 1318.8978 | F51: =('2-1'!F51+'2-2'!F51+'2-3'!F51+'2-4'!F51+'2-5'!F51)/5 -> 1545.1022 | G51: =('2-1'!G51+'2-2'!G51+'2-3'!G51+'2-4'!G51+'2-5'!G51)/5 -> 1576.9956 | H51: =('2-1'!H51+'2-2'!H51+'2-3'!H51+'2-4'!H51+'2-5'!H51)/5 -> 1583.7156 | I51: =('2-1'!I51+'2-2'!I51+'2-3'!I51+'2-4'!I51+'2-5'!I51)/5 -> 1360.2133 | ... N51: =('2-1'!N51+'2-2'!N51+'2-3'!N51+'2-4'!N51+'2-5'!N51)/5 -> 139.16444
A52: 100 | B52: =('2-1'!B52+'2-2'!B52+'2-3'!B52+'2-4'!B52)/4 -> 621.55556 | C52: =('2-1'!C52+'2-2'!C52+'2-3'!C52+'2-4'!C52)/4 -> 929.82222 | D52: =('2-1'!D52+'2-2'!D52+'2-3'!D52+'2-4'!D52)/4 -> 1668.6667 | E52: =('2-1'!E52+'2-2'!E52+'2-3'!E52+'2-4'!E52)/4 -> 1446.1778 | F52: =('2-1'!F52+'2-2'!F52+'2-3'!F52+'2-4'!F52)/4 -> 1709.0222 | G52: =('2-1'!G52+'2-2'!G52+'2-3'!G52+'2-4'!G52)/4 -> 1734.4 | H52: =('2-1'!H52+'2-2'!H52+'2-3'!H52+'2-4'!H52)/4 -> 1741.7778 | I52: =('2-1'!I52+'2-2'!I52+'2-3'!I52+'2-4'!I52)/4 -> 1505.1111 | ... N52: =('2-1'!N52+'2-2'!N52+'2-3'!N52+'2-4'!N52)/4 -> 143.37778
A53: 102 | B53: =('2-1'!B53+'2-2'!B53+'2-3'!B53+'2-4'!B53+'2-5'!B53)/5 -> 569.95556 | C53: =('2-1'!C53+'2-2'!C53+'2-3'!C53+'2-4'!C53+'2-5'!C53)/5 -> 854.54222 | D53: =('2-1'!D53+'2-2'!D53+'2-3'!D53+'2-4'!D53+'2-5'!D53)/5 -> 1529.3511 | E53: =('2-1'!E53+'2-2'!E53+'2-3'!E53+'2-4'!E53+'2-5'!E53)/5 -> 1338.88 | F53: =('2-1'!F53+'2-2'!F53+'2-3'!F53+'2-4'!F53+'2-5'!F53)/5 -> 1569.8133 | G53: =('2-1'!G53+'2-2'!G53+'2-3'!G53+'2-4'!G53+'2-5'!G53)/5 -> 1595.3067 | H53: =('2-1'!H53+'2-2'!H53+'2-3'!H53+'2-4'!H53+'2-5'!H53)/5 -> 1593.9556 | I53: =('2-1'!I53+'2-2'!I53+'2-3'!I53+'2-4'!I53+'2-5'!I53)/5 -> 1373.7244 | ... N53: =('2-1'!N53+'2-2'!N53+'2-3'!N53+'2-4'!N53+'2-5'!N53)/5 -> 133.93778
A54: 104 | B54: =('2-1'!B54+'2-2'!B54+'2-3'!B54+'2-4'!B54+'2-5'!B54)/5 -> 591.92889 | C54: =('2-1'!C54+'2-2'!C54+'2-3'!C54+'2-4'!C54+'2-5'!C54)/5 -> 890.88 | D54: =('2-1'!D54+'2-2'!D54+'2-3'!D54+'2-4'!D54+'2-5'!D54)/5 -> 1579.0933 | E54: =('2-1'!E54+'2-2'!E54+'2-3'!E54+'2-4'!E54+'2-5'!E54)/5 -> 1385.3511 | F54: =('2-1'!F54+'2-2'!F54+'2-3'!F54+'2-4'!F54+'2-5'!F54)/5 -> 1630.6844 | G54: =('2-1'!G54+'2-2'!G54+'2-3'!G54+'2-4'!G54+'2-5'!G54)/5 -> 1651.8756 | H54: =('2-1'!H54+'2-2'!H54+'2-3'!H54+'2-4'!H54+'2-5'!H54)/5 -> 1646.6844 | I54: =('2-1'!I54+'2-2'!I54+'2-3'!I54+'2-4'!I54+'2-5'!I54)/5 -> 1412.7644 | ... N54: =('2-1'!N54+'2-2'!N54+'2-3'!N54+'2-4'!N54+'2-5'!N54)/5 -> 138.56
A55: 106 | B55: =('2-1'!B55+'2-2'!B55+'2-3'!B55+'2-4'!B55+'2-5'!B55)/5 -> 573.26222 | C55: =('2-1'!C55+'2-2'!C55+'2-3'!C55+'2-4'!C55+'2-5'!C55)/5 -> 869.68889 | D55: =('2-1'!D55+'2-2'!D55+'2-3'!D55+'2-4'!D55+'2-5'!D55)/5 -> 1540.3022 | E55: =('2-1'!E55+'2-2'!E55+'2-3'!E55+'2-4'!E55+'2-5'!E55)/5 -> 1352.6756 | F55: =('2-1'!F55+'2-2'!F55+'2-3'!F55+'2-4'!F55+'2-5'!F55)/5 -> 1581.5467 | G55: =('2-1'!G55+'2-2'!G55+'2-3'!G55+'2-4'!G55+'2-5'!G55)/5 -> 1603.7689 | H55: =('2-1'!H55+'2-2'!H55+'2-3'!H55+'2-4'!H55+'2-5'!H55)/5 -> 1613.7956 | I55: =('2-1'!I55+'2-2'!I55+'2-3'!I55+'2-4'!I55+'2-5'!I55)/5 -> 1374.5067 | ... N55: =('2-1'!N55+'2-2'!N55+'2-3'!N55+'2-4'!N55+'2-5'!N55)/5 -> 134.89778
A56: 108 | B56: =('2-1'!B56+'2-2'!B56+'2-3'!B56+'2-4'!B56+'2-5'!B56)/5 -> 571.16444 | C56: =('2-1'!C56+'2-2'!C56+'2-3'!C56+'2-4'!C56+'2-5'!C56)/5 -> 849.13778 | D56: =('2-1'!D56+'2-2'!D56+'2-3'!D56+'2-4'!D56+'2-5'!D56)/5 -> 1506.3467 | E56: =('2-1'!E56+'2-2'!E56+'2-3'!E56+'2-4'!E56+'2-5'!E56)/5 -> 1321.4578 | F56: =('2-1'!F56+'2-2'!F56+'2-3'!F56+'2-4'!F56+'2-5'!F56)/5 -> 1554.4178 | G56: =('2-1'!G56+'2-2'!G56+'2-3'!G56+'2-4'!G56+'2-5'!G56)/5 -> 1570.8089 | H56: =('2-1'!H56+'2-2'!H56+'2-3'!H56+'2-4'!H56+'2-5'!H56)/5 -> 1574.6133 | I56: =('2-1'!I56+'2-2'!I56+'2-3'!I56+'2-4'!I56+'2-5'!I56)/5 -> 1353.4222 | ... N56: =('2-1'!N56+'2-2'!N56+'2-3'!N56+'2-4'!N56+'2-5'!N56)/5 -> 128.35556
A57: 110 | B57: =('2-1'!B57+'2-2'!B57+'2-3'!B57+'2-4'!B57+'2-5'!B57)/5 -> 557.51111 | C57: =('2-1'!C57+'2-2'!C57+'2-3'!C57+'2-4'!C57+'2-5'!C57)/5 -> 831.11111 | D57: =('2-1'!D57+'2-2'!D57+'2-3'!D57+'2-4'!D57+'2-5'!D57)/5 -> 1463.8933 | E57: =('2-1'!E57+'2-2'!E57+'2-3'!E57+'2-4'!E57+'2-5'!E57)/5 -> 1308.3378 | F57: =('2-1'!F57+'2-2'!F57+'2-3'!F57+'2-4'!F57+'2-5'!F57)/5 -> 1507.4844 | G57: =('2-1'!G57+'2-2'!G57+'2-3'!G57+'2-4'!G57+'2-5'!G57)/5 -> 1546.3467 | H57: =('2-1'!H57+'2-2'!H57+'2-3'!H57+'2-4'!H57+'2-5'!H57)/5 -> 1537.92 | I57: =('2-1'!I57+'2-2'!I57+'2-3'!I57+'2-4'!I57+'2-5'!I57)/5 -> 1322.24 | ... N57: =('2-1'!N57+'2-2'!N57+'2-3'!N57+'2-4'!N57+'2-5'!N57)/5 -> 123.02222
...

Sheet 2-1
A1: GratingPhaseAmplitude | B1: -1430800 | C1: -1430900 | D1: -14301000 | E1: -14301100 | F1: -14301200 | G1: -14301300 | H1: -14301400 | I1: -14301500 | J1: -14301600 | K1: -14301700 | L1: -14301800 | M1: -14301900 | N1: -14302000
A2: 0 | B2: 0 | C2: 0 | D2: 0 | E2: 0 | F2: 0 | G2: 0 | H2: 0 | I2: 0 | J2: 0 | K2: 0 | L2: 0 | M2: 0.35555556 | N2: 0
A3: 2 | B3: 0 | C3: 0 | D3: 0 | E3: 0 | F3: 0 | G3: 0 | H3: 0 | I3: 0 | J3: 0 | K3: 0 | L3: 0.17777778 | M3: 0 | N3: 0
A4: 4 | B4: 0 | C4: 0 | D4: 0.17777778 | E4: 0 | F4: 0 | G4: 0 | H4: 0 | I4: 0 | J4: 0 | K4: 0 | L4: 0 | M4: 0.17777778 | N4: 0
A5: 6 | B5: 0 | C5: 0 | D5: 0 | E5: 0 | F5: 0.17777778 | G5: 0.35555556 | H5: 0 | I5: 0 | J5: 0 | K5: 0 | L5: 0 | M5: 0.53333333 | N5: 0
A6: 8 | B6: 0 | C6: 0 | D6: 0.35555556 | E6: 1.4222222 | F6: 1.2444444 | G6: 1.0666667 | H6: 1.6 | I6: 0.35555556 | J6: 0.17777778 | K6: 0 | L6: 0 | M6: 0 | N6: 0
A7: 10 | B7: 0.35555556 | C7: 0.35555556 | D7: 1.9555556 | E7: 0.71111111 | F7: 1.7777778 | G7: 2.3111111 | H7: 2.6666667 | I7: 0.35555556 | J7: 0.88888889 | K7: 0.53333333 | L7: 0 | M7: 0.17777778 | N7: 0
A8: 12 | B8: 0.17777778 | C8: 0.35555556 | D8: 1.2444444 | E8: 0.53333333 | F8: 1.4222222 | G8: 2.4888889 | H8: 1.7777778 | I8: 0.53333333 | J8: 1.2444444 | K8: 0.53333333 | L8: 0.35555556 | M8: 0 | N8: 0
A9: 14 | B9: 1.2444444 | C9: 1.7777778 | D9: 5.3333333 | E9: 2.1333333 | F9: 1.9555556 | G9: 6.4 | H9: 1.4222222 | I9: 1.2444444 | J9: 3.2 | K9: 0.88888889 | L9: 0.88888889 | M9: 0 | N9: 0
A10: 16 | B10: 1.9555556 | C10: 3.0222222 | D10: 11.2 | E10: 4.0888889 | F10: 17.777778 | G10: 19.377778 | H10: 6.5777778 | I10: 3.9111111 | J10: 4.6222222 | K10: 4.6222222 | L10: 0.88888889 | M10: 0.17777778 | N10: 0
A11: 18 | B11: 2.8444444 | C11: 6.7555556 | D11: 14.577778 | E11: 9.9555556 | F11: 32.355556 | G11: 36.977778 | H11: 11.733333 | I11: 8.3555556 | J11: 6.2222222 | K11: 4.9777778 | L11: 1.0666667 | M11: 0.71111111 | N11: 0.17777778
A12: 20 | B12: 6.7555556 | C12: 19.733333 | D12: 122.48889 | E12: 119.82222 | F12: 125.15556 | G12: 140.08889 | H12: 102.22222 | I12: 78.933333 | J12: 66.488889 | K12: 10.844444 | L12: 5.1555556 | M12: 2.1333333 | N12: 0.71111111
A13: 22 | B13: 4.6222222 | C13: 23.288889 | D13: 130.48889 | E13: 116.44444 | F13: 129.95556 | G13: 144.17778 | H13: 128.17778 | I13: 86.755556 | J13: 84.088889 | K13: 13.866667 | L13: 4.9777778 | M13: 1.0666667 | N13: 0.88888889
... A49: 94 | B49: 631.28889 | C49: 924.44444 | D49: 1663.4667 | E49: 1475.7333 | F49: 1705.0667 | G49: 1744.7111 | H49: 1725.3333 | I49: 1510.2222 | J49: 1259.7333 | K49: 867.02222 | L49: 523.37778 | M49: 318.93333 | N49: 150.4
A50: 96 | B50: 363.55556 | C50: 563.55556 | D50: 971.91111 | E50: 844.62222 | F50: 990.22222 | G50: 993.42222 | H50: 1048.3556 | I50: 903.64444 | J50: 749.86667 | K50: 534.75556 | L50: 309.86667 | M50: 187.55556 | N50: 86.933333 | P50: Not considered
A51: 98 | B51: 564.97778 | C51: 809.77778 | D51: 1473.2444 | E51: 1296.8889 | F51: 1513.9556 | G51: 1574.4 | H51: 1545.6 | I51: 1344.5333 | J51: 1116.6222 | K51: 785.77778 | L51: 478.4 | M51: 276.62222 | N51: 139.02222
A52: 100 | B52: 526.04444 | C52: 761.6 | D52: 1385.6 | E52: 1217.0667 | F52: 1413.5111 | G52: 1452.9778 | H52: 1426.1333 | I52: 1236.2667 | J52: 1039.1111 | K52: 727.11111 | L52: 435.55556 | M52: 265.77778 | N52: 116.26667
A53: 102 | B53: 598.04444 | C53: 869.15556 | D53: 1578.3111 | E53: 1387.9111 | F53: 1600 | G53: 1658.6667 | H53: 1635.0222 | I53: 1405.6889 | J53: 1152.1778 | K53: 824.17778 | L53: 498.66667 | M53: 277.86667 | N53: 137.77778
A54: 104 | B54: 626.66667 | C54: 929.42222 | D54: 1654.5778 | E54: 1434.1333 | F54: 1690.4889 | G54: 1731.3778 | H54: 1692.9778 | I54: 1489.0667 | J54: 1213.1556 | K54: 846.22222 | L54: 487.64444 | M54: 290.48889 | N54: 142.75556
A55: 106 | B55: 617.6 | C55: 896.35556 | D55: 1633.2444 | E55: 1429.5111 | F55: 1651.7333 | G55: 1687.2889 | H55: 1700.6222 | I55: 1456.3556 | J55: 1197.8667 | K55: 829.33333 | L55: 493.33333 | M55: 286.22222 | N55: 145.06667
A56: 108 | B56: 616.17778 | C56: 891.91111 | D56: 1611.2 | E56: 1393.9556 | F56: 1671.4667 | G56: 1688 | H56: 1700.8 | I56: 1443.9111 | J56: 1190.2222 | K56: 833.06667 | L56: 485.33333 | M56: 281.77778 | N56: 135.64444
A57: 110 | B57: 579.91111 | C57: 839.82222 | D57: 1531.9111 | E57: 1359.2889 | F57: 1573.3333 | G57: 1584.5333 | H57: 1577.9556 | I57: 1365.3333 | J57: 1118.9333 | K57: 779.2 | L57: 447.64444 | M57: 253.68889 | N57: 123.55556
A58: 112 | B58: 539.2 | C58: 818.31111 | D58: 1457.2444 | E58: 1259.7333 | F58: 1484.8 | G58: 1481.6 | H58: 1492.8 | I58: 1302.2222 | J58: 1069.8667 | K58: 739.37778 | L58: 409.6 | M58: 227.91111 | N58: 116.97778
A59: 114 | B59: 591.11111 | C59: 892.44444 | D59: 1548.2667 | E59: 1370.4889 | F59: 1609.0667 | G59: 1592 | H59: 1635.2 | I59: 1361.2444 | J59: 1118.4 | K59: 776.71111 | L59: 461.51111 | M59: 251.2 | N59: 126.04444
A60: 116 | B60: 544.71111 | C60: 810.13333 | D60: 1454.9333 | E60: 1254.5778 | F60: 1465.7778 | G60: 1477.3333 | H60: 1504.5333 | I60: 1263.4667 | J60: 1030.2222 | K60: 691.37778 | L60: 384.88889 | M60: 206.04444 | N60: 104.53333
A61: 118 | B61: 537.42222 | C61: 818.84444 | D61: 1405.5111 | E61: 1270.2222 | F61: 1454.9333 | G61: 1477.5111 | H61: 1491.7333 | I61: 1296 | J61: 1018.1333 | K61: 684.62222 | L61: 385.42222 | M61: 203.55556 | N61: 102.75556
A62: 120 | B62: 519.28889 | C62: 766.4 | D62: 1372.0889 | E62: 1217.4222 | F62: 1384.8889 | G62: 1387.7333 | H62: 1426.6667 | I62: 1215.1111 | J62: 961.06667 | K62: 660.62222 | L62: 360 | M62: 185.24444 | N62: 88.711111
... A119: 234 | B119: 1691.9111 | C119: 2928.1778 | D119: 4506.8444 | E119: 4193.2444 | F119: 5297.0667 | G119: 5359.6444 | H119: 5314.6667 | I119: 4636.0889 | J119: 4335.6444 | K119: 2978.6667 | L119: 1829.1556 | M119: 1155.0222 | N119: 677.51111
A120: 236 | B120: 2388.0889 | C120: 3960.7111 | D120: 6256 | E120: 5750.4 | F120: 7289.0667 | G120: 7289.7778 | H120: 7018.3111 | I120: 6316.2667 | J120: 5716.2667 | K120: 4031.1111 | L120: 2499.3778 | M120: 1563.3778 | N120: 934.4 | P120: Not considered
A121: 238 | B121: 2041.2444 | C121: 3406.4 | D121: 5379.5556 | E121: 4956.2667 | F121: 6195.7333 | G121: 6284.0889 | H121: 6027.3778 | I121: 5463.1111 | J121: 5020.2667 | K121: 3422.9333 | L121: 2141.1556 | M121: 1336.5333 | N121: 793.06667
A122: 240 | B122: 2271.2889 | C122: 3688.3556 | D122: 5816 | E122: 5358.5778 | F122: 6787.9111 | G122: 6873.2444 | H122: 6598.0444 | I122: 5904.8889 | J122: 5382.9333 | K122: 3772.0889 | L122: 2351.2889 | M122: 1443.3778 | N122: 870.93333
A123: 242 | B123: 2220.4444 | C123: 3689.6 | D123: 5826.4889 | E123: 5319.4667 | F123: 6705.2444 | G123: 6761.2444 | H123: 6542.5778 | I123: 5860.9778 | J123: 5327.6444 | K123: 3699.0222 | L123: 2302.4 | M123: 1432 | N123: 864.88889
A124: 244 | B124: 2338.3111 | C124: 3877.3333 | D124: 6077.5111 | E124: 5579.0222 | F124: 7043.3778 | G124: 7065.7778 | H124: 6871.2889 | I124: 6112.8889 | J124: 5532.0889 | K124: 3844.8 | L124: 2413.5111 | M124: 1499.7333 | N124: 876.8
A125: 246 | B125: 1541.1556 | C125: 2565.6889 | D125: 4009.6 | E125: 3663.8222 | F125: 4604.6222 | G125: 4644.8 | H125: 4481.7778 | I125: 4018.3111 | J125: 3587.5556 | K125: 2534.7556 | L125: 1587.2 | M125: 984.53333 | N125: 594.84444 | P125: Not considered
A126: 248 | B126: 2757.6889 | C126: 4667.2 | D126: 7185.0667 | E126: 6665.2444 | F126: 8256.1778 | G126: 8308.4444 | H126: 8102.7556 | I126: 7158.5778 | J126: 6527.6444 | K126: 4530.1333 | L126: 2811.9111 | M126: 1767.8222 | N126: 1060.2667

Sheet 2-2
A1: GratingPhaseAmplitude | B1: -1430800 | C1: -1430900 | D1: -14301000 | E1: -14301100 | F1: -14301200 | G1: -14301300 | H1: -14301400 | I1: -14301500 | J1: -14301600 | K1: -14301700 | L1: -14301800 | M1: -14301900 | N1: -14302000
A2: 0 | B2: 0 | C2: 0 | D2: 0 | E2: 0 | F2: 0 | G2: 0.17777778 | H2: 0 | I2: 0 | J2: 0 | K2: 0 | L2: 0 | M2: 0 | N2: 0
A3: 2 | B3: 0 | C3: 0 | D3: 0 | E3: 0.17777778 | F3: 0 | G3: 0 | H3: 0 | I3: 0 | J3: 0 | K3: 0 | L3: 0 | M3: 0 | N3: 0
A4: 4 | B4: 0 | C4: 0 | D4: 0 | E4: 0 | F4: 0 | G4: 0 | H4: 0 | I4: 0 | J4: 0 | K4: 0 | L4: 0.17777778 | M4: 0 | N4: 0
A5: 6 | B5: 0 | C5: 0.17777778 | D5: 0.17777778 | E5: 0.17777778 | F5: 0.17777778 | G5: 0.53333333 | H5: 0 | I5: 0.17777778 | J5: 0 | K5: 0 | L5: 0 | M5: 0 | N5: 0
A6: 8 | B6: 0.17777778 | C6: 0.17777778 | D6: 1.4222222 | E6: 1.6 | F6: 1.0666667 | G6: 1.4222222 | H6: 1.2444444 | I6: 0.53333333 | J6: 0.17777778 | K6: 0 | L6: 0 | M6: 0 | N6: 0
A7: 10 | B7: 0 | C7: 0 | D7: 1.6 | E7: 0.71111111 | F7: 1.7777778 | G7: 1.6 | H7: 1.6 | I7: 0.35555556 | J7: 0.53333333 | K7: 0.17777778 | L7: 0.17777778 | M7: 0 | N7: 0
A8: 12 | B8: 0 | C8: 0.17777778 | D8: 1.2444444 | E8: 0 | F8: 1.2444444 | G8: 1.6 | H8: 0.53333333 | I8: 0.35555556 | J8: 0.88888889 | K8: 0.35555556 | L8: 0 | M8: 0.17777778 | N8: 0.17777778
A9: 14 | B9: 0.35555556 | C9: 1.2444444 | D9: 2.1333333 | E9: 1.0666667 | F9: 1.7777778 | G9: 4.8 | H9: 2.1333333 | I9: 1.0666667 | J9: 3.9111111 | K9: 0.88888889 | L9: 0 | M9: 0 | N9: 0.35555556
A10: 16 | B10: 2.4888889 | C10: 3.2 | D10: 8.3555556 | E10: 5.1555556 | F10: 12.266667 | G10: 25.422222 | H10: 6.4 | I10: 4.4444444 | J10: 5.6888889 | K10: 4.2666667 | L10: 1.4222222 | M10: 0.71111111 | N10: 0
A11: 18 | B11: 3.7333333 | C11: 3.3777778 | D11: 22.222222 | E11: 8.7111111 | F11: 41.955556 | G11: 45.333333 | H11: 11.555556 | I11: 10.133333 | J11: 7.8222222 | K11: 3.2 | L11: 1.6 | M11: 1.7777778 | N11: 0
A12: 20 | B12: 0.88888889 | C12: 2.4888889 | D12: 26.311111 | E12: 22.044444 | F12: 26.311111 | G12: 30.577778 | H12: 24.177778 | I12: 20.977778 | J12: 17.955556 | K12: 1.7777778 | L12: 0.88888889 | M12: 1.0666667 | N12: 0.17777778
A13: 22 | B13: 1.6 | C13: 9.0666667 | D13: 51.2 | E13: 54.044444 | F13: 52.444444 | G13: 56.711111 | H13: 49.066667 | I13: 46.4 | J13: 37.333333 | K13: 6.2222222 | L13: 0.35555556 | M13: 0.17777778 | N13: 0.35555556
... A31: 58 | B31: 346.84444 | C31: 564.8 | D31: 1004.4444 | E31: 882.66667 | F31: 1052.0889 | G31: 1072 | H31: 1005.8667 | I31: 888.53333 | J31: 764.08889 | K31: 528.88889 | L31: 313.42222 | M31: 169.24444 | N31: 96.177778
A32: 60 | B32: 0 | C32: 0 | D32: 0 | E32: 0 | F32: 0 | G32: 0 | H32: 0 | I32: 0 | J32: 0 | K32: 0 | L32: 0 | M32: 0 | N32: 0 | P32: Not considered
A33: 62 | B33: 358.93333 | C33: 560.53333 | D33: 1006.7556 | E33: 865.24444 | F33: 1065.9556 | G33: 1093.3333 | H33: 1044.6222 | I33: 905.77778 | J33: 771.37778 | K33: 554.13333 | L33: 310.04444 | M33: 170.84444 | N33: 92.8
A34: 64 | B34: 435.91111 | C34: 675.73333 | D34: 1170.8444 | E34: 1043.5556 | F34: 1242.6667 | G34: 1265.4222 | H34: 1224.5333 | I34: 1067.9111 | J34: 921.24444 | K34: 648.35556 | L34: 368 | M34: 232.35556 | N34: 123.91111
A35: 66 | B35: 355.2 | C35: 538.13333 | D35: 949.15556 | E35: 828.08889 | F35: 1011.0222 | G35: 1001.9556 | H35: 958.4 | I35: 837.15556 | J35: 734.57778 | K35: 515.2 | L35: 289.77778 | M35: 167.64444 | N35: 101.15556
A36: 68 | B36: 444.8 | C36: 688.71111 | D36: 1210.8444 | E36: 1069.6889 | F36: 1294.5778 | G36: 1282.8444 | H36: 1261.3333 | I36: 1102.4 | J36: 921.42222 | K36: 661.86667 | L36: 382.75556 | M36: 225.24444 | N36: 128.53333
A37: 70 | B37: 496.17778 | C37: 749.86667 | D37: 1334.0444 | E37: 1174.4 | F37: 1405.3333 | G37: 1429.8667 | H37: 1395.2 | I37: 1213.8667 | J37: 1032.5333 | K37: 728.88889 | L37: 440.35556 | M37: 271.11111 | N37: 137.6
A38: 72 | B38: 521.6 | C38: 776 | D38: 1371.9111 | E38: 1219.3778 | F38: 1437.3333 | G38: 1486.2222 | H38: 1396.4444 | I38: 1261.8667 | J38: 1056.7111 | K38: 759.28889 | L38: 455.11111 | M38: 276.26667 | N38: 139.55556
A39: 74 | B39: 464.53333 | C39: 695.82222 | D39: 1227.0222 | E39: 1091.9111 | F39: 1312.3556 | G39: 1323.7333 | H39: 1299.0222 | I39: 1152 | J39: 961.06667 | K39: 690.13333 | L39: 404.8 | M39: 238.93333 | N39: 129.42222
A40: 76 | B40: 520.88889 | C40: 772.8 | D40: 1370.3111 | E40: 1203.2 | F40: 1449.6 | G40: 1465.9556 | H40: 1434.8444 | I40: 1281.7778 | J40: 1084.0889 | K40: 776.53333 | L40: 451.91111 | M40: 279.82222 | N40: 145.6
A41: 78 | B41: 531.37778 | C41: 797.33333 | D41: 1427.3778 | E41: 1253.3333 | F41: 1494.2222 | G41: 1528.7111 | H41: 1456.3556 | I41: 1304 | J41: 1095.1111 | K41: 779.2 | L41: 468.62222 | M41: 280.53333 | N41: 138.31111
A42: 80 | B42: 536.17778 | C42: 795.91111 | D42: 1426.3111 | E42: 1237.6889 | F42: 1487.4667 | G42: 1496.8889 | H42: 1467.2 | I42: 1290.6667 | J42: 1085.3333 | K42: 772.97778 | L42: 452.26667 | M42: 283.73333 | N42: 142.57778
A43: 82 | B43: 452.26667 | C43: 678.93333 | D43: 1182.9333 | E43: 1061.6889 | F43: 1230.7556 | G43: 1257.9556 | H43: 1227.5556 | I43: 1083.5556 | J43: 922.66667 | K43: 633.06667 | L43: 370.31111 | M43: 208.71111 | N43: 108.8
A44: 84 | B44: 558.22222 | C44: 810.48889 | D44: 1437.1556 | E44: 1280.1778 | F44: 1483.2 | G44: 1546.8444 | H44: 1496.5333 | I44: 1308.4444 | J44: 1118.2222 | K44: 770.66667 | L44: 453.86667 | M44: 273.42222 | N44: 140.62222
... A96: 188 | B96: 74.488889 | C96: 164.97778 | D96: 354.13333 | E96: 309.86667 | F96: 435.91111 | G96: 471.46667 | H96: 552.17778 | I96: 478.75556 | J96: 488.88889 | K96: 289.95556 | L96: 153.77778 | M96: 58.844444 | N96: 7.1111111
A97: 190 | B97: 19.733333 | C97: 34.311111 | D97: 64.355556 | E97: 57.244444 | F97: 58.133333 | G97: 67.555556 | H97: 74.133333 | I97: 69.866667 | J97: 51.022222 | K97: 33.244444 | L97: 15.466667 | M97: 4.2666667 | N97: 0.53333333 | P97: Not considered
A98: 192 | B98: 137.42222 | C98: 258.48889 | D98: 487.82222 | E98: 415.46667 | F98: 583.46667 | G98: 616.88889 | H98: 698.84444 | I98: 593.06667 | J98: 625.95556 | K98: 384.71111 | L98: 198.4 | M98: 123.91111 | N98: 17.066667
A99: 194 | B99: 153.24444 | C99: 304.53333 | D99: 536.53333 | E99: 475.91111 | F99: 656.71111 | G99: 693.51111 | H99: 781.51111 | I99: 679.11111 | J99: 687.64444 | K99: 460.62222 | L99: 250.31111 | M99: 135.64444 | N99: 31.466667
A100: 196 | B100: 179.91111 | C100: 369.06667 | D100: 672 | E100: 612.97778 | F100: 827.55556 | G100: 880.17778 | H100: 948.26667 | I100: 858.48889 | J100: 868.44444 | K100: 580.26667 | L100: 321.42222 | M100: 170.31111 | N100: 105.77778
A101: 198 | B101: 252.26667 | C101: 463.28889 | D101: 794.31111 | E101: 722.31111 | F101: 969.95556 | G101: 1022.9333 | H101: 1116.0889 | I101: 981.68889 | J101: 987.2 | K101: 640.71111 | L101: 387.2 | M101: 209.77778 | N101: 126.22222
A102: 200 | B102: 304.71111 | C102: 549.68889 | D102: 955.37778 | E102: 851.2 | F102: 1138.4889 | G102: 1205.6889 | H102: 1249.2444 | I102: 1130.1333 | J102: 1125.1556 | K102: 741.33333 | L102: 457.95556 | M102: 252.8 | N102: 141.15556
A103: 202 | B103: 318.75556 | C103: 588.8 | D103: 1014.4 | E103: 921.06667 | F103: 1259.0222 | G103: 1304 | H103: 1334.2222 | I103: 1209.6 | J103: 1201.0667 | K103: 783.46667 | L103: 480.71111 | M103: 283.91111 | N103: 148.08889
A104: 204 | B104: 408 | C104: 693.68889 | D104: 1195.5556 | E104: 1083.9111 | F104: 1455.2889 | G104: 1526.2222 | H104: 1532.0889 | I104: 1413.5111 | J104: 1360.5333 | K104: 922.84444 | L104: 560.17778 | M104: 333.51111 | N104: 164.62222
A105: 206 | B105: 510.22222 | C105: 859.2 | D105: 1430.9333 | E105: 1307.3778 | F105: 1747.9111 | G105: 1835.0222 | H105: 1847.6444 | I105: 1694.0444 | J105: 1582.2222 | K105: 1068.4444 | L105: 656.53333 | M105: 388.62222 | N105: 203.37778
A106: 208 | B106: 323.73333 | C106: 533.33333 | D106: 920.53333 | E106: 830.93333 | F106: 1106.1333 | G106: 1155.5556 | H106: 1152.5333 | I106: 1037.8667 | J106: 996.8 | K106: 670.57778 | L106: 417.77778 | M106: 248.35556 | N106: 141.33333
A107: 210 | B107: 0 | C107: 0 | D107: 0 | E107: 0 | F107: 0 | G107: 0 | H107: 0 | I107: 0 | J107: 0 | K107: 0 | L107: 0 | M107: 0 | N107: 0 | P107: Not considered
A108: 212 | B108: 670.57778 | C108: 1102.4 | D108: 1861.3333 | E108: 1707.2 | F108: 2232.3556 | G108: 2338.3111 | H108: 2313.7778 | I108: 2110.4 | J108: 2000.7111 | K108: 1342.5778 | L108: 835.73333 | M108: 514.31111 | N108: 294.93333
...

Sheet 2-3
A1: GratingPhaseAmplitude | B1: -1430800 | C1: -1430900 | D1: -14301000 | E1: -14301100 | F1: -14301200 | G1: -14301300 | H1: -14301400 | I1: -14301500 | J1: -14301600 | K1: -14301700 | L1: -14301800 | M1: -14301900 | N1: -14302000
A2: 0 | B2: 0 | C2: 0 | D2: 0 | E2: 0 | F2: 0 | G2: 0 | H2: 0 | I2: 0 | J2: 0 | K2: 0 | L2: 0 | M2: 0 | N2: 0
A3: 2 | B3: 0 | C3: 0 | D3: 0 | E3: 0 | F3: 0 | G3: 0.17777778 | H3: 0 | I3: 0 | J3: 0 | K3: 0.17777778 | L3: 0 | M3: 0 | N3: 0
A4: 4 | B4: 0 | C4: 0 | D4: 0 | E4: 0 | F4: 0.17777778 | G4: 0 | H4: 0 | I4: 0 | J4: 0 | K4: 0 | L4: 0 | M4: 0 | N4: 0
A5: 6 | B5: 0 | C5: 0.17777778 | D5: 0 | E5: 0.35555556 | F5: 0.17777778 | G5: 0.17777778 | H5: 0 | I5: 0 | J5: 0 | K5: 0 | L5: 0 | M5: 0 | N5: 0
A6: 8 | B6: 0 | C6: 0.35555556 | D6: 0.53333333 | E6: 0.17777778 | F6: 1.2444444 | G6: 1.9555556 | H6: 0.88888889 | I6: 1.0666667 | J6: 0.35555556 | K6: 0.53333333 | L6: 0.17777778 | M6: 0 | N6: 0
A7: 10 | B7: 0 | C7: 0.17777778 | D7: 1.2444444 | E7: 2.8444444 | F7: 2.4888889 | G7: 2.1333333 | H7: 0.71111111 | I7: 0.53333333 | J7: 0.71111111 | K7: 1.0666667 | L7: 0 | M7: 0 | N7: 0.35555556
A8: 12 | B8: 0 | C8: 0 | D8: 0.71111111 | E8: 0.53333333 | F8: 2.8444444 | G8: 3.2 | H8: 1.0666667 | I8: 1.2444444 | J8: 0.35555556 | K8: 0.35555556 | L8: 0 | M8: 0 | N8: 0.17777778
A9: 14 | B9: 1.2444444 | C9: 0.71111111 | D9: 4.0888889 | E9: 2.8444444 | F9: 7.2888889 | G9: 4.0888889 | H9: 2.4888889 | I9: 1.9555556 | J9: 2.3111111 | K9: 1.4222222 | L9: 0.71111111 | M9: 0 | N9: 0
A10: 16 | B10: 0.71111111 | C10: 5.1555556 | D10: 7.6444444 | E10: 5.5111111 | F10: 10.133333 | G10: 14.222222 | H10: 4.0888889 | I10: 5.6888889 | J10: 4.8 | K10: 2.8444444 | L10: 0 | M10: 0 | N10: 0.17777778
A11: 18 | B11: 2.4888889 | C11: 2.6666667 | D11: 31.466667 | E11: 16.177778 | F11: 43.555556 | G11: 52.8 | H11: 22.933333 | I11: 10.311111 | J11: 9.0666667 | K11: 1.7777778 | L11: 2.3111111 | M11: 0 | N11: 0
A12: 20 | B12: 6.2222222 | C12: 13.511111 | D12: 120.53333 | E12: 96.888889 | F12: 130.48889 | G12: 136.71111 | H12: 106.84444 | I12: 72 | J12: 77.866667 | K12: 11.733333 | L12: 4.6222222 | M12: 1.2444444 | N12: 0
A13: 22 | B13: 6.2222222 | C13: 14.044444 | D13: 104.35556 | E13: 73.955556 | F13: 118.4 | G13: 123.55556 | H13: 115.73333 | I13: 69.688889 | J13: 52.088889 | K13: 9.4222222 | L13: 3.7333333 | M13: 0.35555556 | N13: 0.53333333
... A126: 248 | B126: 2709.8667 | C126: 4472.7111 | D126: 7010.6667 | E126: 6400 | F126: 8001.4222 | G126: 8051.7333 | H126: 7768 | I126: 6866.8444 | J126: 6257.7778 | K126: 4377.0667 | L126: 2714.8444 | M126: 1707.7333 | N126: 1025.2444

Sheet 2-4
A1: GratingPhaseAmplitude | B1: -1430800 | C1: -1430900 | D1: -14301000 | E1: -14301100 | F1: -14301200 | G1: -14301300 | H1: -14301400 | I1: -14301500 | J1: -14301600 | K1: -14301700 | L1: -14301800 | M1: -14301900 | N1: -14302000
A2: 0 | B2: 0 | C2: 0 | D2: 0 | E2: 0 | F2: 0 | G2: 0.17777778 | H2: 0 | I2: 0 | J2: 0 | K2: 0 | L2: 0 | M2: 0 | N2: 0
A3: 2 | B3: 0 | C3: 0 | D3: 0.17777778 | E3: 0.17777778 | F3: 0 | G3: 0 | H3: 0 | I3: 0 | J3: 0.17777778 | K3: 0 | L3: 0 | M3: 0 | N3: 0
A4: 4 | B4: 0 | C4: 0 | D4: 0 | E4: 0 | F4: 0 | G4: 0 | H4: 0 | I4: 0.17777778 | J4: 0 | K4: 0 | L4: 0 | M4: 0 | N4: 0
A5: 6 | B5: 0 | C5: 0 | D5: 0.17777778 | E5: 0 | F5: 0.17777778 | G5: 0.53333333 | H5: 0 | I5: 0 | J5: 0 | K5: 0 | L5: 0 | M5: 0 | N5: 0
A6: 8 | B6: 0.35555556 | C6: 0 | D6: 0.71111111 | E6: 0 | F6: 1.0666667 | G6: 0.35555556 | H6: 0.35555556 | I6: 0.35555556 | J6: 0.35555556 | K6: 0.17777778 | L6: 0.17777778 | M6: 0.35555556 | N6: 0
A7: 10 | B7: 0.35555556 | C7: 0.17777778 | D7: 3.0222222 | E7: 1.0666667 | F7: 1.9555556 | G7: 3.3777778 | H7: 1.2444444 | I7: 1.7777778 | J7: 1.2444444 | K7: 0.88888889 | L7: 0.35555556 | M7: 0 | N7: 0
A8: 12 | B8: 0.17777778 | C8: 0.71111111 | D8: 1.7777778 | E8: 0.71111111 | F8: 1.7777778 | G8: 1.7777778 | H8: 3.7333333 | I8: 0.88888889 | J8: 0.53333333 | K8: 0.35555556 | L8: 0 | M8: 0 | N8: 0.17777778
A9: 14 | B9: 0.53333333 | C9: 0.17777778 | D9: 4.0888889 | E9: 2.6666667 | F9: 3.0222222 | G9: 7.6444444 | H9: 2.6666667 | I9: 3.2 | J9: 3.9111111 | K9: 0.35555556 | L9: 0.17777778 | M9: 0.17777778 | N9: 0
A10: 16 | B10: 0.71111111 | C10: 2.8444444 | D10: 6.0444444 | E10: 7.6444444 | F10: 18.133333 | G10: 16.177778 | H10: 8.1777778 | I10: 4.9777778 | J10: 4.8 | K10: 2.8444444 | L10: 1.7777778 | M10: 0.35555556 | N10: 0
A11: 18 | B11: 3.7333333 | C11: 3.2 | D11: 33.6 | E11: 15.111111 | F11: 35.2 | G11: 53.155556 | H11: 21.155556 | I11: 9.6 | J11: 9.4222222 | K11: 2.8444444 | L11: 1.4222222 | M11: 1.0666667 | N11: 0.17777778
A12: 20 | B12: 4.4444444 | C12: 8.7111111 | D12: 118.04444 | E12: 89.777778 | F12: 122.31111 | G12: 128.17778 | H12: 108.44444 | I12: 50.488889 | J12: 54.044444 | K12: 5.3333333 | L12: 1.9555556 | M12: 1.4222222 | N12: 0.53333333
A13: 22 | B13: 4.9777778 | C13: 15.644444 | D13: 116.8 | E13: 109.51111 | F13: 134.93333 | G13: 145.6 | H13: 118.22222 | I13: 97.6 | J13: 89.6 | K13: 16.711111 | L13: 4.8 | M13: 2.1333333 | N13: 0.17777778
... A126: 248 | B126: 2661.1556 | C126: 4363.5556 | D126: 6903.8222 | E126: 6315.5556 | F126: 7884.4444 | G126: 7968.1778 | H126: 7659.3778 | I126: 6776 | J126: 6167.8222 | K126: 4269.3333 | L126: 2649.2444 | M126: 1692.6222 | N126: 998.93333

Sheet 2-5
A1: GratingPhaseAmplitude | B1: -1430800 | C1: -1430900 | D1: -14301000 | E1: -14301100 | F1: -14301200 | G1: -14301300 | H1: -14301400 | I1: -14301500 | J1: -14301600 | K1: -14301700 | L1: -14301800 | M1: -14301900 | N1: -14302000
A2: 0 | B2: 0 | C2: 0 | D2: 0 | E2: 0 | F2: 0 | G2: 0 | H2: 0 | I2: 0 | J2: 0 | K2: 0 | L2: 0 | M2: 0 | N2: 0
A3: 2 | B3: 0 | C3: 0 | D3: 0 | E3: 0 | F3: 0 | G3: 0 | H3: 0 | I3: 0 | J3: 0 | K3: 0 | L3: 0 | M3: 0 | N3: 0.35555556
A4: 4 | B4: 0 | C4: 0.17777778 | D4: 0 | E4: 0 | F4: 0.17777778 | G4: 0 | H4: 0 | I4: 0 | J4: 0 | K4: 0.17777778 | L4: 0 | M4: 0 | N4: 0
A5: 6 | B5: 0 | C5: 0 | D5: 0.17777778 | E5: 0.17777778 | F5: 0.17777778 | G5: 0.35555556 | H5: 0 | I5: 0 | J5: 0 | K5: 0 | L5: 0.17777778 | M5: 0.17777778 | N5: 0
A6: 8 | B6: 0.17777778 | C6: 0 | D6: 0.35555556 | E6: 0.35555556 | F6: 1.0666667 | G6: 1.4222222 | H6: 0.35555556 | I6: 0.17777778 | J6: 0.71111111 | K6: 0.17777778 | L6: 0 | M6: 0.35555556 | N6: 0
A7: 10 | B7: 0.17777778 | C7: 0.17777778 | D7: 0.88888889 | E7: 1.2444444 | F7: 1.7777778 | G7: 2.6666667 | H7: 0.35555556 | I7: 1.4222222 | J7: 0.88888889 | K7: 0 | L7: 0.17777778 | M7: 0 | N7: 0
A8: 12 | B8: 0 | C8: 0.35555556 | D8: 0.88888889 | E8: 2.6666667 | F8: 1.7777778 | G8: 2.1333333 | H8: 0.53333333 | I8: 1.6 | J8: 1.0666667 | K8: 0 | L8: 0 | M8: 0.35555556 | N8: 0
A9: 14 | B9: 0.71111111 | C9: 1.4222222 | D9: 3.7333333 | E9: 4.8 | F9: 5.8666667 | G9: 5.1555556 | H9: 4.6222222 | I9: 1.7777778 | J9: 1.9555556 | K9: 1.6 | L9: 0 | M9: 0 | N9: 0.17777778
A10: 16 | B10: 2.6666667 | C10: 4.6222222 | D10: 6.5777778 | E10: 8.8888889 | F10: 17.777778 | G10: 20.977778 | H10: 4.8 | I10: 7.4666667 | J10: 9.6 | K10: 3.3777778 | L10: 1.2444444 | M10: 0.17777778 | N10: 0
A11: 18 | B11: 2.3111111 | C11: 4.8 | D11: 12.8 | E11: 15.644444 | F11: 34.666667 | G11: 40.177778 | H11: 13.155556 | I11: 9.6 | J11: 9.7777778 | K11: 3.7333333 | L11: 1.0666667 | M11: 0.53333333 | N11: 0.17777778
A12: 20 | B12: 5.3333333 | C12: 13.333333 | D12: 116.8 | E12: 106.48889 | F12: 126.93333 | G12: 133.15556 | H12: 107.91111 | I12: 73.6 | J12: 66.844444 | K12: 10.133333 | L12: 3.9111111 | M12: 2.6666667 | N12: 0.53333333
A13: 22 | B13: 4.2666667 | C13: 8.8888889 | D13: 112.88889 | E13: 86.933333 | F13: 121.6 | G13: 131.02222 | H13: 99.911111 | I13: 67.911111 | J13: 61.333333 | K13: 7.1111111 | L13: 2.6666667 | M13: 0.35555556 | N13: 0
... A40: 76 | B40: 538.66667 | C40: 824 | D40: 1445.6889 | E40: 1262.7556 | F40: 1517.8667 | G40: 1545.6 | H40: 1550.5778 | I40: 1319.1111 | J40: 1156.6222 | K40: 795.37778 | L40: 476.26667 | M40: 286.04444 | N40: 148.97778
A41: 78 | B41: 103.11111 | C41: 177.06667 | D41: 309.33333 | E41: 268.8 | F41: 327.28889 | G41: 334.4 | H41: 315.73333 | I41: 272.88889 | J41: 240.53333 | K41: 163.37778 | L41: 91.022222 | M41: 54.222222 | N41: 26.666667 | P41: Not considered
A42: 80 | B42: 510.93333 | C42: 786.13333 | D42: 1363.3778 | E42: 1209.0667 | F42: 1435.9111 | G42: 1470.0444 | H42: 1434.1333 | I42: 1250.3111 | J42: 1095.6444 | K42: 740.26667 | L42: 440.17778 | M42: 273.95556 | N42: 140.62222
A43: 82 | B43: 456.88889 | C43: 702.93333 | D43: 1233.4222 | E43: 1109.8667 | F43: 1307.7333 | G43: 1304.8889 | H43: 1322.3111 | I43: 1121.2444 | J43: 966.93333 | K43: 674.13333 | L43: 394.84444 | M43: 216.88889 | N43: 127.28889
A44: 84 | B44: 522.84444 | C44: 812.44444 | D44: 1402.6667 | E44: 1240.5333 | F44: 1454.5778 | G44: 1492.9778 | H44: 1506.4889 | I44: 1299.9111 | J44: 1110.5778 | K44: 775.28889 | L44: 462.22222 | M44: 268.44444 | N44: 137.95556
A45: 86 | B45: 569.6 | C45: 868.26667 | D45: 1505.2444 | E45: 1331.2 | F45: 1591.8222 | G45: 1611.3778 | H45: 1568 | I45: 1361.0667 | J45: 1163.2 | K45: 811.91111 | L45: 486.04444 | M45: 291.73333 | N45: 149.33333
A46: 88 | B46: 628.26667 | C46: 950.93333 | D46: 1666.3111 | E46: 1489.4222 | F46: 1752.8889 | G46: 1767.1111 | H46: 1777.0667 | I46: 1520.7111 | J46: 1289.6 | K46: 915.73333 | L46: 531.91111 | M46: 325.68889 | N46: 155.55556
A47: 90 | B47: 127.64444 | C47: 190.4 | D47: 334.22222 | E47: 291.91111 | F47: 349.51111 | G47: 355.02222 | H47: 354.48889 | I47: 295.82222 | J47: 260.62222 | K47: 172.8 | L47: 106.13333 | M47: 65.955556 | N47: 31.466667 | P47: Not considered
A48: 92 | B48: 619.91111 | C48: 922.84444 | D48: 1619.0222 | E48: 1435.5556 | F48: 1688.8889 | G48: 1744.1778 | H48: 1723.5556 | I48: 1485.3333 | J48: 1261.6889 | K48: 881.24444 | L48: 509.86667 | M48: 318.4 | N48: 148.97778
A49: 94 | B49: 590.57778 | C49: 891.37778 | D49: 1550.5778 | E49: 1374.4 | F49: 1624.5333 | G49: 1659.3778 | H49: 1611.9111 | I49: 1425.7778 | J49: 1189.6889 | K49: 835.2 | L49: 489.06667 | M49: 305.6 | N49: 150.57778
A50: 96 | B50: 387.73333 | C50: 586.13333 | D50: 1039.4667 | E50: 908.8 | F50: 1071.6444 | G50: 1078.0444 | H50: 1106.4889 | I50: 924.8 | J50: 782.4 | K50: 540.8 | L50: 323.2 | M50: 200.71111 | N50: 97.422222 | P50: Not considered
A51: 98 | B51: 573.33333 | C51: 887.11111 | D51: 1577.7778 | E51: 1377.2444 | F51: 1639.1111 | G51: 1637.5111 | H51: 1652.6222 | I51: 1408.5333 | J51: 1190.2222 | K51: 833.77778 | L51: 481.24444 | M51: 294.57778 | N51: 141.68889
A52: 100 | B52: 265.77778 | C52: 406.04444 | D52: 696.17778 | E52: 617.6 | F52: 729.06667 | G52: 738.84444 | H52: 737.95556 | I52: 633.95556 | J52: 543.64444 | K52: 371.2 | L52: 218.31111 | M52: 133.15556 | N52: 65.6 | P52: Not considered
A53: 102 | B53: 620.62222 | C53: 914.13333 | D53: 1648.8889 | E53: 1432.8889 | F53: 1673.4222 | G53: 1720 | H53: 1714.4889 | I53: 1476.6222 | J53: 1221.8667 | K53: 854.04444 | L53: 495.82222 | M53: 303.64444 | N53: 140.8
A54: 104 | B54: 609.06667 | C54: 904.35556 | D54: 1607.8222 | E54: 1434.6667 | F54: 1649.0667 | G54: 1691.2 | H54: 1670.7556 | I54: 1441.4222 | J54: 1195.0222 | K54: 819.02222 | L54: 488.71111 | M54: 289.24444 | N54: 140.08889
A55: 106 | B55: 537.77778 | C55: 822.04444 | D55: 1476.4444 | E55: 1279.1111 | F55: 1516.0889 | G55: 1546.4889 | H55: 1513.7778 | I55: 1293.3333 | J55: 1072.8889 | K55: 748.08889 | L55: 430.4 | M55: 255.64444 | N55: 118.4
A56: 108 | B56: 585.77778 | C56: 878.04444 | D56: 1550.4 | E56: 1344.3556 | F56: 1591.6444 | G56: 1612.8 | H56: 1604.6222 | I56: 1394.4889 | J56: 1142.7556 | K56: 777.77778 | L56: 461.86667 | M56: 264.88889 | N56: 132.26667
A57: 110 | B57: 576.53333 | C57: 812.26667 | D57: 1474.3111 | E57: 1304.8889 | F57: 1483.2 | G57: 1557.6889 | H57: 1533.6889 | I57: 1334.0444 | J57: 1084.6222 | K57: 749.68889 | L57: 437.86667 | M57: 238.75556 | N57: 126.04444
A58: 112 | B58: 593.06667 | C58: 849.77778 | D58: 1526.0444 | E58: 1352.5333 | F58: 1583.6444 | G58: 1585.6 | H58: 1571.3778 | I58: 1386.8444 | J58: 1078.2222 | K58: 768 | L58: 454.93333 | M58: 253.33333 | N58: 121.42222
A59: 114 | B59: 607.82222 | C59: 870.04444 | D59: 1576.7111 | E59: 1379.2 | F59: 1624.1778 | G59: 1657.7778 | H59: 1640.7111 | I59: 1387.2 | J59: 1135.8222 | K59: 763.02222 | L59: 459.55556 | M59: 265.42222 | N59: 125.68889
A60: 116 | B60: 552.17778 | C60: 811.37778 | D60: 1448.3556 | E60: 1278.7556 | F60: 1466.1333 | G60: 1476.4444 | H60: 1520 | I60: 1271.1111 | J60: 1002.4889 | K60: 705.77778 | L60: 395.37778 | M60: 210.66667 | N60: 108.97778
A61: 118 | B61: 545.77778 | C61: 795.02222 | D61: 1411.0222 | E61: 1249.4222 | F61: 1431.1111 | G61: 1439.6444 | H61: 1460.9778 | I61: 1218.1333 | J61: 978.84444 | K61: 672 | L61: 377.06667 | M61: 193.24444 | N61: 102.22222
A62: 120 | B62: 554.31111 | C62: 776.35556 | D62: 1434.3111 | E62: 1237.5111 | F62: 1428.4444 | G62: 1422.7556 | H62: 1472.3556 | I62: 1237.5111 | J62: 982.93333 | K62: 661.33333 | L62: 374.22222 | M62: 177.42222 | N62: 81.066667
A63: 122 | B63: 497.06667 | C63: 720 | D63: 1306.1333 | E63: 1147.3778 | F63: 1315.0222 | G63: 1312.7111 | H63: 1347.0222 | I63: 1131.3778 | J63: 890.66667 | K63: 612.44444 | L63: 316.97778 | M63: 162.48889 | N63: 42.844444
A64: 124 | B64: 447.28889 | C64: 637.68889 | D64: 1146.4889 | E64: 1016.3556 | F64: 1141.3333 | G64: 1171.7333 | H64: 1187.0222 | I64: 991.46667 | J64: 763.91111 | K64: 517.33333 | L64: 281.06667 | M64: 138.31111 | N64: 23.822222
... A104: 204 | B104: 407.11111 | C104: 678.93333 | D104: 1190.0444 | E104: 1082.6667 | F104: 1431.2889 | G104: 1558.0444 | H104: 1519.2889 | I104: 1399.4667 | J104: 1362.1333 | K104: 889.6 | L104: 557.15556 | M104: 318.57778 | N104: 162.31111
A105: 206 | B105: 320 | C105: 514.31111 | D105: 896.88889 | E105: 821.33333 | F105: 1070.0444 | G105: 1144 | H105: 1142.7556 | I105: 1043.3778 | J105: 986.84444 | K105: 658.84444 | L105: 405.33333 | M105: 241.77778 | N105: 132.44444 | P105: Not considered
...
